File: debug/ppms_ac.dat
[Header]
; ACMS Data File (default extension .dat)
; Copyright 1999, Quantum Design, Inc. All rights reserved.
TITLE,
FILEOPENTIME,4930616.58,02/27/2010,12:24 am
BYAPP,ACMS,1.0,1.1
INFO,PPMS ACMS Option Version: 1.0.9 Build 14,APPNAME
INFO,HARMONICS,1
DATATYPE,COMMENT,1
DATATYPE,TIME,2
FIELDGROUP,AC Mag,2,3,4,5,6,8,9,10,11,12
FIELDGROUP,DC Mag,2,3,4,7,8
STARTUPGROUP,All
STARTUPAXIS,X,2,LINEAR,AUTO
TIMEMODE,MINUTES,RELATIVE
PLOT_APPEARANCE,ALL,HORZ_GRID_ON,VERT_GRID_ON,MARKERS_AND_LINES
RECORDS,ALL_RECORDS
DATATYPE,TIME,2
DATATYPE,COMMENT,1
[Data]
Comment,Time Stamp (sec),Temperature (K),Magnetic Field (Oe),Frequency (Hz),Amplitude (Oe),M-DC (emu),M-Std.Dev. (emu),M' (emu),M'' (emu),Moment (emu),Phase (deg),Calcoil' (emu),Calcoil'' (emu),Calcoil (emu),CC Phase (deg),Count,Gain,Measure Type,Elapsed (sec),Sample Center (cm),Max.Signal (V),PPMS Status (code),DSP Status (code),Min.Temperature (K),Max.Temperature (K),Min.Field (Oe),Max.Field (Oe),DC Position (cm),PPMS Temperature (K),PPMS Position,Bridge 1 Resistance (ohms),Bridge 1 Excitation (uA),Bridge 2 Resistance (ohms),Bridge 2 Excitation (uA),Bridge 3 Resistance (ohms),Bridge 3 Excitation (uA),Bridge 4 Resistance (ohms),Bridge 4 Excitation (uA),Signal 1 Vin (V),Signal 2 Vin (V),Digital Inputs (code),Drive 1 Iout (mA),Drive 1 Ipower (watts),Drive 2 Iout (mA),Drive 2 Ipower (watts),Pressure (),Map 20 (),Map 21 (),Map 22 (),Map 23 (),Map 24 (),Map 25 (),Map 26 (),Map 27 (),Map 28 (),Map 29 ()
,4941702.03,100.0872383,9998.957,1000,9.99871967373226,,0.385743317863009,,,,,,,,,,125,1,0,-0.642970886688334,0.000378976808186316,4369,0,100.0809326,100.093544,9998.957,9998.957,,99.86775,,,,,,,,,,,,,,,,,,,,,,,100.0872383
,4941753.87,100.07829,9998.957,1000,9.9985331041582,,9.20830949628141E-9,2.97149345023397E-6,-1.1354210087322E-8,2.97151514262843E-6,-0.218928684362311,1.5177597342373E-8,-2.7384493979037E-10,1.51800675933362E-8,-1.03365879868272,333,5,5,13.4965986394558,-0.642970886688334,0.000808421627007144,4369,0,100.0717468,100.0843658,9998.957,9998.957,,99.8907875,,,,,,,,,,,,,,,,,,,,,,,100.07829
,4942108.63,101.1003494,9998.957,1000,9.99887646560816,,0.37785020335871,,,,,,,,,,125,1,0,-0.613542278778061,0.000379159103695379,4369,0,101.1003494,101.1003494,9998.957,9998.957,,100.8367,,,,,,,,,,,,,,,,,,,,,,,101.1003494
,4942157.45,101.067173975,9998.957,1000,9.99869248051396,,9.78220180089027E-9,2.93127630018201E-6,1.28524883108274E-8,2.93130447658795E-6,0.251217743433242,1.51780035037841E-8,-2.73954412086682E-10,1.51804756638514E-8,-1.03404425895735,333,5,5,13.4965986394558,-0.613542278778061,0.000809877080173316,4369,0,101.0654297,101.0735855,9998.957,9998.957,,100.9322875,,,,,,,,,,,,,,,,,,,,,,,101.067173975
,4942488.81,102.11730575,9998.957,1000,9.99888621691358,,0.355133020197172,,,,,,,,,,125,1,0,-0.634752672661929,0.00037940498431464,4369,0,102.1080627,102.1265488,9998.957,9998.957,,101.8064,,,,,,,,,,,,,,,,,,,,,,,102.11730575
,4942538.87,102.089486125,9998.957,1000,9.99859858490655,,1.02013653365922E-8,2.94102229501428E-6,3.58793676229842E-9,2.94102448358753E-6,0.0698986648290512,1.51789075402411E-8,-2.73943581990416E-10,1.51813793576639E-8,-1.03394181894311,333,5,5,13.4965986394558,-0.634752672661929,0.000809814141658022,4369,0,102.0855408,102.0946884,9998.957,9998.957,,101.89425,,,,,,,,,,,,,,,,,,,,,,,102.089486125
,4942869.13,103.1114197,9998.957,1000,9.9990401737699,,0.395749713298003,,,,,,,,,,125,1,0,-0.634731276175995,0.000379663418217458,4369,0,103.1016083,103.1212311,9998.957,9998.957,,102.79835,,,,,,,,,,,,,,,,,,,,,,,103.1114197
,4942917.19,103.08067895,9998.957,1000,9.9987892424918,,1.12247524133018E-8,2.92415171600051E-6,6.3879713479333E-9,2.92415869343076E-6,0.125165603980655,1.51787249015451E-8,-2.73981879515475E-10,1.51811974398296E-8,-1.03409877341431,333,5,5,13.4965986394558,-0.634731276175995,0.000809393240336994,4369,0,103.0710068,103.0854416,9998.957,9998.957,,102.927875,,,,,,,,,,,,,,,,,,,,,,,103.08067895
,4943247.89,104.1161423,9998.957,1000,9.99902473664265,,0.375166552437841,,,,,,,,,,125,1,0,-0.598196530214466,0.000379736281841589,4369,0,104.1073227,104.1249619,9998.957,9998.957,,103.8059,,,,,,,,,,,,,,,,,,,,,,,104.1161423
,4943295.57,104.0900049,9998.957,1000,9.9986998121027,,6.98506932872646E-9,2.88759279235393E-6,9.9787360773134E-9,2.88761003420269E-6,0.197997857495675,1.51793228259138E-8,-2.73817726474733E-10,1.51817923052794E-8,-1.03343863897879,333,5,5,13.4965986394558,-0.598196530214466,0.000807945654485234,4369,0,104.0814972,104.0979309,9998.957,9998.957,,103.8781125,,,,,,,,,,,,,,,,,,,,,,,104.0900049
,4943624.67,105.11097335,9998.957,1000,9.99905984216108,,0.375183069824179,,,,,,,,,,125,1,0,-0.646356497479287,0.000380040835416611,4369,0,105.099617,105.1223297,9998.957,9998.957,,104.792,,,,,,,,,,,,,,,,,,,,,,,105.11097335
,4943676.16,105.0815925625,9998.957,1000,9.99883693845636,,9.22544755856201E-9,2.94840371734904E-6,5.34980220937437E-9,2.94840857088385E-6,0.103961594416606,1.51793773131364E-8,-2.7420662335873E-10,1.51818538027098E-8,-1.0349023745564,333,5,5,13.4965986394558,-0.646356497479287,0.000806639680292886,4369,0,105.0715866,105.0871201,9998.957,9998.957,,104.947325,,,,,,,,,,,,,,,,,,,,,,,105.0815925625
,4944005.33,106.1123047,9998.957,1000,9.99906493492982,,0.327772284936372,,,,,,,,,,125,1,0,-0.651705881259308,0.00038028480575359,4369,0,106.1111908,106.1134186,9998.957,9998.957,,105.79675,,,,,,,,,,,,,,,,,,,,,,,106.1123047
,4944054.84,106.0854892875,9998.957,1000,9.99882221171125,,9.16197271422925E-9,2.92783195389716E-6,-1.20943040666481E-9,2.92783220369323E-6,-0.0236677702362726,1.51796735188212E-8,-2.73936458892911E-10,1.51821450830083E-8,-1.03386277930343,333,5,5,13.4965986394558,-0.651705881259308,0.000805491052388771,4369,0,106.0783463,106.0905075,9998.957,9998.957,,105.913125,,,,,,,,,,,,,,,,,,,,,,,106.0854892875
,4944383.61,107.1048851,9998.957,1000,9.99909207013906,,0.412846688877986,,,,,,,,,,125,1,0,-0.666847038596462,0.000380527957398164,4369,0,107.0962219,107.1135483,9998.957,9998.957,,106.852,,,,,,,,,,,,,,,,,,,,,,,107.1048851
,4944433.26,107.0959138625,9998.957,1000,9.99881840404573,,8.40371240317282E-9,2.94225740838612E-6,-4.9170285164875E-8,2.94266824058476E-6,-0.957423909800241,1.51799410205624E-8,-2.73986491141863E-10,1.51824134440174E-8,-1.03403334671395,333,5,5,13.4965986394558,-0.666847038596462,0.000804432898600393,4369,0,107.0912704,107.1017914,9998.957,9998.957,,106.8469,,,,,,,,,,,,,,,,,,,,,,,107.0959138625
,4944771.63,108.14953995,9998.957,1000,9.99894423731129,,0.351663653196345,,,,,,,,,,125,1,0,-0.641411612757629,0.000380656219208433,4369,0,108.1427383,108.1563416,9998.957,9998.957,,107.7317,,,,,,,,,,,,,,,,,,,,,,,108.14953995
,4944820.66,108.1111002125,9998.957,1000,9.99860410598438,,1.33972976828347E-8,2.93086636558275E-6,1.42141695466223E-8,2.93090083345038E-6,0.277871945568259,1.51809512842618E-8,-2.74108942854815E-10,1.51834257533563E-8,-1.03442655403495,333,5,5,13.4965986394558,-0.641411612757629,0.00080394905876407,4369,0,108.1050034,108.1184616,9998.957,9998.957,,107.8665375,,,,,,,,,,,,,,,,,,,,,,,108.1111002125
,4945150.43,109.12452315,9998.957,1000,9.99898364834121,,0.377286618197322,,,,,,,,,,125,1,0,-0.659378893575969,0.0003808436997694,4369,0,109.1234665,109.1255798,9998.957,9998.957,,108.7782,,,,,,,,,,,,,,,,,,,,,,,109.12452315
,4945199.28,109.0983352625,9998.957,1000,9.99870893268289,,8.64340738414771E-9,2.93689312417971E-6,-2.14224335039543E-8,2.93697125343631E-6,-0.417922344063413,1.51807020964935E-8,-2.740786255988E-10,1.51831760588979E-8,-1.03432914257911,333,5,5,13.4965986394558,-0.659378893575969,0.000801962561875106,4369,0,109.0917816,109.1064148,9998.957,9998.957,,108.8629125,,,,,,,,,,,,,,,,,,,,,,,109.0983352625
,4945528.46,110.12636565,9998.957,1000,9.99899780524625,,0.428245348874578,,,,,,,,,,125,1,0,-0.646571552951226,0.000381257958126822,4369,0,110.1151962,110.1375351,9998.957,9998.957,,109.7859,,,,,,,,,,,,,,,,,,,,,,,110.12636565
,4945576.38,110.10035325,9998.957,1000,9.99852139881397,,9.59255326759557E-9,2.90550553631556E-6,-2.40947869303228E-9,2.90550653538207E-6,-0.0475142540825573,1.51814097678087E-8,-2.74092020967758E-10,1.51838838567106E-8,-1.03433147714259,333,5,5,13.4965986394558,-0.646571552951226,0.000801132560204668,4369,0,110.0923233,110.1052704,9998.957,9998.957,,109.8799125,,,,,,,,,,,,,,,,,,,,,,,110.10035325
,4945904.29,111.1353378,9998.957,1000,9.99887539546667,,0.386806568681531,,,,,,,,,,125,1,0,-0.641190565286142,0.00038123612632933,4369,0,111.1284027,111.1422729,9998.957,9998.957,,110.75645,,,,,,,,,,,,,,,,,,,,,,,111.1353378
,4945953.24,111.1016864625,9998.957,1000,9.99852714053266,,6.94329392174618E-9,2.90408233023229E-6,1.5322015543768E-8,2.90412274963159E-6,0.302291250332703,1.51817999414893E-8,-2.74108166528031E-10,1.51842742582701E-8,-1.0343658136357,333,5,5,13.4965986394558,-0.641190565286142,0.00080010194201673,4369,0,111.0937958,111.1064148,9998.957,9998.957,,110.8842,,,,,,,,,,,,,,,,,,,,,,,111.1016864625
,4946281.21,112.13047025,9998.957,1000,9.99876389866952,,0.388639346514434,,,,,,,,,,125,1,0,-0.639775668813007,0.000381377760115563,4369,0,112.1298294,112.1311111,9998.957,9998.957,,111.7555,,,,,,,,,,,,,,,,,,,,,,,112.13047025
,4946331.07,112.09906295,9998.957,1000,9.99853444895997,,1.02740921657544E-8,2.87036840233184E-6,-1.32071392193175E-8,2.87039878651581E-6,-0.263627482808545,1.51822856662715E-8,-2.74215872590708E-10,1.51847618485458E-8,-1.0347390633093,333,5,5,13.4965986394558,-0.639775668813007,0.00079892971216938,4369,0,112.093132,112.1072388,9998.957,9998.957,,111.9061,,,,,,,,,,,,,,,,,,,,,,,112.09906295
,4946655.26,113.1295624,9998.957,1000,9.99866237718104,,0.349893634688619,,,,,,,,,,125,1,0,-0.641192905089428,0.000381699779128578,4369,0,113.1256485,113.1334763,9998.957,9998.957,,112.7603,,,,,,,,,,,,,,,,,,,,,,,113.1295624
,4946704.54,113.1015643875,9998.957,1000,9.99835468310197,,1.01414362390139E-8,2.85429291938728E-6,-1.63341057389578E-8,2.85433965615073E-6,-0.327879839726052,1.51827429555712E-8,-2.74294995771501E-10,1.51852204922962E-8,-1.03500639796374,333,5,5,13.4965986394558,-0.641192905089428,0.000797993501754383,4369,0,113.096344,113.1093826,9998.957,9998.957,,112.8619625,,,,,,,,,,,,,,,,,,,,,,,113.1015643875
,4947048.87,114.15636445,9998.957,1000,9.99843480194243,,0.392932207807008,,,,,,,,,,125,1,0,-0.66656125604602,0.000381713151104542,4369,0,114.1490784,114.1636505,9998.957,9998.957,,113.65695,,,,,,,,,,,,,,,,,,,,,,,114.15636445
,4947099.65,114.1120834375,9998.957,1000,9.99814089584029,,1.38958186561748E-8,2.88788609409558E-6,-7.62923504375267E-9,2.88789617155776E-6,-0.151363986586659,1.51837445436539E-8,-2.74389804245294E-10,1.51862236297117E-8,-1.03529578165433,333,5,5,13.4965986394558,-0.66656125604602,0.000796896011393946,4369,0,114.1045227,114.1231003,9998.957,9998.957,,113.87595,,,,,,,,,,,,,,,,,,,,,,,114.1120834375
,4947425.87,115.13214495,9998.957,1000,9.99844597378906,,0.366431381273104,,,,,,,,,,125,1,0,-0.636916858047416,0.000381881801740172,4369,0,115.1263657,115.1379242,9998.957,9998.957,,114.76465,,,,,,,,,,,,,,,,,,,,,,,115.13214495
,4947474.66,115.108119975,9998.957,1000,9.99804124086364,,7.33638431343704E-9,2.85477719723851E-6,-8.41011686288297E-9,2.85478958523016E-6,-0.168791738958646,1.51837344307883E-8,-2.74450588857774E-10,1.51862146168962E-8,-1.03552576671274,333,5,5,13.4965986394558,-0.636916858047416,0.000795121931994098,4369,0,115.1010513,115.1177673,9998.957,9998.957,,114.81955,,,,,,,,,,,,,,,,,,,,,,,115.108119975
,4947801.88,116.13874055,9998.957,1000,9.99828884297816,,0.384415996758795,,,,,,,,,,125,1,0,-0.640923668227439,0.000382003514011193,4369,0,116.1300812,116.1473999,9998.957,9998.957,,115.75985,,,,,,,,,,,,,,,,,,,,,,,116.13874055
,4947851.14,116.109178525,9998.957,1000,10.0018730508977,,1.22489381638955E-8,2.84717020778809E-6,-7.47582244614269E-9,2.84718002241469E-6,-0.150441336113772,1.5184205812342E-8,-2.7455971842783E-10,1.51866878940256E-8,-1.03590527944647,333,5,5,13.4965986394558,-0.640923668227439,0.000794331266895719,4369,0,116.1029739,116.1147308,9998.957,9998.957,,115.8400125,,,,,,,,,,,,,,,,,,,,,,,116.109178525
,4948177.06,117.12656785,9998.957,1000,9.99823533767587,,0.387025607652193,,,,,,,,,,125,1,0,-0.645441707233799,0.000382072284173295,4369,0,117.1259079,117.1272278,9998.957,9998.957,,116.76435,,,,,,,,,,,,,,,,,,,,,,,117.12656785
,4948225.88,117.118004825,9998.957,1000,10.0017633258977,,1.25825502042302E-8,2.83237524616821E-6,-1.46259019380327E-8,2.83241300874606E-6,-0.295862988278998,1.51844768117559E-8,-2.74485715898E-10,1.51869575114631E-8,-1.0356076520859,333,5,5,13.4965986394558,-0.645441707233799,0.000793457994996015,4369,0,117.1069031,117.1245804,9998.957,9998.957,,116.8257125,,,,,,,,,,,,,,,,,,,,,,,117.118004825
,4948552.70,118.1334801,9998.957,1000,9.99807837687997,,0.399617695871815,,,,,,,,,,125,1,0,-0.63405046516229,0.000382268770350728,4369,0,118.1247101,118.1422501,9998.957,9998.957,,117.79115,,,,,,,,,,,,,,,,,,,,,,,118.1334801
,4948601.36,118.113922125,9998.957,1000,10.0015645686771,,9.01948965474964E-9,2.83783221173229E-6,9.93286345882166E-9,2.83784959497889E-6,0.200543509321301,1.51851069562128E-8,-2.74464231094163E-10,1.51875871647136E-8,-1.03548364724048,333,5,5,13.4965986394558,-0.63405046516229,0.00079193960331455,4369,0,118.1017914,118.1233597,9998.957,9998.957,,117.8008125,,,,,,,,,,,,,,,,,,,,,,,118.113922125
,4948928.49,119.14403535,9998.957,1000,10.00180088403,,0.368787493838235,,,,,,,,,,125,1,0,-0.67772106304648,0.000382627903419481,4369,0,119.1433563,119.1447144,9998.957,9998.957,,118.77245,,,,,,,,,,,,,,,,,,,,,,,119.14403535
,4948977.10,119.1158513875,9998.957,1000,10.0013762401332,,6.62764244195866E-9,2.84181732527602E-6,2.07313002812217E-8,2.84189294257371E-6,0.417970194237578,1.51856221104349E-8,-2.74538336627118E-10,1.51881035741532E-8,-1.03572803826285,333,5,5,13.4965986394558,-0.67772106304648,0.000790688700323083,4369,0,119.1114044,119.1209869,9998.957,9998.957,,118.8062,,,,,,,,,,,,,,,,,,,,,,,119.1158513875
,4949301.50,120.15986635,9998.957,1000,10.0014956703358,,0.395442705113109,,,,,,,,,,125,1,0,-0.655249388604932,0.000382430598549642,4369,0,120.152359,120.1673737,9998.957,9998.957,,119.76835,,,,,,,,,,,,,,,,,,,,,,,120.15986635
,4949351.97,120.1409511625,9998.957,1000,10.001064976914,,6.74862477646829E-9,2.82993447067275E-6,-1.5598994733166E-8,2.82997746226689E-6,-0.315819154263579,1.51868780429709E-8,-2.74515103600047E-10,1.51893588816044E-8,-1.0355547807456,333,5,5,13.4965986394558,-0.655249388604932,0.000790047514198526,4369,0,120.134613,120.1483688,9998.957,9998.957,,119.758425,,,,,,,,,,,,,,,,,,,,,,,120.1409511625
,4949678.11,121.1551437,9998.957,1000,10.0014617143392,,0.370628809185767,,,,,,,,,,125,1,0,-0.647906180666683,0.000382398669545809,4369,0,121.1524429,121.1578445,9998.957,9998.957,,120.7401,,,,,,,,,,,,,,,,,,,,,,,121.1551437
,4949726.93,121.12500955,9998.957,1000,10.0010256118249,,1.09536382020269E-8,2.82538568598927E-6,-4.55207289242714E-9,2.82538935298494E-6,-0.0923110569986534,1.51867815351143E-8,-2.74504587374327E-10,1.51892621994546E-8,-1.03552169795319,333,5,5,13.4965986394558,-0.647906180666683,0.00078859599468956,4369,0,121.1206436,121.1314087,9998.957,9998.957,,120.8211125,,,,,,,,,,,,,,,,,,,,,,,121.12500955
,4950052.70,122.14889145,9998.957,1000,10.0012798542189,,0.389268541101256,,,,,,,,,,125,1,0,-0.629269616263792,0.000382451884552197,4369,0,122.146843,122.1509399,9998.957,9998.957,,121.7584,,,,,,,,,,,,,,,,,,,,,,,122.14889145
,4950100.32,122.1276454875,9998.957,1000,10.0008229145385,,1.82070281092768E-8,2.7823760450242E-6,-3.10676905155912E-9,2.78237777951493E-6,-0.0639757810299102,1.51874950124319E-8,-2.7452153583147E-10,1.51899758665469E-8,-1.03553698010046,333,5,5,13.4965986394558,-0.629269616263792,0.000786983195235154,4369,0,122.1177368,122.1423416,9998.957,9998.957,,121.770325,,,,,,,,,,,,,,,,,,,,,,,122.1276454875
,4950429.59,123.1452942,9998.957,1000,10.0010752080296,,0.385007676376904,,,,,,,,,,125,1,0,-0.640121079016954,0.00038251028461049,4369,0,123.1419373,123.1486511,9998.957,9998.957,,122.7122,,,,,,,,,,,,,,,,,,,,,,,123.1452942
,4950477.29,123.1243772625,9998.957,1000,10.0007546632782,,1.1191926586031E-8,2.80067113431976E-6,-1.95884461939197E-8,2.80073963620973E-6,-0.400731446051736,1.51876158459689E-8,-2.74687174270508E-10,1.51900996747366E-8,-1.03615341533873,333,5,5,13.4965986394558,-0.640121079016954,0.00078563395081354,4369,0,123.1125946,123.1333923,9998.957,9998.957,,122.8015375,,,,,,,,,,,,,,,,,,,,,,,123.1243772625
,4950802.22,124.1557846,9998.957,1000,10.000870719426,,0.408484858991523,,,,,,,,,,125,1,0,-0.632924127605761,0.000382635817446072,4369,0,124.1402893,124.1712799,9998.957,9998.957,,123.7218,,,,,,,,,,,,,,,,,,,,,,,124.1557846
,4950851.39,124.1369323875,9998.957,1000,10.0003873088824,,1.56678926774381E-8,2.77913384258568E-6,2.45104611518573E-9,2.77913492343069E-6,0.0505317733276482,1.51885253183025E-8,-2.74645928621862E-10,1.51910082526087E-8,-1.03593584474601,333,5,5,13.4965986394558,-0.632924127605761,0.000784084089874427,4369,0,124.1233139,124.1529694,9998.957,9998.957,,123.772,,,,,,,,,,,,,,,,,,,,,,,124.1369323875
,4951176.69,125.1524887,9998.957,1000,10.0006736950467,,0.361006455360493,,,,,,,,,,125,1,0,-0.660109897258812,0.000382452157449666,4369,0,125.1403351,125.1646423,9998.957,9998.957,,124.77295,,,,,,,,,,,,,,,,,,,,,,,125.1524887
,4951223.24,125.1397419,9998.957,1000,10.0001827474195,,1.18850198945569E-8,2.81498763184751E-6,-3.50504518507992E-9,2.81498981397734E-6,-0.0713410567250889,1.51891687165791E-8,-2.74833872889174E-10,1.51916549446856E-8,-1.03660069464172,333,5,5,13.4965986394558,-0.660109897258812,0.000783631719295752,4369,0,125.1221542,125.1532059,9998.957,9998.957,,124.714475,,,,,,,,,,,,,,,,,,,,,,,125.1397419
,4951548.58,126.17453385,9998.957,1000,10.0004134058351,,0.364161477598675,,,,,,,,,,125,1,0,-0.632749698382277,0.000382574961310562,4369,0,126.1656876,126.1833801,9998.957,9998.957,,125.68265,,,,,,,,,,,,,,,,,,,,,,,126.17453385
,4951597.76,126.1556015125,9998.957,1000,9.99989512774831,,1.52066399332704E-8,2.80025647966217E-6,4.91449090513141E-8,2.8006876966159E-6,1.00544605522267,1.51899904266207E-8,-2.7475049276252E-10,1.51924750121269E-8,-1.03623022924785,333,5,5,13.4965986394558,-0.632749698382277,0.000780740481249438,4369,0,126.1499557,126.1627274,9998.957,9998.957,,125.72285,,,,,,,,,,,,,,,,,,,,,,,126.1556015125
,4951920.53,127.1477966,9998.957,1000,10.0003288669726,,0.340685363988274,,,,,,,,,,125,1,0,-0.653426770857712,0.000382592699646025,4369,0,127.1358795,127.1597137,9998.957,9998.957,,126.758,,,,,,,,,,,,,,,,,,,,,,,127.1477966
,4951969.21,127.1459579375,9998.957,1000,9.99997740831014,,1.14550781486868E-8,2.79072243209898E-6,2.03106353638735E-8,2.79079634063995E-6,0.4169863424291,1.51900004641768E-8,-2.74811700873944E-10,1.51924861550909E-8,-1.03646034249186,333,5,5,13.4965986394558,-0.653426770857712,0.000779780668891206,4369,0,127.1367874,127.1578064,9998.957,9998.957,,126.7144,,,,,,,,,,,,,,,,,,,,,,,127.1459579375
,4952294.45,128.1612015,9998.957,1000,10.0001585620697,,0.42538641064497,,,,,,,,,,125,1,0,-0.647055029191502,0.000382553129513069,4369,0,128.1526642,128.1697388,9998.957,9998.957,,127.76175,,,,,,,,,,,,,,,,,,,,,,,128.1612015
,4952343.54,128.14606285,9998.957,1000,9.99958484732514,,1.22500343403193E-8,2.79647662695361E-6,-1.51063731772702E-8,2.79651742844711E-6,-0.30950482461742,1.51912726286669E-8,-2.74372035345922E-10,1.51937501655208E-8,-1.03471585324962,333,5,5,13.4965986394558,-0.647055029191502,0.000779882943978558,4369,0,128.1362915,128.1533508,9998.957,9998.957,,127.7253375,,,,,,,,,,,,,,,,,,,,,,,128.14606285
,4952670.52,129.1538162,9998.957,1000,9.9998965150574,,0.378193913291667,,,,,,,,,,125,1,0,-0.607541524233286,0.000382589970671338,4369,0,129.1429901,129.1646423,9998.957,9998.957,,128.746,,,,,,,,,,,,,,,,,,,,,,,129.1538162
,4952719.77,129.1558876,9998.957,1000,9.9993643297833,,1.08411404988959E-8,2.74083375971841E-6,7.77151838655244E-9,2.74084477760237E-6,0.162459327959508,1.51917559436284E-8,-2.74600847329734E-10,1.51942375352014E-8,-1.03554562550556,333,5,5,13.4965986394558,-0.607541524233286,0.000777849243203124,4369,0,129.1389313,129.1677856,9998.957,9998.957,,128.687875,,,,,,,,,,,,,,,,,,,,,,,129.1558876
,4953043.66,130.1640396,9998.957,1000,9.9996186375055,,0.409482673772741,,,,,,,,,,125,1,0,-0.673119139275024,0.000382639638010634,4369,0,130.1625671,130.1655121,9998.957,9998.957,,129.7251,,,,,,,,,,,,,,,,,,,,,,,130.1640396
,4953093.04,130.1487045375,9998.957,1000,9.99921247146751,,9.95207236985735E-9,2.80439671039505E-6,-1.41443891223459E-8,2.8044323798263E-6,-0.288977278332311,1.51922626850613E-8,-2.74737917975413E-10,1.51947466716454E-8,-1.03602786859028,333,5,5,13.4965986394558,-0.673119139275024,0.000776716349927833,4369,0,130.1344452,130.1578522,9998.957,9998.957,,129.718125,,,,,,,,,,,,,,,,,,,,,,,130.1487045375
,4953417.59,131.16161345,9998.957,1000,9.99949470243821,,0.35165979569103,,,,,,,,,,125,1,0,-0.658762009751973,0.000382658195038502,4369,0,131.1557617,131.1674652,9998.957,9998.957,,130.75725,,,,,,,,,,,,,,,,,,,,,,,131.16161345
,4953465.14,131.1611652375,9998.957,1000,9.99890433053069,,6.46291597709609E-9,2.76916998338772E-6,-2.7128512033233E-8,2.76930286409065E-6,-0.561287147613712,1.51929232922062E-8,-2.74786741710331E-10,1.51954080536286E-8,-1.03616689523028,333,5,5,13.4965986394558,-0.658762009751973,0.000774997341728868,4369,0,131.1496582,131.1734161,9998.957,9998.957,,130.652425,,,,,,,,,,,,,,,,,,,,,,,131.1611652375
,4953790.90,132.1688461,9998.957,1000,9.99933932361461,,0.352607865576727,,,,,,,,,,125,1,0,-0.675058681157824,0.000382623264162514,4369,0,132.1605682,132.177124,9998.957,9998.957,,131.7309,,,,,,,,,,,,,,,,,,,,,,,132.1688461
,4953840.33,132.1612987625,9998.957,1000,9.99882391827865,,1.04747873267294E-8,2.78445446703692E-6,-3.2372135568642E-9,2.78445634883247E-6,-0.0666121830396378,1.51934128516596E-8,-2.74945899463572E-10,1.51959004119073E-8,-1.03673351770743,333,5,5,13.4965986394558,-0.675058681157824,0.00077373857142299,4369,0,132.1542664,132.1710968,9998.957,9998.957,,131.6891125,,,,,,,,,,,,,,,,,,,,,,,132.1612987625
,4954163.17,133.1845627,9998.957,1000,9.99909629154076,,0.415499374772621,,,,,,,,,,125,1,0,-0.66802216915211,0.000382630359496699,4369,0,133.174408,133.1947174,9998.957,9998.957,,132.6893,,,,,,,,,,,,,,,,,,,,,,,133.1845627
,4954214.52,133.18653485,9998.957,1000,9.99834794969168,,8.50609964506553E-9,2.77792541186875E-6,1.38617161188396E-8,2.77795999630663E-6,0.285900850762208,1.51946448808912E-8,-2.75140798391314E-10,1.51971357668257E-8,-1.0373841562112,333,5,5,13.4965986394558,-0.66802216915211,0.000771933022765495,4369,0,133.1772003,133.1959839,9998.957,9998.957,,132.637125,,,,,,,,,,,,,,,,,,,,,,,133.18653485
,4954534.59,134.16812135,9998.957,1000,9.9989936085795,,0.416287061843819,,,,,,,,,,125,1,0,-0.66282033483935,0.000382789458720926,4369,0,134.1588593,134.1773834,9998.957,9998.957,,133.7378,,,,,,,,,,,,,,,,,,,,,,,134.16812135
,4954584.72,134.16542435,9998.957,1000,9.99841357977552,,1.04904491732916E-8,2.73054770400789E-6,6.85102527260249E-9,2.73055629870728E-6,0.143756510529194,1.51944585680484E-8,-2.75093799111409E-10,1.51969486336715E-8,-1.03721970533132,333,5,5,13.4965986394558,-0.66282033483935,0.000771543590702114,4369,0,134.1567688,134.1773834,9998.957,9998.957,,133.6792,,,,,,,,,,,,,,,,,,,,,,,134.16542435
,4954906.96,135.1566467,9998.957,1000,9.99874269359827,,0.352264514226879,,,,,,,,,,125,1,0,-0.638955152432571,0.000382762168974061,4369,0,135.1476898,135.1656036,9998.957,9998.957,,134.76365,,,,,,,,,,,,,,,,,,,,,,,135.1566467
,4954956.08,135.1589946625,9998.957,1000,9.99830921225521,,9.19644594685672E-9,2.71609350729721E-6,-7.76615262841445E-9,2.71610461019245E-6,-0.163825934136355,1.51949818461412E-8,-2.75239856744534E-10,1.51974744705593E-8,-1.03773455337745,333,5,5,13.4965986394558,-0.638955152432571,0.000770040933649472,4369,0,135.1488953,135.1715546,9998.957,9998.957,,134.6603125,,,,,,,,,,,,,,,,,,,,,,,135.1589946625
,4955280.10,136.17505645,9998.957,1000,9.99866777997197,,0.386204594744688,,,,,,,,,,125,1,0,-0.655563226790365,0.000382985672000891,4369,0,136.1682587,136.1818542,9998.957,9998.957,,135.6789,,,,,,,,,,,,,,,,,,,,,,,136.17505645
,4955330.86,136.157993325,9998.957,1000,9.99808732785502,,7.02512325139128E-9,2.75043602239367E-6,-1.40583544336477E-8,2.75047195052233E-6,-0.292854425595692,1.51957186560071E-8,-2.75293139403845E-10,1.51982121246259E-8,-1.03788508421019,333,5,5,13.4965986394558,-0.655563226790365,0.000769218799293445,4369,0,136.1508179,136.1689453,9998.957,9998.957,,135.7109875,,,,,,,,,,,,,,,,,,,,,,,136.157993325
,4955653.18,137.18006895,9998.957,1000,9.9983710584593,,0.348979351042826,,,,,,,,,,125,1,0,-0.64503090893056,0.000382939279431219,4369,0,137.1670532,137.1930847,9998.957,9998.957,,136.75425,,,,,,,,,,,,,,,,,,,,,,,137.18006895
,4955701.67,137.1626625,9998.957,1000,10.0017975754109,,1.2767709661367E-8,2.73691769845791E-6,-1.56220706017601E-9,2.73691814430448E-6,-0.0327038922666247,1.51960906067602E-8,-2.75353907382786E-10,1.51985851151736E-8,-1.03808873188171,333,5,5,13.4965986394558,-0.64503090893056,0.000767609933496244,4369,0,137.1534729,137.1764374,9998.957,9998.957,,136.676175,,,,,,,,,,,,,,,,,,,,,,,137.1626625
,4956025.59,138.17879485,9998.957,1000,9.99823644807749,,0.384385355827099,,,,,,,,,,125,1,0,-0.655397604904635,0.000383063993574396,4369,0,138.16716,138.1904297,9998.957,9998.957,,137.7436,,,,,,,,,,,,,,,,,,,,,,,138.17879485
,4956075.91,138.166042325,9998.957,1000,10.0014672366719,,1.01183859413781E-8,2.75511188470791E-6,-6.49408851946422E-11,2.75511188547327E-6,-0.00135052179166451,1.51969419677218E-8,-2.75571404434951E-10,1.51994402781565E-8,-1.03885033084595,333,5,5,13.4965986394558,-0.655397604904635,0.000766799600111835,4369,0,138.1460724,138.1770935,9998.957,9998.957,,137.6495375,,,,,,,,,,,,,,,,,,,,,,,138.166042325
,4956399.89,139.1703415,9998.957,1000,9.99814477145747,,0.400175973681307,,,,,,,,,,125,1,0,-0.651490895133271,0.000383280947061978,4369,0,139.1672058,139.1734772,9998.957,9998.957,,138.79525,,,,,,,,,,,,,,,,,,,,,,,139.1703415
,4956448.78,139.17969515,9998.957,1000,10.001268411437,,8.30666674720235E-9,2.72625639746219E-6,4.1893344931765E-9,2.72625961625576E-6,0.0880441754195805,1.51976854182722E-8,-2.75541585777002E-10,1.52001830659455E-8,-1.03868714241901,333,5,5,13.4965986394558,-0.651490895133271,0.000765131729456546,4369,0,139.1612244,139.2036591,9998.957,9998.957,,138.5755125,,,,,,,,,,,,,,,,,,,,,,,139.17969515
,4956770.61,140.1898346,9998.957,1000,10.0017245211394,,0.392057138720804,,,,,,,,,,125,1,0,-0.633391394440461,0.000383317242425309,4369,0,140.1798859,140.1997833,9998.957,9998.957,,139.6608,,,,,,,,,,,,,,,,,,,,,,,140.1898346
,4956819.18,140.189905175,9998.957,1000,10.0010350923657,,6.59986429939615E-9,2.72677585271457E-6,2.41175138331082E-9,2.72677691927521E-6,0.0506763837328345,1.51986375645163E-8,-2.7568515414981E-10,1.52011376587986E-8,-1.03916313194395,333,5,5,13.4965986394558,-0.633391394440461,0.000764411870187872,4369,0,140.1813965,140.1976166,9998.957,9998.957,,139.59495,,,,,,,,,,,,,,,,,,,,,,,140.189905175
,4957140.07,141.19436645,9998.957,1000,10.0016128602832,,0.410946020062807,,,,,,,,,,125,1,0,-0.6697807372668,0.000383411119154528,4369,0,141.1928253,141.1959076,9998.957,9998.957,,140.36355,,,,,,,,,,,,,,,,,,,,,,,141.19436645
,4957187.69,141.1507702125,9998.957,1000,10.0010299818911,,1.16160881095E-8,2.73233836484408E-6,-1.81681179657495E-8,2.73239876674493E-6,-0.380970802749346,1.51987574440849E-8,-2.75881717922409E-10,1.52012610847393E-8,-1.03989569318577,333,5,5,13.4965986394558,-0.6697807372668,0.000764793434936842,4369,0,141.1407776,141.1592255,9998.957,9998.957,,140.8104625,,,,,,,,,,,,,,,,,,,,,,,141.1507702125
,4957510.29,142.1674728,9998.957,1000,10.0015458031885,,0.404059953874065,,,,,,,,,,125,1,0,-0.661367364729711,0.000383687291392809,4369,0,142.1573486,142.177597,9998.957,9998.957,,141.813,,,,,,,,,,,,,,,,,,,,,,,142.1674728
,4957560.01,142.1751709125,9998.957,1000,10.0008411548379,,1.48881958357384E-8,2.72366642537783E-6,1.14391422253777E-9,2.72366666559441E-6,0.0240636858508276,1.5199031337603E-8,-2.75757391551725E-10,1.52015326773465E-8,-1.03940843914927,333,5,5,13.4965986394558,-0.661367364729711,0.000761253143451559,4369,0,142.1707001,142.1924896,9998.957,9998.957,,141.57185,,,,,,,,,,,,,,,,,,,,,,,142.1751709125
,4957882.85,143.16942595,9998.957,1000,10.0013784943357,,0.402089263505373,,,,,,,,,,125,1,0,-0.639383652151439,0.000383885414955054,4369,0,143.166275,143.1725769,9998.957,9998.957,,142.811,,,,,,,,,,,,,,,,,,,,,,,143.16942595
,4957932.64,143.1695461375,9998.957,1000,10.0007478156574,,9.97331240603744E-9,2.68595933792856E-6,9.25132683316183E-9,2.68597527018657E-6,0.197344717343166,1.5199928222507E-8,-2.75754781366906E-10,1.5202429367335E-8,-1.03933728561543,333,5,5,13.4965986394558,-0.639383652151439,0.000761052526934059,4369,0,143.1614685,143.1740723,9998.957,9998.957,,142.5938375,,,,,,,,,,,,,,,,,,,,,,,143.1695461375
,4958256.42,144.1667404,9998.957,1000,10.0012552283842,,0.442779181044102,,,,,,,,,,125,1,0,-0.634373431221291,0.000383973015042493,4369,0,144.1434021,144.1900787,9998.957,9998.957,,143.81925,,,,,,,,,,,,,,,,,,,,,,,144.1667404
,4958306.67,144.1699428625,9998.957,1000,10.0005766430918,,1.24716356437922E-8,2.68773299475225E-6,-1.50098577181997E-8,2.68777490629491E-6,-0.319969490924791,1.52002313624738E-8,-2.75918898993726E-10,1.52027354351628E-8,-1.03993498416514,333,5,5,13.4965986394558,-0.634373431221291,0.000758786740383478,4369,0,144.1501923,144.1820984,9998.957,9998.957,,143.5741375,,,,,,,,,,,,,,,,,,,,,,,144.1699428625
,4958658.72,145.17394255,9998.957,1000,10.0010767496931,,0.425609489043138,,,,,,,,,,125,1,0,-0.658116214853389,0.000384071258131209,4369,0,145.1634369,145.1844482,9998.957,9998.957,,144.58885,,,,,,,,,,,,,,,,,,,,,,,145.17394255
,4958708.36,145.1666641,9998.957,1000,10.0006061518194,,1.43836655933346E-8,2.70771774614877E-6,2.30361983868083E-9,2.7077187260632E-6,0.0487449855889907,1.52004242642129E-8,-2.76105650726707E-10,1.52029316956446E-8,-1.040625491078,333,5,5,13.4965986394558,-0.658116214853389,0.000757614510536129,4369,0,145.1509094,145.1816101,9998.957,9998.957,,144.6725625,,,,,,,,,,,,,,,,,,,,,,,145.1666641
,4959065.61,146.17754365,9998.957,1000,10.0009682813722,,0.403164036755185,,,,,,,,,,125,1,0,-0.637208785071417,0.000384158858218648,4369,0,146.1636505,146.1914368,9998.957,9998.957,,145.5118,,,,,,,,,,,,,,,,,,,,,,,146.17754365
,4959114.41,146.1661929875,9998.957,1000,10.0003861677994,,1.09117332595312E-8,2.67877913164947E-6,-1.1007730992271E-8,2.67880174822668E-6,-0.235440455137621,1.52011678883976E-8,-2.76266450300201E-10,1.52036781182322E-8,-1.04118047688962,333,5,5,13.4965986394558,-0.637208785071417,0.000756961523439955,4369,0,146.154541,146.1741638,9998.957,9998.957,,145.6942625,,,,,,,,,,,,,,,,,,,,,,,146.1661929875
,4959533.85,147.20317075,9998.957,1000,10.0006538502628,,0.381592917976776,,,,,,,,,,125,1,0,-0.613130251074876,0.000384590854911533,4369,0,147.1921539,147.2141876,9998.957,9998.957,,146.6662,,,,,,,,,,,,,,,,,,,,,,,147.20317075
,4959583.36,147.2033043125,9998.957,1000,10.000014706443,,1.11805464975526E-8,2.71311353297654E-6,1.68617654522398E-8,2.713165929676E-6,0.356083719096417,1.52019837850525E-8,-2.76205107678035E-10,1.52044927657094E-8,-1.04089348658744,333,5,5,13.4965986394558,-0.613130251074876,0.000752363078166293,4369,0,147.1949768,147.2102051,9998.957,9998.957,,146.4588375,,,,,,,,,,,,,,,,,,,,,,,147.2033043125
,4960009.97,148.18448635,9998.957,1000,10.0005341075231,,0.394318602485177,,,,,,,,,,125,1,0,-0.628590645531745,0.000384871393509312,4369,0,148.1843414,148.1846313,9998.957,9998.957,,147.65625,,,,,,,,,,,,,,,,,,,,,,,148.18448635
,4960059.44,148.1731834625,9998.957,1000,10.0001694620104,,1.41024754997116E-8,2.65759673901547E-6,-3.6576729281438E-8,2.65784843141038E-6,-0.78851688698154,1.52021429114561E-8,-2.76492646009653E-10,1.5204657091945E-8,-1.04196594679723,333,5,5,13.4965986394558,-0.628590645531745,0.000751725825698942,4369,0,148.1668854,148.1778564,9998.957,9998.957,,147.5483625,,,,,,,,,,,,,,,,,,,,,,,148.1731834625
,4960491.94,149.1703491,9998.957,1000,10.0006508919879,,0.396449970785334,,,,,,,,,,125,1,0,-0.661248962725019,0.000384901685128333,4369,0,149.1581268,149.1825714,9998.957,9998.957,,148.7339,,,,,,,,,,,,,,,,,,,,,,,149.1703491
,4960541.05,149.1770400875,9998.957,1000,10.0000335516868,,9.09666505330735E-9,2.73076030863183E-6,-9.3682211346704E-9,2.7307763780226E-6,-0.196559699925274,1.52022954831549E-8,-2.76410371729239E-10,1.5204808142517E-8,-1.04164551162609,333,5,5,13.4965986394558,-0.661248962725019,0.000750644069967328,4369,0,149.1707153,149.1886749,9998.957,9998.957,,148.48415,,,,,,,,,,,,,,,,,,,,,,,149.1770400875
,4960966.82,150.17929075,9998.957,1000,10.0005314915305,,0.39555066488292,,,,,,,,,,125,1,0,-0.616377093426025,0.000385304481792071,4369,0,150.1677246,150.1908569,9998.957,9998.957,,149.6898,,,,,,,,,,,,,,,,,,,,,,,150.17929075
,4961016.33,150.174133275,9998.957,1000,9.99999661105966,,1.31697241451862E-8,2.64678463920609E-6,-1.0704144707633E-8,2.64680628400555E-6,-0.231714723724963,1.52026492637359E-8,-2.76368694537828E-10,1.52051611070547E-8,-1.04146425565716,333,5,5,13.4965986394558,-0.616377093426025,0.000749385299661449,4369,0,150.1623535,150.1904449,9998.957,9998.957,,149.58815,,,,,,,,,,,,,,,,,,,,,,,150.174133275
,4961045.76,150.144807825,9998.957,10000,10.0015793611,,8.76643683600595E-9,2.63476104919922E-6,8.37967224357361E-8,2.63609326031313E-6,1.82163793959257,1.49976536935726E-8,-3.29528415723884E-9,1.53554066696158E-8,-12.3921142982641,588,5,5,13.4965986394558,-0.616377093426025,0.0044794638036682,4369,0,150.1359253,150.1540985,9998.957,9998.957,,149.7999375,,,,,,,,,,,,,,,,,,,,,,,150.144807825