File: debug/squid_MvT.dat
[Header]
TITLE,MPMS RSO Measurement
BYAPP,MPMS Measurement,1.1,Summary
FILEOPENTIME, 1222958089.968000 10/2/2008, 4:34:49 PM

INFO, APPNAME, MPMS MultiVu Application, Revision 1.56,  Build 72

INFO, NAME, TbMnO3 TF on LaAlO3
INFO, WEIGHT, 1.000
INFO, AREA, 1.000
INFO, LENGTH, 1.000
INFO, SHAPE, Rectangular
INFO, COMMENT, Probe von Joost 7125
INFO, SEQUENCE FILE: RSO-0Field-2K-300K.seq


INFO, BACKGROUND DATA FILE:, None


STARTUPAXIS,X,4,LINEAR,AUTO,0.000000,0.000000
STARTUPAXIS,Y1,5,LINEAR,AUTO,0.000000,0.000000


STARTUPGROUP,Longitudinal
FIELDGROUP,Longitudinal,1,2,3,4,5,6,7,8,9,10,11,19,20,21,22,23,35
FIELDGROUP,Transverse,1,2,3,4,12,13,14,15,16,17,18,24,25,26,27,28,35

PLOT_APPEARANCE,ALL,HORZ_GRID_ON,VERT_GRID_ON,MARKERS_AND_LINES

[Data]
Time,Comment,Field (Oe),Temperature (K),Long Moment (emu),Long Scan Std Dev,Long Offset (cm),Long Offset Std Dev,Long Algorithm,Long Reg Fit,Long Reg Factor,Trans Moment (emu),Trans Scan Std Dev,Trans Offset (cm),Trans Offset Std Dev,Trans Algorithm,Trans Reg Fit,Trans Reg Factor,Long Moment [w/o ABS] (emu),Long Scan Std Dev [w/o ABS],Long Offset [w/o ABS] (cm),Long Offset Std Dev [w/o ABS],Long Reg Fit [w/o ABS],Trans Moment [w/o ABS] (emu),Trans Scan Std Dev [w/o ABS],Trans Offset [w/o ABS] (cm),Trans Offset Std Dev [w/o ABS],Trans Reg Fit [w/o ABS],RSO Position (deg),Amplitude (cm),Frequency,Cycles to Average,Scans per Measurement,Delta Temp (K),Error,EC Comp. Running,Using ABS,
1222958089.968,,1.000000e+002,2.001253e+000,-3.026976e-006,1.252531e-008,7.701983e-002,1.922640e-003,3,9.147719e-001,1.825000e+000,,,,,,,,,,,,,,,,,,0,5.000000e+000,1.000000e+000,3,3,3.708959e-003,0,,0,
1222958636.718,,1.000000e+002,4.081511e+000,-3.591066e-006,1.074305e-008,8.114502e-002,1.330385e-003,3,9.130038e-001,1.825000e+000,,,,,,,,,,,,,,,,,,0,5.000000e+000,1.000000e+000,3,3,1.495352e-001,0,,0,
1222959091.531,,1.000000e+002,6.076933e+000,-3.835069e-006,1.237543e-008,8.065060e-002,1.076273e-003,3,9.143746e-001,1.825000e+000,,,,,,,,,,,,,,,,,,0,5.000000e+000,1.000000e+000,3,3,1.287580e-001,0,,0,
1222959563.375,,1.000000e+002,8.053967e+000,-3.919983e-006,1.885624e-008,7.860091e-002,7.251054e-004,3,9.122021e-001,1.825000e+000,,,,,,,,,,,,,,,,,,0,5.000000e+000,1.000000e+000,3,3,9.980202e-002,0,,0,
1222960043.750,,1.000000e+002,1.005454e+001,-3.981968e-006,7.324767e-009,7.845037e-002,1.027155e-003,3,9.125627e-001,1.825000e+000,,,,,,,,,,,,,,,,,,0,5.000000e+000,1.000000e+000,3,3,1.000795e-001,0,,0,
1222960546.421,,1.000000e+002,1.205096e+001,-4.009221e-006,1.884148e-008,8.099386e-002,1.308205e-003,3,9.129089e-001,1.825000e+000,,,,,,,,,,,,,,,,,,0,5.000000e+000,1.000000e+000,3,3,9.805965e-002,0,,0,
1222961024.734,,1.000000e+002,1.405815e+001,-4.035033e-006,2.227967e-008,7.821641e-002,1.340336e-003,3,9.151942e-001,1.825000e+000,,,,,,,,,,,,,,,,,,0,5.000000e+000,1.000000e+000,3,3,1.183901e-001,0,,0,
1222961500.796,,1.000000e+002,1.605240e+001,-4.007318e-006,1.121026e-008,7.754136e-002,1.367558e-003,3,9.133021e-001,1.825000e+000,,,,,,,,,,,,,,,,,,0,5.000000e+000,1.000000e+000,3,3,9.964943e-002,0,,0,
1222961981.906,,1.000000e+002,1.805863e+001,-3.951307e-006,1.122243e-008,7.115392e-002,4.245103e-004,3,9.144066e-001,1.825000e+000,,,,,,,,,,,,,,,,,,0,5.000000e+000,1.000000e+000,3,3,1.034813e-001,0,,0,
1222962462.265,,1.000000e+002,2.005640e+001,-3.860353e-006,1.045498e-008,6.534693e-002,5.032374e-004,3,9.096410e-001,1.825000e+000,,,,,,,,,,,,,,,,,,0,5.000000e+000,1.000000e+000,3,3,9.475899e-002,0,,0,
1222962941.468,,1.000000e+002,2.205420e+001,-3.712143e-006,9.386034e-009,5.563129e-002,3.653797e-003,3,9.088311e-001,1.825000e+000,,,,,,,,,,,,,,,,,,0,5.000000e+000,1.000000e+000,3,3,1.000595e-001,0,,0,
1222963422.078,,1.000000e+002,2.405952e+001,-3.547434e-006,7.859178e-009,4.934929e-002,3.094140e-003,3,9.082095e-001,1.825000e+000,,,,,,,,,,,,,,,,,,0,5.000000e+000,1.000000e+000,3,3,1.006413e-001,0,,0,
1222963905.937,,1.000000e+002,2.607340e+001,-3.389008e-006,9.936869e-009,3.590787e-002,2.724028e-003,3,9.052629e-001,1.825000e+000,,,,,,,,,,,,,,,,,,0,5.000000e+000,1.000000e+000,3,3,1.178894e-001,0,,0,
1222964385.578,,1.000000e+002,2.807261e+001,-3.236700e-006,9.280176e-009,2.700105e-002,1.288287e-003,3,9.031728e-001,1.825000e+000,,,,,,,,,,,,,,,,,,0,5.000000e+000,1.000000e+000,3,3,1.170311e-001,0,,0,
1222964860.484,,1.000000e+002,3.005480e+001,-3.123663e-006,6.454856e-009,1.423468e-002,1.056236e-003,3,9.003606e-001,1.825000e+000,,,,,,,,,,,,,,,,,,0,5.000000e+000,1.000000e+000,3,3,9.939957e-002,0,,0,
1222965343.796,,1.000000e+002,3.206816e+001,-3.038244e-006,7.192146e-009,8.123164e-003,1.479965e-003,3,8.980680e-001,1.825000e+000,,,,,,,,,,,,,,,,,,0,5.000000e+000,1.000000e+000,3,3,1.137123e-001,0,,0,
1222965820.906,,1.000000e+002,3.405880e+001,-2.961555e-006,6.833373e-009,1.136306e-003,2.375512e-003,3,8.992805e-001,1.825000e+000,,,,,,,,,,,,,,,,,,0,5.000000e+000,1.000000e+000,3,3,9.918213e-002,0,,0,
1222966300.734,,1.000000e+002,3.605822e+001,-2.933931e-006,5.932875e-009,-4.606440e-003,3.737797e-003,3,8.991106e-001,1.825000e+000,,,,,,,,,,,,,,,,,,0,5.000000e+000,1.000000e+000,3,3,1.016388e-001,0,,0,
1222966779.843,,1.000000e+002,3.805499e+001,-2.905124e-006,2.033879e-008,-8.198960e-003,6.864762e-004,3,8.972895e-001,1.825000e+000,,,,,,,,,,,,,,,,,,0,5.000000e+000,1.000000e+000,3,3,1.017303e-001,0,,0,
1222967259.500,,1.000000e+002,4.005120e+001,-2.903832e-006,8.286537e-009,-8.039805e-003,4.795864e-003,3,9.002399e-001,1.825000e+000,,,,,,,,,,,,,,,,,,0,5.000000e+000,1.000000e+000,3,3,9.286118e-002,0,,0,
1222967745.843,,1.000000e+002,4.206630e+001,-2.914708e-006,9.799510e-009,-6.851610e-003,1.552765e-003,3,9.025251e-001,1.825000e+000,,,,,,,,,,,,,,,,,,0,5.000000e+000,1.000000e+000,3,3,1.301117e-001,0,,0,
1222968227.781,,1.000000e+002,4.406661e+001,-2.886369e-006,1.334952e-008,-7.297723e-004,1.358629e-003,3,9.010126e-001,1.825000e+000,,,,,,,,,,,,,,,,,,0,5.000000e+000,1.000000e+000,3,3,1.307297e-001,0,,0,
1222968701.281,,1.000000e+002,4.605959e+001,-2.826559e-006,8.690848e-009,2.272645e-003,3.997120e-003,3,9.014645e-001,1.825000e+000,,,,,,,,,,,,,,,,,,0,5.000000e+000,1.000000e+000,3,3,9.836960e-002,0,,0,
1222969189.343,,1.000000e+002,4.806830e+001,-2.818422e-006,8.408295e-009,4.983374e-003,1.077615e-004,3,9.044154e-001,1.825000e+000,,,,,,,,,,,,,,,,,,0,5.000000e+000,1.000000e+000,3,3,1.280403e-001,0,,0,
1222969660.046,,1.000000e+002,5.005198e+001,-2.856371e-006,5.766498e-009,4.203195e-003,3.662813e-003,3,9.012194e-001,1.825000e+000,,,,,,,,,,,,,,,,,,0,5.000000e+000,1.000000e+000,3,3,9.436035e-002,0,,0,
1222970143.218,,1.000000e+002,5.205651e+001,-2.903585e-006,8.409514e-009,5.414448e-003,2.690219e-003,3,9.048497e-001,1.825000e+000,,,,,,,,,,,,,,,,,,0,5.000000e+000,1.000000e+000,3,3,1.194992e-001,0,,0,
1222970622.562,,1.000000e+002,5.406735e+001,-2.952814e-006,1.927671e-008,3.028218e-003,2.023286e-003,3,9.048069e-001,1.825000e+000,,,,,,,,,,,,,,,,,,0,5.000000e+000,1.000000e+000,3,3,9.178925e-002,0,,0,
1222971104.390,,1.000000e+002,5.607091e+001,-2.978969e-006,6.798166e-009,-4.474461e-004,2.290096e-003,3,9.043337e-001,1.825000e+000,,,,,,,,,,,,,,,,,,0,5.000000e+000,1.000000e+000,3,3,1.202507e-001,0,,0,
1222971585.718,,1.000000e+002,5.807256e+001,-2.994847e-006,9.924332e-009,3.177414e-004,8.978457e-004,3,9.044652e-001,1.825000e+000,,,,,,,,,,,,,,,,,,0,5.000000e+000,1.000000e+000,3,3,1.124992e-001,0,,0,
1222972062.031,,1.000000e+002,6.005983e+001,-3.027274e-006,5.302382e-009,2.762646e-004,4.523278e-003,3,9.016130e-001,1.825000e+000,,,,,,,,,,,,,,,,,,0,5.000000e+000,1.000000e+000,3,3,9.402084e-002,0,,0,
1222972546.140,,1.000000e+002,6.207557e+001,-3.051939e-006,8.681300e-009,-1.871186e-004,7.047202e-004,3,9.023777e-001,1.825000e+000,,,,,,,,,,,,,,,,,,0,5.000000e+000,1.000000e+000,3,3,1.149292e-001,0,,0,
1222973018.718,,1.000000e+002,6.405116e+001,-3.064578e-006,5.328435e-009,9.261906e-006,2.137548e-003,3,9.064908e-001,1.825000e+000,,,,,,,,,,,,,,,,,,0,5.000000e+000,1.000000e+000,3,3,9.506989e-002,0,,0,
1222973501.187,,1.000000e+002,6.605915e+001,-3.092352e-006,1.597240e-008,7.989168e-004,2.120432e-004,3,9.052195e-001,1.825000e+000,,,,,,,,,,,,,,,,,,0,5.000000e+000,1.000000e+000,3,3,9.391785e-002,0,,0,
1222973980.031,,1.000000e+002,6.806268e+001,-3.113470e-006,1.431724e-008,-2.556010e-004,1.346284e-003,3,9.045566e-001,1.825000e+000,,,,,,,,,,,,,,,,,,0,5.000000e+000,1.000000e+000,3,3,9.898376e-002,0,,0,
1222974459.937,,1.000000e+002,7.005555e+001,-3.130103e-006,7.952377e-009,5.620549e-004,8.801573e-004,3,9.035137e-001,1.825000e+000,,,,,,,,,,,,,,,,,,0,5.000000e+000,1.000000e+000,3,3,8.506012e-002,0,,0,
1222974937.562,,1.000000e+002,7.204137e+001,-3.143038e-006,2.452842e-009,-1.315626e-003,1.511752e-003,3,9.046928e-001,1.825000e+000,,,,,,,,,,,,,,,,,,0,5.000000e+000,1.000000e+000,3,3,9.150696e-002,0,,0,
1222975418.187,,1.000000e+002,7.404865e+001,-3.153218e-006,1.798598e-008,-1.655990e-003,1.318590e-003,3,9.062352e-001,1.825000e+000,,,,,,,,,,,,,,,,,,0,5.000000e+000,1.000000e+000,3,3,8.796692e-002,0,,0,
1222975900.312,,1.000000e+002,7.605273e+001,-3.169594e-006,6.145668e-009,-1.874877e-003,2.871107e-003,3,9.034105e-001,1.825000e+000,,,,,,,,,,,,,,,,,,0,5.000000e+000,1.000000e+000,3,3,1.081924e-001,0,,0,
1222976383.218,,1.000000e+002,7.806008e+001,-3.176061e-006,5.832403e-009,-1.358084e-003,6.992283e-004,3,9.060829e-001,1.825000e+000,,,,,,,,,,,,,,,,,,0,5.000000e+000,1.000000e+000,3,3,1.101074e-001,0,,0,
1222976862.187,,1.000000e+002,8.006187e+001,-3.186329e-006,1.150856e-008,-2.887867e-003,3.627594e-003,3,9.079076e-001,1.825000e+000,,,,,,,,,,,,,,,,,,0,5.000000e+000,1.000000e+000,3,3,1.063461e-001,0,,0,
1222977340.234,,1.000000e+002,8.205245e+001,-3.186287e-006,1.342099e-008,-9.088396e-004,6.719760e-004,3,9.059893e-001,1.825000e+000,,,,,,,,,,,,,,,,,,0,5.000000e+000,1.000000e+000,3,3,8.641815e-002,0,,0,
1222977820.968,,1.000000e+002,8.406036e+001,-3.191939e-006,1.065075e-008,-1.069858e-003,1.425806e-003,3,9.074479e-001,1.825000e+000,,,,,,,,,,,,,,,,,,0,5.000000e+000,1.000000e+000,3,3,8.705139e-002,0,,0,
1222978310.546,,1.000000e+002,8.608358e+001,-3.197381e-006,1.090122e-009,-1.554447e-003,1.518935e-003,3,9.091176e-001,1.825000e+000,,,,,,,,,,,,,,,,,,0,5.000000e+000,1.000000e+000,3,3,1.009140e-001,0,,0,
1222978783.500,,1.000000e+002,8.805802e+001,-3.191118e-006,1.013988e-008,-1.001270e-003,4.765724e-003,3,9.074048e-001,1.825000e+000,,,,,,,,,,,,,,,,,,0,5.000000e+000,1.000000e+000,3,3,1.191635e-001,0,,0,
1222979264.171,,1.000000e+002,9.005869e+001,-3.194960e-006,1.971250e-009,-2.327176e-003,2.405880e-003,3,9.077117e-001,1.825000e+000,,,,,,,,,,,,,,,,,,0,5.000000e+000,1.000000e+000,3,3,9.471130e-002,0,,0,
1222979744.171,,1.000000e+002,9.205932e+001,-3.189844e-006,1.210999e-008,-2.104340e-003,9.117788e-004,3,9.099289e-001,1.825000e+000,,,,,,,,,,,,,,,,,,0,5.000000e+000,1.000000e+000,3,3,1.059036e-001,0,,0,
1222980213.671,,1.000000e+002,9.403048e+001,-3.201825e-006,4.425269e-009,-3.312698e-003,1.031690e-003,3,9.095600e-001,1.825000e+000,,,,,,,,,,,,,,,,,,0,5.000000e+000,1.000000e+000,3,3,1.059418e-001,0,,0,
1222980701.890,,1.000000e+002,9.605271e+001,-3.195304e-006,1.627036e-008,-1.841184e-003,2.911044e-003,3,9.067439e-001,1.825000e+000,,,,,,,,,,,,,,,,,,0,5.000000e+000,1.000000e+000,3,3,1.221466e-001,0,,0,
1222981183.625,,1.000000e+002,9.806991e+001,-3.204139e-006,7.877404e-009,2.213788e-004,1.303397e-003,3,9.070129e-001,1.825000e+000,,,,,,,,,,,,,,,,,,0,5.000000e+000,1.000000e+000,3,3,1.012650e-001,0,,0,
1222981658.406,,1.000000e+002,1.000512e+002,-3.208193e-006,2.166673e-009,-2.672164e-004,1.723792e-003,3,9.074970e-001,1.825000e+000,,,,,,,,,,,,,,,,,,0,5.000000e+000,1.000000e+000,3,3,1.267090e-001,0,,0,
1222982134.265,,1.000000e+002,1.020541e+002,-3.218474e-006,8.751970e-009,-8.942281e-004,1.378759e-003,3,9.077204e-001,1.825000e+000,,,,,,,,,,,,,,,,,,0,5.000000e+000,1.000000e+000,3,3,1.084976e-001,0,,0,
1222982617.875,,1.000000e+002,1.040632e+002,-3.215061e-006,8.072246e-009,-1.992642e-003,2.073925e-003,3,9.074159e-001,1.825000e+000,,,,,,,,,,,,,,,,,,0,5.000000e+000,1.000000e+000,3,3,1.121979e-001,0,,0,
1222983098.203,,1.000000e+002,1.060330e+002,-3.207769e-006,1.062981e-008,-5.223873e-003,1.184579e-003,3,9.078940e-001,1.825000e+000,,,,,,,,,,,,,,,,,,0,5.000000e+000,1.000000e+000,3,3,9.180450e-002,0,,0,
1222983575.796,,1.000000e+002,1.080465e+002,-3.194830e-006,4.027274e-009,-3.081564e-003,1.140298e-003,3,9.093043e-001,1.825000e+000,,,,,,,,,,,,,,,,,,0,5.000000e+000,1.000000e+000,3,3,8.990479e-002,0,,0,
1222984055.421,,1.000000e+002,1.100588e+002,-3.201513e-006,1.502617e-008,-2.306436e-003,1.866727e-003,3,9.072388e-001,1.825000e+000,,,,,,,,,,,,,,,,,,0,5.000000e+000,1.000000e+000,3,3,6.700134e-002,0,,0,
1222984536.625,,1.000000e+002,1.120538e+002,-3.200746e-006,1.262851e-008,-2.126406e-003,7.309073e-004,3,9.078891e-001,1.825000e+000,,,,,,,,,,,,,,,,,,0,5.000000e+000,1.000000e+000,3,3,9.570313e-002,0,,0,
1222985012.359,,1.000000e+002,1.140465e+002,-3.204362e-006,9.728619e-009,-4.354086e-003,1.682789e-003,3,9.071266e-001,1.825000e+000,,,,,,,,,,,,,,,,,,0,5.000000e+000,1.000000e+000,3,3,7.139587e-002,0,,0,
1222985486.953,,1.000000e+002,1.160170e+002,-3.212549e-006,9.085565e-009,-3.543915e-003,1.646866e-003,3,9.085386e-001,1.825000e+000,,,,,,,,,,,,,,,,,,0,5.000000e+000,1.000000e+000,3,3,8.489990e-002,0,,0,
1222985968.843,,1.000000e+002,1.180245e+002,-3.209772e-006,1.056781e-008,-4.226716e-003,1.172958e-003,3,9.084499e-001,1.825000e+000,,,,,,,,,,,,,,,,,,0,5.000000e+000,1.000000e+000,3,3,1.342926e-001,0,,0,
1222986452.875,,1.000000e+002,1.200448e+002,-3.196784e-006,7.211706e-009,-4.323232e-003,2.086486e-003,3,9.087390e-001,1.825000e+000,,,,,,,,,,,,,,,,,,0,5.000000e+000,1.000000e+000,3,3,1.024017e-001,0,,0,
1222986928.734,,1.000000e+002,1.220272e+002,-3.202638e-006,1.214725e-008,-3.131940e-003,3.050991e-003,3,9.117640e-001,1.825000e+000,,,,,,,,,,,,,,,,,,0,5.000000e+000,1.000000e+000,3,3,8.059692e-002,0,,0,
1222987409.765,,1.000000e+002,1.240346e+002,-3.213009e-006,7.359878e-009,-3.768232e-003,2.523446e-003,3,9.093845e-001,1.825000e+000,,,,,,,,,,,,,,,,,,0,5.000000e+000,1.000000e+000,3,3,5.110168e-002,0,,0,
1222987890.031,,1.000000e+002,1.260372e+002,-3.205004e-006,1.036645e-008,-2.920619e-003,2.297100e-003,3,9.081089e-001,1.825000e+000,,,,,,,,,,,,,,,,,,0,5.000000e+000,1.000000e+000,3,3,1.184006e-001,0,,0,
1222988368.531,,1.000000e+002,1.280400e+002,-3.223552e-006,2.287803e-009,-4.714211e-003,4.387366e-004,3,9.083989e-001,1.825000e+000,,,,,,,,,,,,,,,,,,0,5.000000e+000,1.000000e+000,3,3,8.110046e-002,0,,0,
1222988850.093,,1.000000e+002,1.300370e+002,-3.214017e-006,1.242318e-008,-3.116888e-003,7.879423e-004,3,9.110063e-001,1.825000e+000,,,,,,,,,,,,,,,,,,0,5.000000e+000,1.000000e+000,3,3,1.108093e-001,0,,0,
1222989333.281,,1.000000e+002,1.320338e+002,-3.209125e-006,9.186417e-009,-3.688809e-003,1.554303e-003,3,9.101198e-001,1.825000e+000,,,,,,,,,,,,,,,,,,0,5.000000e+000,1.000000e+000,3,3,1.349030e-001,0,,0,
1222989812.656,,1.000000e+002,1.340359e+002,-3.205767e-006,7.816439e-009,-5.314474e-003,1.235347e-003,3,9.085115e-001,1.825000e+000,,,,,,,,,,,,,,,,,,0,5.000000e+000,1.000000e+000,3,3,1.163025e-001,0,,0,
1222990286.234,,1.000000e+002,1.360456e+002,-3.208824e-006,5.972798e-009,-5.714036e-003,3.217622e-003,3,9.092583e-001,1.825000e+000,,,,,,,,,,,,,,,,,,0,5.000000e+000,1.000000e+000,3,3,5.960083e-002,0,,0,
1222990774.078,,1.000000e+002,1.380629e+002,-3.210147e-006,6.592836e-009,-5.555946e-003,2.728563e-003,3,9.098564e-001,1.825000e+000,,,,,,,,,,,,,,,,,,0,5.000000e+000,1.000000e+000,3,3,6.100464e-002,0,,0,
1222991253.843,,1.000000e+002,1.400625e+002,-3.205633e-006,1.277147e-008,-6.694305e-003,1.295824e-003,3,9.092137e-001,1.825000e+000,,,,,,,,,,,,,,,,,,0,5.000000e+000,1.000000e+000,3,3,1.016083e-001,0,,0,
1222991727.906,,1.000000e+002,1.420381e+002,-3.217457e-006,4.962880e-009,-5.427913e-003,5.825367e-004,3,9.118425e-001,1.825000e+000,,,,,,,,,,,,,,,,,,0,5.000000e+000,1.000000e+000,3,3,9.599304e-002,0,,0,
1222992205.562,,1.000000e+002,1.440402e+002,-3.215762e-006,6.409066e-009,-7.311451e-003,2.571501e-003,3,9.100102e-001,1.825000e+000,,,,,,,,,,,,,,,,,,0,5.000000e+000,1.000000e+000,3,3,7.789612e-002,0,,0,
1222992693.343,,1.000000e+002,1.460694e+002,-3.221456e-006,6.874797e-009,-6.517345e-003,9.941482e-004,3,9.082502e-001,1.825000e+000,,,,,,,,,,,,,,,,,,0,5.000000e+000,1.000000e+000,3,3,9.680176e-002,0,,0,
1222993170.578,,1.000000e+002,1.480634e+002,-3.210035e-006,2.816952e-009,-7.595851e-003,1.707383e-003,3,9.100780e-001,1.825000e+000,,,,,,,,,,,,,,,,,,0,5.000000e+000,1.000000e+000,3,3,1.207123e-001,0,,0,
1222993646.171,,1.000000e+002,1.500435e+002,-3.207906e-006,4.907196e-009,-7.136575e-003,2.163152e-003,3,9.087142e-001,1.825000e+000,,,,,,,,,,,,,,,,,,0,5.000000e+000,1.000000e+000,3,3,1.104889e-001,0,,0,
1222994133.796,,1.000000e+002,1.520518e+002,-3.223309e-006,9.723306e-009,-6.320019e-003,2.767991e-003,3,9.102225e-001,1.825000e+000,,,,,,,,,,,,,,,,,,0,5.000000e+000,1.000000e+000,3,3,1.177063e-001,0,,0,
1222994606.343,,1.000000e+002,1.540455e+002,-3.224681e-006,3.650471e-009,-7.605066e-003,1.076084e-003,3,9.075549e-001,1.825000e+000,,,,,,,,,,,,,,,,,,0,5.000000e+000,1.000000e+000,3,3,7.420349e-002,0,,0,
1222995088.187,,1.000000e+002,1.560303e+002,-3.227224e-006,1.178707e-008,-5.387945e-003,3.273805e-003,3,9.082721e-001,1.825000e+000,,,,,,,,,,,,,,,,,,0,5.000000e+000,1.000000e+000,3,3,1.330109e-001,0,,0,
1222995562.546,,1.000000e+002,1.580435e+002,-3.216624e-006,8.795166e-009,-5.876865e-003,2.886431e-003,3,9.086328e-001,1.825000e+000,,,,,,,,,,,,,,,,,,0,5.000000e+000,1.000000e+000,3,3,8.749390e-002,0,,0,
1222996044.578,,1.000000e+002,1.600323e+002,-3.231120e-006,3.346664e-009,-6.672898e-003,1.149232e-003,3,9.092041e-001,1.825000e+000,,,,,,,,,,,,,,,,,,0,5.000000e+000,1.000000e+000,3,3,1.394043e-001,0,,0,
1222996527.265,,1.000000e+002,1.620493e+002,-3.233521e-006,5.012729e-009,-7.250126e-003,3.947100e-003,3,9.101551e-001,1.825000e+000,,,,,,,,,,,,,,,,,,0,5.000000e+000,1.000000e+000,3,3,1.069031e-001,0,,0,
1222997011.593,,1.000000e+002,1.640569e+002,-3.233679e-006,1.505889e-008,-6.969828e-003,2.408880e-003,3,9.086270e-001,1.825000e+000,,,,,,,,,,,,,,,,,,0,5.000000e+000,1.000000e+000,3,3,1.405945e-001,0,,0,
1222997485.968,,1.000000e+002,1.660402e+002,-3.237774e-006,1.584763e-008,-8.135771e-003,4.377839e-003,3,9.109651e-001,1.825000e+000,,,,,,,,,,,,,,,,,,0,5.000000e+000,1.000000e+000,3,3,9.049988e-002,0,,0,
1222997973.718,,1.000000e+002,1.680550e+002,-3.236694e-006,1.012810e-008,-8.441666e-003,6.532256e-004,3,9.091905e-001,1.825000e+000,,,,,,,,,,,,,,,,,,0,5.000000e+000,1.000000e+000,3,3,1.196899e-001,0,,0,
1222998447.656,,1.000000e+002,1.700447e+002,-3.239026e-006,2.562352e-009,-1.008328e-002,2.066449e-003,3,9.102684e-001,1.825000e+000,,,,,,,,,,,,,,,,,,0,5.000000e+000,1.000000e+000,3,3,1.167908e-001,0,,0,
1222998934.140,,1.000000e+002,1.720598e+002,-3.236833e-006,2.336585e-009,-7.435712e-003,1.505723e-003,3,9.096543e-001,1.825000e+000,,,,,,,,,,,,,,,,,,0,5.000000e+000,1.000000e+000,3,3,9.089661e-002,0,,0,
1222999409.234,,1.000000e+002,1.740524e+002,-3.237013e-006,8.985647e-009,-1.055740e-002,1.366659e-003,3,9.100213e-001,1.825000e+000,,,,,,,,,,,,,,,,,,0,5.000000e+000,1.000000e+000,3,3,1.161041e-001,0,,0,
1222999884.156,,1.000000e+002,1.760364e+002,-3.238092e-006,8.252854e-009,-9.428299e-003,1.175345e-003,3,9.100930e-001,1.825000e+000,,,,,,,,,,,,,,,,,,0,5.000000e+000,1.000000e+000,3,3,7.110596e-002,0,,0,
1223000371.843,,1.000000e+002,1.780441e+002,-3.232777e-006,2.898479e-009,-9.090393e-003,1.482741e-003,3,9.108784e-001,1.825000e+000,,,,,,,,,,,,,,,,,,0,5.000000e+000,1.000000e+000,3,3,8.459473e-002,0,,0,
1223000847.937,,1.000000e+002,1.800491e+002,-3.231924e-006,5.992221e-009,-1.037598e-002,3.521372e-003,3,9.077873e-001,1.825000e+000,,,,,,,,,,,,,,,,,,0,5.000000e+000,1.000000e+000,3,3,6.790161e-002,0,,0,
1223001330.109,,1.000000e+002,1.820529e+002,-3.238382e-006,4.260139e-009,-1.031492e-002,2.026741e-003,3,9.093004e-001,1.825000e+000,,,,,,,,,,,,,,,,,,0,5.000000e+000,1.000000e+000,3,3,1.197052e-001,0,,0,
1223001809.718,,1.000000e+002,1.840522e+002,-3.246853e-006,1.187789e-008,-1.036735e-002,8.862202e-004,3,9.124525e-001,1.825000e+000,,,,,,,,,,,,,,,,,,0,5.000000e+000,1.000000e+000,3,3,7.069397e-002,0,,0,
1223002296.953,,1.000000e+002,1.860648e+002,-3.247265e-006,9.223750e-009,-1.043058e-002,1.027577e-003,3,9.079374e-001,1.825000e+000,,,,,,,,,,,,,,,,,,0,5.000000e+000,1.000000e+000,3,3,1.181030e-001,0,,0,
1223002772.828,,1.000000e+002,1.880547e+002,-3.244181e-006,6.121916e-009,-1.067810e-002,1.608134e-003,3,9.092987e-001,1.825000e+000,,,,,,,,,,,,,,,,,,0,5.000000e+000,1.000000e+000,3,3,8.700562e-002,0,,0,
1223003256.500,,1.000000e+002,1.900751e+002,-3.251483e-006,6.356526e-009,-1.198140e-002,2.402921e-003,3,9.108159e-001,1.825000e+000,,,,,,,,,,,,,,,,,,0,5.000000e+000,1.000000e+000,3,3,1.092072e-001,0,,0,
1223003728.593,,1.000000e+002,1.920386e+002,-3.256360e-006,4.705352e-009,-1.024923e-002,2.333779e-003,3,9.087064e-001,1.825000e+000,,,,,,,,,,,,,,,,,,0,5.000000e+000,1.000000e+000,3,3,9.739685e-002,0,,0,
1223004218.562,,1.000000e+002,1.940729e+002,-3.256933e-006,1.226633e-008,-1.315430e-002,9.709559e-004,3,9.090393e-001,1.825000e+000,,,,,,,,,,,,,,,,,,0,5.000000e+000,1.000000e+000,3,3,1.134949e-001,0,,0,
1223004692.906,,1.000000e+002,1.960595e+002,-3.255359e-006,1.322547e-008,-1.311621e-002,1.442877e-003,3,9.090104e-001,1.825000e+000,,,,,,,,,,,,,,,,,,0,5.000000e+000,1.000000e+000,3,3,7.229614e-002,0,,0,
1223005170.734,,1.000000e+002,1.980484e+002,-3.255581e-006,8.270338e-009,-1.342882e-002,5.571696e-004,3,9.108729e-001,1.825000e+000,,,,,,,,,,,,,,,,,,0,5.000000e+000,1.000000e+000,3,3,1.104889e-001,0,,0,
1223005651.421,,1.000000e+002,2.000562e+002,-3.261276e-006,7.281944e-009,-1.146504e-002,4.692844e-004,3,9.108872e-001,1.825000e+000,,,,,,,,,,,,,,,,,,0,5.000000e+000,1.000000e+000,3,3,7.499695e-002,0,,0,
1223006130.500,,1.000000e+002,2.020358e+002,-3.266525e-006,1.012207e-008,-1.359592e-002,1.350851e-003,3,9.121879e-001,1.825000e+000,,,,,,,,,,,,,,,,,,0,5.000000e+000,1.000000e+000,3,3,1.145935e-001,0,,0,
1223006604.593,,1.000000e+002,2.040352e+002,-3.259918e-006,3.429307e-009,-1.194364e-002,1.523088e-003,3,9.096786e-001,1.825000e+000,,,,,,,,,,,,,,,,,,0,5.000000e+000,1.000000e+000,3,3,9.339905e-002,0,,0,
1223007088.968,,1.000000e+002,2.060609e+002,-3.267500e-006,1.020250e-008,-1.574617e-002,7.726788e-004,3,9.124173e-001,1.825000e+000,,,,,,,,,,,,,,,,,,0,5.000000e+000,1.000000e+000,3,3,1.029968e-001,0,,0,
1223007563.625,,1.000000e+002,2.080434e+002,-3.264599e-006,5.356262e-009,-1.373246e-002,3.775960e-003,3,9.103071e-001,1.825000e+000,,,,,,,,,,,,,,,,,,0,5.000000e+000,1.000000e+000,3,3,8.880615e-002,0,,0,
1223008045.031,,1.000000e+002,2.100387e+002,-3.265984e-006,4.104569e-009,-1.419201e-002,6.907741e-004,3,9.085194e-001,1.825000e+000,,,,,,,,,,,,,,,,,,0,5.000000e+000,1.000000e+000,3,3,9.040833e-002,0,,0,
1223008532.578,,1.000000e+002,2.120734e+002,-3.267189e-006,5.560609e-009,-1.260485e-002,1.612655e-003,3,9.115658e-001,1.825000e+000,,,,,,,,,,,,,,,,,,0,5.000000e+000,1.000000e+000,3,3,1.423035e-001,0,,0,
1223009010.687,,1.000000e+002,2.140607e+002,-3.272038e-006,3.812968e-009,-1.254753e-002,1.746493e-003,3,9.088424e-001,1.825000e+000,,,,,,,,,,,,,,,,,,0,5.000000e+000,1.000000e+000,3,3,1.277924e-001,0,,0,
1223009484.578,,1.000000e+002,2.160620e+002,-3.269256e-006,1.430564e-008,-1.349245e-002,6.098378e-004,3,9.109173e-001,1.825000e+000,,,,,,,,,,,,,,,,,,0,5.000000e+000,1.000000e+000,3,3,8.679199e-002,0,,0,
1223009962.640,,1.000000e+002,2.180536e+002,-3.266671e-006,8.062515e-009,-1.414016e-002,1.156615e-003,3,9.116565e-001,1.825000e+000,,,,,,,,,,,,,,,,,,0,5.000000e+000,1.000000e+000,3,3,1.058960e-001,0,,0,
1223010443.562,,1.000000e+002,2.200504e+002,-3.281666e-006,3.010959e-009,-1.386846e-002,1.200012e-003,3,9.105016e-001,1.825000e+000,,,,,,,,,,,,,,,,,,0,5.000000e+000,1.000000e+000,3,3,8.979797e-002,0,,0,
1223010935.281,,1.000000e+002,2.220809e+002,-3.287420e-006,1.180609e-008,-1.085410e-002,5.393707e-004,3,9.110642e-001,1.825000e+000,,,,,,,,,,,,,,,,,,0,5.000000e+000,1.000000e+000,3,3,1.186981e-001,0,,0,
1223011399.593,,1.000000e+002,2.240513e+002,-3.287358e-006,3.304977e-009,-1.168101e-002,1.413396e-003,3,9.113070e-001,1.825000e+000,,,,,,,,,,,,,,,,,,0,5.000000e+000,1.000000e+000,3,3,7.429504e-002,0,,0,
1223011885.125,,1.000000e+002,2.260630e+002,-3.295805e-006,3.070776e-009,-1.462690e-002,4.350645e-003,3,9.091884e-001,1.825000e+000,,,,,,,,,,,,,,,,,,0,5.000000e+000,1.000000e+000,3,3,1.040039e-001,0,,0,
1223012359.140,,1.000000e+002,2.280295e+002,-3.284822e-006,4.984062e-009,-1.460857e-002,1.212298e-003,3,9.089081e-001,1.825000e+000,,,,,,,,,,,,,,,,,,0,5.000000e+000,1.000000e+000,3,3,9.609985e-002,0,,0,
1223012841.000,,1.000000e+002,2.300482e+002,-3.287803e-006,1.345548e-008,-1.368220e-002,2.078437e-003,3,9.078773e-001,1.825000e+000,,,,,,,,,,,,,,,,,,0,5.000000e+000,1.000000e+000,3,3,9.770203e-002,0,,0,
1223013319.406,,1.000000e+002,2.320467e+002,-3.294999e-006,5.620438e-009,-1.567210e-002,6.290161e-004,3,9.108327e-001,1.825000e+000,,,,,,,,,,,,,,,,,,0,5.000000e+000,1.000000e+000,3,3,8.940125e-002,0,,0,
1223013806.875,,1.000000e+002,2.340483e+002,-3.299973e-006,1.170577e-008,-1.425825e-002,3.766052e-003,3,9.106039e-001,1.825000e+000,,,,,,,,,,,,,,,,,,0,5.000000e+000,1.000000e+000,3,3,9.089661e-002,0,,0,
1223014283.718,,1.000000e+002,2.360530e+002,-3.299130e-006,7.735973e-009,-1.555782e-002,8.745605e-004,3,9.091306e-001,1.825000e+000,,,,,,,,,,,,,,,,,,0,5.000000e+000,1.000000e+000,3,3,9.230042e-002,0,,0,
1223014765.296,,1.000000e+002,2.380450e+002,-3.295562e-006,2.899407e-009,-1.565946e-002,2.329651e-003,3,9.092852e-001,1.825000e+000,,,,,,,,,,,,,,,,,,0,5.000000e+000,1.000000e+000,3,3,1.145935e-001,0,,0,
1223015248.625,,1.000000e+002,2.400757e+002,-3.310480e-006,1.499875e-008,-1.484617e-002,1.062732e-003,3,9.105089e-001,1.825000e+000,,,,,,,,,,,,,,,,,,0,5.000000e+000,1.000000e+000,3,3,1.163940e-001,0,,0,
1223015721.687,,1.000000e+002,2.420513e+002,-3.311080e-006,1.195235e-008,-1.544158e-002,1.065613e-003,3,9.106217e-001,1.825000e+000,,,,,,,,,,,,,,,,,,0,5.000000e+000,1.000000e+000,3,3,9.680176e-002,0,,0,
1223016203.000,,1.000000e+002,2.440576e+002,-3.323961e-006,5.377970e-009,-1.551419e-002,2.126118e-003,3,9.101756e-001,1.825000e+000,,,,,,,,,,,,,,,,,,0,5.000000e+000,1.000000e+000,3,3,9.829712e-002,0,,0,
1223016674.984,,1.000000e+002,2.460453e+002,-3.327844e-006,1.665529e-009,-1.522386e-002,1.330451e-003,3,9.074354e-001,1.825000e+000,,,,,,,,,,,,,,,,,,0,5.000000e+000,1.000000e+000,3,3,5.540466e-002,0,,0,
1223017170.421,,1.000000e+002,2.480806e+002,-3.321338e-006,1.251358e-008,-1.503511e-002,8.523997e-004,3,9.121041e-001,1.825000e+000,,,,,,,,,,,,,,,,,,0,5.000000e+000,1.000000e+000,3,3,1.352081e-001,0,,0,
1223017637.312,,1.000000e+002,2.500371e+002,-3.334122e-006,6.178246e-009,-1.598591e-002,5.686014e-004,3,9.095924e-001,1.825000e+000,,,,,,,,,,,,,,,,,,0,5.000000e+000,1.000000e+000,3,3,9.140015e-002,0,,0,
1223018119.234,,1.000000e+002,2.520654e+002,-3.330571e-006,1.764118e-008,-1.470877e-002,3.108399e-003,3,9.078318e-001,1.825000e+000,,,,,,,,,,,,,,,,,,0,5.000000e+000,1.000000e+000,3,3,9.269714e-002,0,,0,
1223018602.359,,1.000000e+002,2.540600e+002,-3.343330e-006,2.137148e-009,-1.655138e-002,2.112004e-003,3,9.096785e-001,1.825000e+000,,,,,,,,,,,,,,,,,,0,5.000000e+000,1.000000e+000,3,3,1.177979e-001,0,,0,
1223019072.734,,1.000000e+002,2.560327e+002,-3.356698e-006,5.911506e-009,-1.618341e-002,1.448633e-003,3,9.097610e-001,1.825000e+000,,,,,,,,,,,,,,,,,,0,5.000000e+000,1.000000e+000,3,3,7.171631e-002,0,,0,
1223019558.890,,1.000000e+002,2.580506e+002,-3.363626e-006,6.075255e-009,-1.359348e-002,1.511242e-003,3,9.097934e-001,1.825000e+000,,,,,,,,,,,,,,,,,,0,5.000000e+000,1.000000e+000,3,3,9.689331e-002,0,,0,
1223020040.015,,1.000000e+002,2.600595e+002,-3.360218e-006,3.396351e-009,-1.831472e-002,7.846264e-004,3,9.086522e-001,1.825000e+000,,,,,,,,,,,,,,,,,,0,5.000000e+000,1.000000e+000,3,3,1.106873e-001,0,,0,
1223020518.703,,1.000000e+002,2.620607e+002,-3.358756e-006,1.555039e-008,-1.735416e-002,2.528619e-003,3,9.084940e-001,1.825000e+000,,,,,,,,,,,,,,,,,,0,5.000000e+000,1.000000e+000,3,3,9.988403e-002,0,,0,
1223020990.265,,1.000000e+002,2.640425e+002,-3.374299e-006,3.969327e-009,-1.552844e-002,3.171552e-004,3,9.083877e-001,1.825000e+000,,,,,,,,,,,,,,,,,,0,5.000000e+000,1.000000e+000,3,3,8.862305e-002,0,,0,
1223021478.750,,1.000000e+002,2.660521e+002,-3.357204e-006,6.916815e-009,-1.499381e-002,1.781996e-003,3,9.051338e-001,1.825000e+000,,,,,,,,,,,,,,,,,,0,5.000000e+000,1.000000e+000,3,3,1.030273e-001,0,,0,
1223021955.328,,1.000000e+002,2.680497e+002,-3.360336e-006,8.914221e-009,-1.596780e-002,1.675876e-003,3,9.079161e-001,1.825000e+000,,,,,,,,,,,,,,,,,,0,5.000000e+000,1.000000e+000,3,3,1.045837e-001,0,,0,
1223022437.765,,1.000000e+002,2.700583e+002,-3.365192e-006,9.685591e-009,-1.772897e-002,7.488707e-004,3,9.057539e-001,1.825000e+000,,,,,,,,,,,,,,,,,,0,5.000000e+000,1.000000e+000,3,3,9.289551e-002,0,,0,
1223022924.703,,1.000000e+002,2.720756e+002,-3.353400e-006,1.211848e-008,-1.531925e-002,2.160480e-004,3,9.064330e-001,1.825000e+000,,,,,,,,,,,,,,,,,,0,5.000000e+000,1.000000e+000,3,3,1.078186e-001,0,,0,
1223023397.593,,1.000000e+002,2.740486e+002,-3.358457e-006,1.206571e-008,-1.210976e-002,1.945546e-003,3,9.090953e-001,1.825000e+000,,,,,,,,,,,,,,,,,,0,5.000000e+000,1.000000e+000,3,3,9.570313e-002,0,,0,
1223023880.843,,1.000000e+002,2.760603e+002,-3.362525e-006,1.040361e-008,-1.598201e-002,6.814483e-004,3,9.084185e-001,1.825000e+000,,,,,,,,,,,,,,,,,,0,5.000000e+000,1.000000e+000,3,3,1.111145e-001,0,,0,
1223024362.203,,1.000000e+002,2.780600e+002,-3.351229e-006,1.141044e-008,-1.345779e-002,2.122646e-003,3,9.083068e-001,1.825000e+000,,,,,,,,,,,,,,,,,,0,5.000000e+000,1.000000e+000,3,3,1.127014e-001,0,,0,
1223024842.375,,1.000000e+002,2.800609e+002,-3.343158e-006,1.317736e-008,-1.388408e-002,2.214262e-003,3,9.085323e-001,1.825000e+000,,,,,,,,,,,,,,,,,,0,5.000000e+000,1.000000e+000,3,3,1.142883e-001,0,,0,
1223025316.968,,1.000000e+002,2.820406e+002,-3.355704e-006,7.026509e-009,-1.500926e-002,1.042646e-003,3,9.084086e-001,1.825000e+000,,,,,,,,,,,,,,,,,,0,5.000000e+000,1.000000e+000,3,3,1.015015e-001,0,,0,
1223025800.218,,1.000000e+002,2.840589e+002,-3.342750e-006,1.582606e-008,-1.155561e-002,4.734912e-004,3,9.075913e-001,1.825000e+000,,,,,,,,,,,,,,,,,,0,5.000000e+000,1.000000e+000,3,3,1.029968e-001,0,,0,
1223026283.140,,1.000000e+002,2.860546e+002,-3.339649e-006,5.270980e-009,-1.019731e-002,1.495827e-003,3,9.056478e-001,1.825000e+000,,,,,,,,,,,,,,,,,,0,5.000000e+000,1.000000e+000,3,3,1.195068e-001,0,,0,
1223026757.734,,1.000000e+002,2.880638e+002,-3.343224e-006,1.116054e-008,-7.407780e-003,1.009764e-004,3,9.076745e-001,1.825000e+000,,,,,,,,,,,,,,,,,,0,5.000000e+000,1.000000e+000,3,3,9.088135e-002,0,,0,
1223027237.515,,1.000000e+002,2.900533e+002,-3.320287e-006,2.883028e-009,-7.201702e-003,5.202910e-004,3,9.069887e-001,1.825000e+000,,,,,,,,,,,,,,,,,,0,5.000000e+000,1.000000e+000,3,3,1.074829e-001,0,,0,
1223027720.953,,1.000000e+002,2.920631e+002,-3.324170e-006,1.580932e-008,-6.124866e-003,2.461753e-003,3,9.081911e-001,1.825000e+000,,,,,,,,,,,,,,,,,,0,5.000000e+000,1.000000e+000,3,3,1.090088e-001,0,,0,
1223028201.031,,1.000000e+002,2.940672e+002,-3.304540e-006,9.698057e-009,-5.730507e-003,2.376576e-003,3,9.083871e-001,1.825000e+000,,,,,,,,,,,,,,,,,,0,5.000000e+000,1.000000e+000,3,3,1.263123e-001,0,,0,
1223028674.578,,1.000000e+002,2.960593e+002,-3.297112e-006,1.967945e-008,-4.377021e-003,2.499795e-003,3,9.085198e-001,1.825000e+000,,,,,,,,,,,,,,,,,,0,5.000000e+000,1.000000e+000,3,3,9.600830e-002,0,,0,
1223029144.328,,1.000000e+002,2.980392e+002,-3.299698e-006,3.134579e-009,-3.302743e-004,9.628127e-004,3,9.074265e-001,1.825000e+000,,,,,,,,,,,,,,,,,,0,5.000000e+000,1.000000e+000,3,3,8.129883e-002,0,,0,
1223029867.640,,1.000000e+002,2.999899e+002,-3.285001e-006,9.584837e-009,1.592196e-003,1.076799e-003,3,9.092044e-001,1.825000e+000,,,,,,,,,,,,,,,,,,0,5.000000e+000,1.000000e+000,3,3,1.641846e-002,0,,0,