File: debug/squid_MvH.dat
[Header]
TITLE,MPMS RSO Measurement
BYAPP,MPMS Measurement,1.1,Summary
FILEOPENTIME, 1223035272.812000 10/3/2008, 2:01:12 PM

INFO, APPNAME, MPMS MultiVu Application, Revision 1.56,  Build 72

INFO, NAME, TbMnO3 TF on LaAlO3
INFO, WEIGHT, 1.000
INFO, AREA, 1.000
INFO, LENGTH, 1.000
INFO, SHAPE, Rectangular
INFO, COMMENT, Probe von Joost 7125
INFO, SEQUENCE FILE: RSO-0Field-2K-300K.seq


INFO, BACKGROUND DATA FILE:, None


STARTUPAXIS,X,4,LINEAR,AUTO,0.000000,0.000000
STARTUPAXIS,Y1,5,LINEAR,AUTO,0.000000,0.000000


STARTUPGROUP,Longitudinal
FIELDGROUP,Longitudinal,1,2,3,4,5,6,7,8,9,10,11,19,20,21,22,23,35
FIELDGROUP,Transverse,1,2,3,4,12,13,14,15,16,17,18,24,25,26,27,28,35

PLOT_APPEARANCE,ALL,HORZ_GRID_ON,VERT_GRID_ON,MARKERS_AND_LINES

[Data]
Time,Comment,Field (Oe),Temperature (K),Long Moment (emu),Long Scan Std Dev,Long Offset (cm),Long Offset Std Dev,Long Algorithm,Long Reg Fit,Long Reg Factor,Trans Moment (emu),Trans Scan Std Dev,Trans Offset (cm),Trans Offset Std Dev,Trans Algorithm,Trans Reg Fit,Trans Reg Factor,Long Moment [w/o ABS] (emu),Long Scan Std Dev [w/o ABS],Long Offset [w/o ABS] (cm),Long Offset Std Dev [w/o ABS],Long Reg Fit [w/o ABS],Trans Moment [w/o ABS] (emu),Trans Scan Std Dev [w/o ABS],Trans Offset [w/o ABS] (cm),Trans Offset Std Dev [w/o ABS],Trans Reg Fit [w/o ABS],RSO Position (deg),Amplitude (cm),Frequency,Cycles to Average,Scans per Measurement,Delta Temp (K),Error,EC Comp. Running,Using ABS,
1223035272.796,,0.000000e+000,2.000478e+000,-1.745309e-006,5.595860e-010,0.000000e+000,0.000000e+000,2,9.508283e-001,1.825000e+000,,,,,,,,,,,,,,,,,,1,8.000000e-001,4.000000e+000,2,2,6.898999e-003,0,,0,
1223036259.046,,2.957156e+004,1.999229e+000,-9.977728e-004,1.282845e-006,0.000000e+000,0.000000e+000,2,9.850074e-001,1.825000e+000,,,,,,,,,,,,,,,,,,1,8.000000e-001,4.000000e+000,2,2,1.229048e-004,0,,0,
1223037324.937,,5.914751e+004,1.999800e+000,-2.496778e-003,6.745142e-006,0.000000e+000,0.000000e+000,2,9.815975e-001,1.825000e+000,,,,,,,,,,,,,,,,,,1,8.000000e-001,4.000000e+000,2,2,2.269745e-004,0,,0,
1223038116.328,,3.075554e+004,1.999738e+000,-1.021557e-003,3.802271e-007,0.000000e+000,0.000000e+000,2,9.866141e-001,1.825000e+000,,,,,,,,,,,,,,,,,,1,8.000000e-001,4.000000e+000,2,2,2.098083e-005,0,,0,
1223039130.640,,-2.366118e+003,1.999964e+000,6.509278e-005,3.703387e-007,0.000000e+000,0.000000e+000,2,9.863039e-001,1.825000e+000,,,,,,,,,,,,,,,,,,1,8.000000e-001,4.000000e+000,2,2,1.440048e-004,0,,0,
1223040093.281,,-3.193951e+004,1.999769e+000,1.125482e-003,1.108083e-006,0.000000e+000,0.000000e+000,2,9.797654e-001,1.825000e+000,,,,,,,,,,,,,,,,,,1,8.000000e-001,4.000000e+000,2,2,6.198883e-005,0,,0,
1223041169.328,,-5.796426e+004,1.999265e+000,2.454354e-003,1.412562e-005,0.000000e+000,0.000000e+000,2,9.803501e-001,1.825000e+000,,,,,,,,,,,,,,,,,,1,8.000000e-001,4.000000e+000,2,2,4.309416e-004,0,,0,
1223041928.015,,-2.838978e+004,1.999445e+000,9.011725e-004,3.025600e-007,0.000000e+000,0.000000e+000,2,9.838606e-001,1.825000e+000,,,,,,,,,,,,,,,,,,1,8.000000e-001,4.000000e+000,2,2,6.198883e-005,0,,0,
1223046050.890,,9.462728e+003,1.199958e+001,-3.290639e-004,6.101827e-008,0.000000e+000,0.000000e+000,2,9.816515e-001,1.825000e+000,,,,,,,,,,,,,,,,,,1,8.000000e-001,4.000000e+000,2,2,1.279831e-003,0,,0,
1223046890.765,,3.903459e+004,1.199911e+001,-1.573753e-003,4.526835e-006,0.000000e+000,0.000000e+000,2,9.850974e-001,1.825000e+000,,,,,,,,,,,,,,,,,,1,8.000000e-001,4.000000e+000,2,2,5.998611e-004,0,,0,
1223047945.828,,5.086482e+004,1.199986e+001,-2.156319e-003,5.456371e-006,0.000000e+000,0.000000e+000,2,9.848101e-001,1.825000e+000,,,,,,,,,,,,,,,,,,1,8.000000e-001,4.000000e+000,2,2,1.270294e-003,0,,0,
1223048622.921,,2.128742e+004,1.199994e+001,-7.709437e-004,5.163936e-006,0.000000e+000,0.000000e+000,2,9.840465e-001,1.825000e+000,,,,,,,,,,,,,,,,,,1,8.000000e-001,4.000000e+000,2,2,1.870155e-003,0,,0,
1223049913.812,,-1.419278e+004,1.200075e+001,4.961595e-004,1.168217e-006,0.000000e+000,0.000000e+000,2,9.823759e-001,1.825000e+000,,,,,,,,,,,,,,,,,,1,8.000000e-001,4.000000e+000,2,2,1.359940e-003,0,,0,
1223050804.375,,-4.376537e+004,1.200048e+001,1.812567e-003,6.574744e-006,0.000000e+000,0.000000e+000,2,9.851986e-001,1.825000e+000,,,,,,,,,,,,,,,,,,1,8.000000e-001,4.000000e+000,2,2,1.359940e-003,0,,0,
1223051821.515,,-4.613476e+004,1.200005e+001,1.919876e-003,2.137635e-006,0.000000e+000,0.000000e+000,2,9.848852e-001,1.825000e+000,,,,,,,,,,,,,,,,,,1,8.000000e-001,4.000000e+000,2,2,2.810478e-003,0,,0,
1223052442.859,,-1.655228e+004,1.199873e+001,5.759700e-004,4.328243e-006,0.000000e+000,0.000000e+000,2,9.829924e-001,1.825000e+000,,,,,,,,,,,,,,,,,,1,8.000000e-001,4.000000e+000,2,2,1.109123e-003,0,,0,
1223054109.515,,1.537602e+004,2.199980e+001,-6.338662e-004,6.109235e-007,0.000000e+000,0.000000e+000,2,9.878182e-001,1.825000e+000,,,,,,,,,,,,,,,,,,1,8.000000e-001,4.000000e+000,2,2,7.896423e-004,0,,0,
1223055013.453,,4.495007e+004,2.199980e+001,-2.001473e-003,1.418011e-006,0.000000e+000,0.000000e+000,2,9.890022e-001,1.825000e+000,,,,,,,,,,,,,,,,,,1,8.000000e-001,4.000000e+000,2,2,3.961563e-003,0,,0,
1223056025.140,,4.495152e+004,2.200000e+001,-1.995816e-003,4.820875e-006,0.000000e+000,0.000000e+000,2,9.874890e-001,1.825000e+000,,,,,,,,,,,,,,,,,,1,8.000000e-001,4.000000e+000,2,2,0.000000e+000,0,,0,
1223056635.109,,1.536729e+004,2.200059e+001,-6.384972e-004,1.386911e-005,0.000000e+000,0.000000e+000,2,9.875249e-001,1.825000e+000,,,,,,,,,,,,,,,,,,1,8.000000e-001,4.000000e+000,2,2,2.370834e-003,0,,0,
1223057886.500,,-1.774207e+004,2.199921e+001,7.409644e-004,1.433981e-006,0.000000e+000,0.000000e+000,2,9.894903e-001,1.825000e+000,,,,,,,,,,,,,,,,,,1,8.000000e-001,4.000000e+000,2,2,1.590729e-003,0,,0,
1223058822.359,,-4.731655e+004,2.199940e+001,2.126572e-003,2.636878e-005,0.000000e+000,0.000000e+000,2,9.890352e-001,1.825000e+000,,,,,,,,,,,,,,,,,,1,8.000000e-001,4.000000e+000,2,2,1.590729e-003,0,,0,
1223059810.968,,-4.258504e+004,2.200059e+001,1.880201e-003,3.083882e-006,0.000000e+000,0.000000e+000,2,9.893363e-001,1.825000e+000,,,,,,,,,,,,,,,,,,1,8.000000e-001,4.000000e+000,2,2,7.896423e-004,0,,0,
1223060408.375,,-1.299469e+004,2.199980e+001,5.284940e-004,2.825568e-007,0.000000e+000,0.000000e+000,2,9.867231e-001,1.825000e+000,,,,,,,,,,,,,,,,,,1,8.000000e-001,4.000000e+000,2,2,1.579285e-003,0,,0,
1223062115.437,,2.128888e+004,3.199863e+001,-9.586425e-004,7.722669e-007,0.000000e+000,0.000000e+000,2,9.743629e-001,1.825000e+000,,,,,,,,,,,,,,,,,,1,8.000000e-001,4.000000e+000,2,2,3.019333e-003,0,,0,
1223063094.562,,5.086627e+004,3.199976e+001,-2.381569e-003,6.096311e-006,0.000000e+000,0.000000e+000,2,9.722736e-001,1.825000e+000,,,,,,,,,,,,,,,,,,1,8.000000e-001,4.000000e+000,2,2,4.529953e-003,0,,0,
1223064028.734,,3.903532e+004,3.199863e+001,-1.798687e-003,2.104050e-007,0.000000e+000,0.000000e+000,2,9.734997e-001,1.825000e+000,,,,,,,,,,,,,,,,,,1,8.000000e-001,4.000000e+000,2,2,3.019333e-003,0,,0,
1223064637.109,,9.457197e+003,3.199825e+001,-4.090278e-004,1.087175e-006,0.000000e+000,0.000000e+000,2,9.728305e-001,1.825000e+000,,,,,,,,,,,,,,,,,,1,8.000000e-001,4.000000e+000,2,2,1.510620e-003,0,,0,
1223065761.546,,-2.010637e+004,3.199976e+001,9.027594e-004,3.726004e-006,0.000000e+000,0.000000e+000,2,9.741439e-001,1.825000e+000,,,,,,,,,,,,,,,,,,1,8.000000e-001,4.000000e+000,2,2,1.508713e-003,0,,0,
1223066720.406,,-4.968158e+004,3.199901e+001,2.313721e-003,5.564866e-006,0.000000e+000,0.000000e+000,2,9.726763e-001,1.825000e+000,,,,,,,,,,,,,,,,,,1,8.000000e-001,4.000000e+000,2,2,3.019333e-003,0,,0,
1223067681.218,,-4.022002e+004,3.199939e+001,1.852575e-003,4.797332e-006,0.000000e+000,0.000000e+000,2,9.740900e-001,1.825000e+000,,,,,,,,,,,,,,,,,,1,8.000000e-001,4.000000e+000,2,2,1.508713e-003,0,,0,
1223068267.171,,-1.062967e+004,3.199863e+001,4.658636e-004,5.258889e-007,0.000000e+000,0.000000e+000,2,9.764576e-001,1.825000e+000,,,,,,,,,,,,,,,,,,1,8.000000e-001,4.000000e+000,2,2,6.038666e-003,0,,0,
1223069859.046,,1.774207e+004,4.199930e+001,-8.277119e-004,5.084786e-007,0.000000e+000,0.000000e+000,2,9.845593e-001,1.825000e+000,,,,,,,,,,,,,,,,,,1,8.000000e-001,4.000000e+000,2,2,2.399445e-003,0,,0,
1223070789.015,,4.731364e+004,4.200050e+001,-2.247795e-003,7.128763e-008,0.000000e+000,0.000000e+000,2,9.826132e-001,1.825000e+000,,,,,,,,,,,,,,,,,,1,8.000000e-001,4.000000e+000,2,2,0.000000e+000,0,,0,
1223071772.765,,4.258359e+004,4.199990e+001,-2.011042e-003,8.150970e-006,0.000000e+000,0.000000e+000,2,9.828638e-001,1.825000e+000,,,,,,,,,,,,,,,,,,1,8.000000e-001,4.000000e+000,2,2,4.798889e-003,0,,0,
1223072368.656,,1.299412e+004,4.199930e+001,-5.898384e-004,1.985265e-006,0.000000e+000,0.000000e+000,2,9.854175e-001,1.825000e+000,,,,,,,,,,,,,,,,,,1,8.000000e-001,4.000000e+000,2,2,2.399445e-003,0,,0,
1223073903.109,,-2.957157e+004,4.200230e+001,1.375250e-003,3.951349e-006,0.000000e+000,0.000000e+000,2,9.833058e-001,1.825000e+000,,,,,,,,,,,,,,,,,,1,8.000000e-001,4.000000e+000,2,2,2.399445e-003,0,,0,
1223074972.906,,-5.914605e+004,4.200110e+001,2.775209e-003,3.616891e-006,0.000000e+000,0.000000e+000,2,9.814910e-001,1.825000e+000,,,,,,,,,,,,,,,,,,1,8.000000e-001,4.000000e+000,2,2,2.399445e-003,0,,0,
1223075767.718,,-3.075481e+004,4.200110e+001,1.412315e-003,4.687273e-006,0.000000e+000,0.000000e+000,2,9.836063e-001,1.825000e+000,,,,,,,,,,,,,,,,,,1,8.000000e-001,4.000000e+000,2,2,9.620667e-003,0,,0,
1223077163.343,,1.183154e+003,5.200008e+001,-4.481227e-005,5.349902e-008,0.000000e+000,0.000000e+000,2,9.694758e-001,1.825000e+000,,,,,,,,,,,,,,,,,,1,8.000000e-001,4.000000e+000,2,2,0.000000e+000,0,,0,
1223078137.937,,3.075408e+004,5.199938e+001,-1.419691e-003,6.817582e-007,0.000000e+000,0.000000e+000,2,9.582063e-001,1.825000e+000,,,,,,,,,,,,,,,,,,1,8.000000e-001,4.000000e+000,2,2,5.611420e-003,0,,0,
1223079215.343,,5.914750e+004,5.199412e+001,-2.773905e-003,1.710125e-005,0.000000e+000,0.000000e+000,2,9.576083e-001,1.825000e+000,,,,,,,,,,,,,,,,,,1,8.000000e-001,4.000000e+000,2,2,7.019043e-003,0,,0,
1223079990.375,,2.957229e+004,5.200043e+001,-1.364933e-003,7.309432e-006,0.000000e+000,0.000000e+000,2,9.578040e-001,1.825000e+000,,,,,,,,,,,,,,,,,,1,8.000000e-001,4.000000e+000,2,2,7.022858e-003,0,,0,
1223080730.468,,2.328637e-001,5.199867e+001,3.039101e-006,4.425075e-007,0.000000e+000,0.000000e+000,2,8.956518e-001,1.825000e+000,,,,,,,,,,,,,,,,,,1,8.000000e-001,4.000000e+000,2,2,7.011414e-003,0,,0,
1223081784.453,,-2.957157e+004,5.200183e+001,1.363883e-003,2.841620e-007,0.000000e+000,0.000000e+000,2,9.577816e-001,1.825000e+000,,,,,,,,,,,,,,,,,,1,8.000000e-001,4.000000e+000,2,2,7.022858e-003,0,,0,
1223082850.734,,-5.914605e+004,5.200079e+001,2.775754e-003,2.005926e-006,0.000000e+000,0.000000e+000,2,9.571428e-001,1.825000e+000,,,,,,,,,,,,,,,,,,1,8.000000e-001,4.000000e+000,2,2,8.422852e-003,0,,0,
1223083641.781,,-3.075481e+004,5.200499e+001,1.413362e-003,4.452584e-007,0.000000e+000,0.000000e+000,2,9.572346e-001,1.825000e+000,,,,,,,,,,,,,,,,,,1,8.000000e-001,4.000000e+000,2,2,5.607605e-003,0,,0,
1223084924.515,,2.619717e-001,6.199853e+001,-2.296179e-006,4.054695e-008,0.000000e+000,0.000000e+000,2,9.136173e-001,1.825000e+000,,,,,,,,,,,,,,,,,,1,8.000000e-001,4.000000e+000,2,2,5.741119e-003,0,,0,
1223085875.734,,2.957157e+004,6.200235e+001,-1.350488e-003,1.187026e-006,0.000000e+000,0.000000e+000,2,9.426246e-001,1.825000e+000,,,,,,,,,,,,,,,,,,1,8.000000e-001,4.000000e+000,2,2,3.822327e-003,0,,0,
1223086942.953,,5.914750e+004,6.199757e+001,-2.743409e-003,3.706782e-006,0.000000e+000,0.000000e+000,2,9.419590e-001,1.825000e+000,,,,,,,,,,,,,,,,,,1,8.000000e-001,4.000000e+000,2,2,1.338959e-002,0,,0,
1223087738.375,,3.075481e+004,6.199518e+001,-1.409502e-003,7.632531e-007,0.000000e+000,0.000000e+000,2,9.424132e-001,1.825000e+000,,,,,,,,,,,,,,,,,,1,8.000000e-001,4.000000e+000,2,2,7.648468e-003,0,,0,
1223088766.734,,-5.915041e+003,6.199901e+001,2.589534e-004,1.968204e-006,0.000000e+000,0.000000e+000,2,9.449501e-001,1.825000e+000,,,,,,,,,,,,,,,,,,1,8.000000e-001,4.000000e+000,2,2,1.338959e-002,0,,0,
1223089660.000,,-3.548486e+004,6.199518e+001,1.629713e-003,3.034079e-006,0.000000e+000,0.000000e+000,2,9.415231e-001,1.825000e+000,,,,,,,,,,,,,,,,,,1,8.000000e-001,4.000000e+000,2,2,2.103043e-002,0,,0,
1223090731.406,,-5.441309e+004,6.200235e+001,2.517838e-003,2.861376e-006,0.000000e+000,0.000000e+000,2,9.415148e-001,1.825000e+000,,,,,,,,,,,,,,,,,,1,8.000000e-001,4.000000e+000,2,2,1.147079e-002,0,,0,
1223091449.843,,-2.483788e+004,6.199805e+001,1.126753e-003,1.527798e-005,0.000000e+000,0.000000e+000,2,9.442369e-001,1.825000e+000,,,,,,,,,,,,,,,,,,1,8.000000e-001,4.000000e+000,2,2,1.338196e-002,0,,0,
1223093009.875,,7.095372e+003,7.200203e+001,-3.208881e-004,1.018172e-006,0.000000e+000,0.000000e+000,2,9.491451e-001,1.825000e+000,,,,,,,,,,,,,,,,,,1,8.000000e-001,4.000000e+000,2,2,2.223206e-002,0,,0,
1223093824.437,,3.667101e+004,7.200203e+001,-1.734448e-003,6.390680e-006,0.000000e+000,0.000000e+000,2,9.466223e-001,1.825000e+000,,,,,,,,,,,,,,,,,,1,8.000000e-001,4.000000e+000,2,2,4.943848e-003,0,,0,
1223094889.765,,5.323130e+004,7.199708e+001,-2.526108e-003,1.260784e-006,0.000000e+000,0.000000e+000,2,9.461327e-001,1.825000e+000,,,,,,,,,,,,,,,,,,1,8.000000e-001,4.000000e+000,2,2,7.423401e-003,0,,0,
1223095592.671,,2.365609e+004,7.199956e+001,-1.111453e-003,7.316594e-006,0.000000e+000,0.000000e+000,2,9.479142e-001,1.825000e+000,,,,,,,,,,,,,,,,,,1,8.000000e-001,4.000000e+000,2,2,1.728821e-002,0,,0,
1223096470.984,,-5.915041e+003,7.200017e+001,2.645677e-004,6.618372e-007,0.000000e+000,0.000000e+000,2,9.492517e-001,1.825000e+000,,,,,,,,,,,,,,,,,,1,8.000000e-001,4.000000e+000,2,2,1.483917e-002,0,,0,
1223097366.578,,-3.548486e+004,7.199770e+001,1.680226e-003,7.610964e-006,0.000000e+000,0.000000e+000,2,9.470670e-001,1.825000e+000,,,,,,,,,,,,,,,,,,1,8.000000e-001,4.000000e+000,2,2,1.481628e-002,0,,0,
1223098436.406,,-5.441454e+004,7.200079e+001,2.573899e-003,4.125287e-006,0.000000e+000,0.000000e+000,2,9.461550e-001,1.825000e+000,,,,,,,,,,,,,,,,,,1,8.000000e-001,4.000000e+000,2,2,4.943848e-003,0,,0,
1223099153.812,,-2.483788e+004,7.201376e+001,1.169594e-003,8.288935e-006,0.000000e+000,0.000000e+000,2,9.455777e-001,1.825000e+000,,,,,,,,,,,,,,,,,,1,8.000000e-001,4.000000e+000,2,2,1.730347e-002,0,,0,
1223100410.578,,3.548850e+003,8.199717e+001,-1.611374e-004,1.773234e-007,0.000000e+000,0.000000e+000,2,9.660352e-001,1.825000e+000,,,,,,,,,,,,,,,,,,1,8.000000e-001,4.000000e+000,2,2,1.541138e-002,0,,0,
1223101367.421,,3.311984e+004,8.199486e+001,-1.635209e-003,3.826144e-006,0.000000e+000,0.000000e+000,2,9.642254e-001,1.825000e+000,,,,,,,,,,,,,,,,,,1,8.000000e-001,4.000000e+000,2,2,9.254456e-003,0,,0,
1223102443.687,,5.678102e+004,8.200719e+001,-2.823230e-003,6.086927e-006,0.000000e+000,0.000000e+000,2,9.622835e-001,1.825000e+000,,,,,,,,,,,,,,,,,,1,8.000000e-001,4.000000e+000,2,2,2.159119e-002,0,,0,
1223103188.171,,2.720582e+004,8.199486e+001,-1.335783e-003,1.621583e-006,0.000000e+000,0.000000e+000,2,9.636258e-001,1.825000e+000,,,,,,,,,,,,,,,,,,1,8.000000e-001,4.000000e+000,2,2,2.159119e-002,0,,0,
1223103978.859,,-2.366118e+003,8.199870e+001,1.033652e-004,6.537495e-007,0.000000e+000,0.000000e+000,2,9.690812e-001,1.825000e+000,,,,,,,,,,,,,,,,,,1,8.000000e-001,4.000000e+000,2,2,6.179810e-003,0,,0,
1223104951.390,,-3.193878e+004,8.199331e+001,1.576917e-003,5.747283e-006,0.000000e+000,0.000000e+000,2,9.643107e-001,1.825000e+000,,,,,,,,,,,,,,,,,,1,8.000000e-001,4.000000e+000,2,2,1.233673e-002,0,,0,
1223106030.546,,-5.796572e+004,8.199794e+001,2.884345e-003,8.176982e-006,0.000000e+000,0.000000e+000,2,9.632035e-001,1.825000e+000,,,,,,,,,,,,,,,,,,1,8.000000e-001,4.000000e+000,2,2,2.774048e-002,0,,0,
1223106787.765,,-2.838906e+004,8.198869e+001,1.394935e-003,3.929864e-007,0.000000e+000,0.000000e+000,2,9.650978e-001,1.825000e+000,,,,,,,,,,,,,,,,,,1,8.000000e-001,4.000000e+000,2,2,2.775574e-002,0,,0,
1223108301.109,,4.731946e+003,9.199599e+001,-2.220795e-004,2.048660e-006,0.000000e+000,0.000000e+000,2,9.713994e-001,1.825000e+000,,,,,,,,,,,,,,,,,,1,8.000000e-001,4.000000e+000,2,2,3.776550e-003,0,,0,
1223109188.765,,3.430380e+004,9.200448e+001,-1.716362e-003,1.546757e-007,0.000000e+000,0.000000e+000,2,9.686376e-001,1.825000e+000,,,,,,,,,,,,,,,,,,1,8.000000e-001,4.000000e+000,2,2,2.266693e-002,0,,0,
1223110263.187,,5.559633e+004,9.200921e+001,-2.807648e-003,7.722916e-006,0.000000e+000,0.000000e+000,2,9.680033e-001,1.825000e+000,,,,,,,,,,,,,,,,,,1,8.000000e-001,4.000000e+000,2,2,1.889038e-002,0,,0,
1223110997.468,,2.602257e+004,9.200165e+001,-1.298032e-003,1.144715e-006,0.000000e+000,0.000000e+000,2,9.690906e-001,1.825000e+000,,,,,,,,,,,,,,,,,,1,8.000000e-001,4.000000e+000,2,2,1.132965e-002,0,,0,
1223112087.515,,-9.463601e+003,9.199315e+001,4.595447e-004,2.080589e-006,0.000000e+000,0.000000e+000,2,9.704669e-001,1.825000e+000,,,,,,,,,,,,,,,,,,1,8.000000e-001,4.000000e+000,2,2,1.889038e-002,0,,0,
1223112927.390,,-3.903532e+004,9.199787e+001,1.960533e-003,1.775823e-005,0.000000e+000,0.000000e+000,2,9.687671e-001,1.825000e+000,,,,,,,,,,,,,,,,,,1,8.000000e-001,4.000000e+000,2,2,1.889038e-002,0,,0,
1223113985.437,,-5.086482e+004,9.199315e+001,2.555716e-003,4.830753e-006,0.000000e+000,0.000000e+000,2,9.682295e-001,1.825000e+000,,,,,,,,,,,,,,,,,,1,8.000000e-001,4.000000e+000,2,2,1.889038e-002,0,,0,
1223114663.406,,-2.128888e+004,9.199881e+001,1.060907e-003,2.486006e-006,0.000000e+000,0.000000e+000,2,9.684779e-001,1.825000e+000,,,,,,,,,,,,,,,,,,1,8.000000e-001,4.000000e+000,2,2,7.545471e-003,0,,0,
1223116289.890,,1.064510e+004,1.019972e+002,-5.280112e-004,2.866726e-007,0.000000e+000,0.000000e+000,2,9.819287e-001,1.825000e+000,,,,,,,,,,,,,,,,,,1,8.000000e-001,4.000000e+000,2,2,4.600525e-003,0,,0,
1223117140.296,,4.022147e+004,1.020006e+002,-2.061940e-003,3.962298e-006,0.000000e+000,0.000000e+000,2,9.784847e-001,1.825000e+000,,,,,,,,,,,,,,,,,,1,8.000000e-001,4.000000e+000,2,2,4.501343e-003,0,,0,
1223118192.187,,4.968303e+004,1.020097e+002,-2.545354e-003,7.450279e-006,0.000000e+000,0.000000e+000,2,9.802333e-001,1.825000e+000,,,,,,,,,,,,,,,,,,1,8.000000e-001,4.000000e+000,2,2,5.870056e-002,0,,0,
1223118856.906,,2.010491e+004,1.020085e+002,-1.016097e-003,2.990121e-006,0.000000e+000,0.000000e+000,2,9.814184e-001,1.825000e+000,,,,,,,,,,,,,,,,,,1,8.000000e-001,4.000000e+000,2,2,2.709961e-002,0,,0,
1223120055.000,,-1.301157e+004,1.019848e+002,6.506524e-004,9.748928e-007,0.000000e+000,0.000000e+000,2,9.813001e-001,1.825000e+000,,,,,,,,,,,,,,,,,,1,8.000000e-001,4.000000e+000,2,2,1.350403e-002,0,,0,
1223120933.296,,-4.258504e+004,1.020097e+002,2.174952e-003,1.800823e-005,0.000000e+000,0.000000e+000,2,9.785869e-001,1.825000e+000,,,,,,,,,,,,,,,,,,1,8.000000e-001,4.000000e+000,2,2,4.501343e-003,0,,0,
1223121968.640,,-4.731655e+004,1.019984e+002,2.420200e-003,1.693118e-006,0.000000e+000,0.000000e+000,2,9.795241e-001,1.825000e+000,,,,,,,,,,,,,,,,,,1,8.000000e-001,4.000000e+000,2,2,2.259827e-002,0,,0,
1223122613.203,,-1.773843e+004,1.019904e+002,8.863783e-004,1.520991e-006,0.000000e+000,0.000000e+000,2,9.739796e-001,1.825000e+000,,,,,,,,,,,,,,,,,,1,8.000000e-001,4.000000e+000,2,2,1.359558e-002,0,,0,
1223124291.703,,1.537660e+004,1.119967e+002,-7.719802e-004,6.922126e-007,0.000000e+000,0.000000e+000,2,9.742845e-001,1.825000e+000,,,,,,,,,,,,,,,,,,1,8.000000e-001,4.000000e+000,2,2,3.189850e-002,0,,0,
1223125194.968,,4.495007e+004,1.120113e+002,-2.302231e-003,4.316101e-006,0.000000e+000,0.000000e+000,2,9.731762e-001,1.825000e+000,,,,,,,,,,,,,,,,,,1,8.000000e-001,4.000000e+000,2,2,4.249573e-002,0,,0,
1223126209.968,,4.495152e+004,1.119913e+002,-2.300001e-003,6.666117e-007,0.000000e+000,0.000000e+000,2,9.737220e-001,1.825000e+000,,,,,,,,,,,,,,,,,,1,8.000000e-001,4.000000e+000,2,2,1.589966e-002,0,,0,
1223126820.875,,1.536787e+004,1.119980e+002,-7.697303e-004,1.829107e-006,0.000000e+000,0.000000e+000,2,9.733571e-001,1.825000e+000,,,,,,,,,,,,,,,,,,1,8.000000e-001,4.000000e+000,2,2,1.069641e-002,0,,0,
1223128015.125,,-1.892531e+004,1.120086e+002,9.522902e-004,5.998517e-007,0.000000e+000,0.000000e+000,2,9.735382e-001,1.825000e+000,,,,,,,,,,,,,,,,,,1,8.000000e-001,4.000000e+000,2,2,3.720093e-002,0,,0,
1223128959.906,,-4.849979e+004,1.120033e+002,2.485434e-003,3.137965e-006,0.000000e+000,0.000000e+000,2,9.736668e-001,1.825000e+000,,,,,,,,,,,,,,,,,,1,8.000000e-001,4.000000e+000,2,2,4.250336e-002,0,,0,
1223129935.750,,-4.140325e+004,1.119913e+002,2.115023e-003,6.087256e-006,0.000000e+000,0.000000e+000,2,9.739445e-001,1.825000e+000,,,,,,,,,,,,,,,,,,1,8.000000e-001,4.000000e+000,2,2,1.059723e-002,0,,0,
1223130527.484,,-1.179952e+004,1.120073e+002,5.905292e-004,1.079354e-006,0.000000e+000,0.000000e+000,2,9.770108e-001,1.825000e+000,,,,,,,,,,,,,,,,,,1,8.000000e-001,4.000000e+000,2,2,1.599884e-002,0,,0,
1223132170.890,,1.892385e+004,1.220065e+002,-9.532510e-004,2.618949e-006,0.000000e+000,0.000000e+000,2,9.696980e-001,1.825000e+000,,,,,,,,,,,,,,,,,,1,8.000000e-001,4.000000e+000,2,2,1.239777e-002,0,,0,
1223133115.625,,4.849834e+004,1.220033e+002,-2.472115e-003,3.961145e-007,0.000000e+000,0.000000e+000,2,9.676075e-001,1.825000e+000,,,,,,,,,,,,,,,,,,1,8.000000e-001,4.000000e+000,2,2,2.490234e-002,0,,0,
1223134083.515,,4.140325e+004,1.220002e+002,-2.104779e-003,1.715508e-007,0.000000e+000,0.000000e+000,2,9.681526e-001,1.825000e+000,,,,,,,,,,,,,,,,,,1,8.000000e-001,4.000000e+000,2,2,2.490234e-002,0,,0,
1223134674.515,,1.181232e+004,1.219956e+002,-5.884683e-004,1.310298e-006,0.000000e+000,0.000000e+000,2,9.701145e-001,1.825000e+000,,,,,,,,,,,,,,,,,,1,8.000000e-001,4.000000e+000,2,2,6.202698e-003,0,,0,
1223135784.718,,-1.774279e+004,1.219801e+002,8.925997e-004,3.801901e-006,0.000000e+000,0.000000e+000,2,9.689306e-001,1.825000e+000,,,,,,,,,,,,,,,,,,1,8.000000e-001,4.000000e+000,2,2,4.339600e-002,0,,0,
1223136724.515,,-4.731655e+004,1.219925e+002,2.418878e-003,9.161671e-006,0.000000e+000,0.000000e+000,2,9.676350e-001,1.825000e+000,,,,,,,,,,,,,,,,,,1,8.000000e-001,4.000000e+000,2,2,1.860046e-002,0,,0,
1223137709.203,,-4.258504e+004,1.219894e+002,2.169312e-003,5.945340e-006,0.000000e+000,0.000000e+000,2,9.680061e-001,1.825000e+000,,,,,,,,,,,,,,,,,,1,8.000000e-001,4.000000e+000,2,2,3.720093e-002,0,,0,
1223138299.781,,-1.299470e+004,1.220002e+002,6.502902e-004,9.359769e-006,0.000000e+000,0.000000e+000,2,9.660860e-001,1.825000e+000,,,,,,,,,,,,,,,,,,1,8.000000e-001,4.000000e+000,2,2,1.249695e-002,0,,0,
1223139803.156,,1.537631e+004,1.320060e+002,-7.781697e-004,1.632779e-007,0.000000e+000,0.000000e+000,2,9.750443e-001,1.825000e+000,,,,,,,,,,,,,,,,,,1,8.000000e-001,4.000000e+000,2,2,2.120972e-002,0,,0,
1223140708.828,,4.495152e+004,1.319989e+002,-2.321742e-003,6.997055e-008,0.000000e+000,0.000000e+000,2,9.728049e-001,1.825000e+000,,,,,,,,,,,,,,,,,,1,8.000000e-001,4.000000e+000,2,2,4.249573e-002,0,,0,
1223141717.578,,4.495152e+004,1.319936e+002,-2.317118e-003,3.197563e-006,0.000000e+000,0.000000e+000,2,9.730110e-001,1.825000e+000,,,,,,,,,,,,,,,,,,1,8.000000e-001,4.000000e+000,2,2,4.249573e-002,0,,0,
1223142328.171,,1.536758e+004,1.320042e+002,-7.812122e-004,2.973164e-006,0.000000e+000,0.000000e+000,2,9.758993e-001,1.825000e+000,,,,,,,,,,,,,,,,,,1,8.000000e-001,4.000000e+000,2,2,5.670166e-002,0,,0,
1223143360.890,,-1.774279e+004,1.319812e+002,9.006019e-004,1.583388e-007,0.000000e+000,0.000000e+000,2,9.744750e-001,1.825000e+000,,,,,,,,,,,,,,,,,,1,8.000000e-001,4.000000e+000,2,2,2.130127e-002,0,,0,
1223144295.171,,-4.731655e+004,1.319990e+002,2.450538e-003,6.260454e-006,0.000000e+000,0.000000e+000,2,9.732987e-001,1.825000e+000,,,,,,,,,,,,,,,,,,1,8.000000e-001,4.000000e+000,2,2,2.130127e-002,0,,0,
1223145279.468,,-4.258504e+004,1.320025e+002,2.182490e-003,1.105005e-005,0.000000e+000,0.000000e+000,2,9.718698e-001,1.825000e+000,,,,,,,,,,,,,,,,,,1,8.000000e-001,4.000000e+000,2,2,3.540039e-002,0,,0,
1223145876.781,,-1.299848e+004,1.319937e+002,6.531233e-004,1.185174e-006,0.000000e+000,0.000000e+000,2,9.753699e-001,1.825000e+000,,,,,,,,,,,,,,,,,,1,8.000000e-001,4.000000e+000,2,2,1.419067e-002,0,,0,
1223147630.750,,1.892385e+004,1.419991e+002,-9.541047e-004,1.691966e-006,0.000000e+000,0.000000e+000,2,9.650797e-001,1.825000e+000,,,,,,,,,,,,,,,,,,1,8.000000e-001,4.000000e+000,2,2,1.600647e-002,0,,0,
1223148573.171,,4.849979e+004,1.420121e+002,-2.474982e-003,3.793216e-007,0.000000e+000,0.000000e+000,2,9.643466e-001,1.825000e+000,,,,,,,,,,,,,,,,,,1,8.000000e-001,4.000000e+000,2,2,7.995605e-003,0,,0,
1223149547.484,,4.140325e+004,1.419921e+002,-2.116840e-003,2.497365e-006,0.000000e+000,0.000000e+000,2,9.631573e-001,1.825000e+000,,,,,,,,,,,,,,,,,,1,8.000000e-001,4.000000e+000,2,2,2.400208e-002,0,,0,
1223150134.796,,1.179836e+004,1.419951e+002,-5.886863e-004,1.542229e-007,0.000000e+000,0.000000e+000,2,9.659061e-001,1.825000e+000,,,,,,,,,,,,,,,,,,1,8.000000e-001,4.000000e+000,2,2,3.199768e-002,0,,0,
1223151218.734,,-1.774207e+004,1.420101e+002,8.922470e-004,1.126852e-006,0.000000e+000,0.000000e+000,2,9.644793e-001,1.825000e+000,,,,,,,,,,,,,,,,,,1,8.000000e-001,4.000000e+000,2,2,7.995605e-003,0,,0,
1223152150.453,,-4.731509e+004,1.419991e+002,2.418453e-003,4.057128e-006,0.000000e+000,0.000000e+000,2,9.637048e-001,1.825000e+000,,,,,,,,,,,,,,,,,,1,8.000000e-001,4.000000e+000,2,2,2.400208e-002,0,,0,
1223153131.531,,-4.258504e+004,1.419981e+002,2.165968e-003,1.450938e-006,0.000000e+000,0.000000e+000,2,9.635327e-001,1.825000e+000,,,,,,,,,,,,,,,,,,1,8.000000e-001,4.000000e+000,2,2,2.400208e-002,0,,0,
1223153717.625,,-1.299440e+004,1.420081e+002,6.488238e-004,3.357342e-006,0.000000e+000,0.000000e+000,2,9.657840e-001,1.825000e+000,,,,,,,,,,,,,,,,,,1,8.000000e-001,4.000000e+000,2,2,7.995605e-003,0,,0,
1223155283.750,,1.655810e+004,1.520062e+002,-8.470453e-004,6.738969e-007,0.000000e+000,0.000000e+000,2,9.795166e-001,1.825000e+000,,,,,,,,,,,,,,,,,,1,8.000000e-001,4.000000e+000,2,2,4.978943e-002,0,,0,
1223156199.703,,4.613330e+004,1.520062e+002,-2.408285e-003,4.406486e-006,0.000000e+000,0.000000e+000,2,9.789264e-001,1.825000e+000,,,,,,,,,,,,,,,,,,1,8.000000e-001,4.000000e+000,2,2,4.528809e-002,0,,0,
1223157194.578,,4.376683e+004,1.520107e+002,-2.280552e-003,5.341949e-006,0.000000e+000,0.000000e+000,2,9.793600e-001,1.825000e+000,,,,,,,,,,,,,,,,,,1,8.000000e-001,4.000000e+000,2,2,2.709961e-002,0,,0,
1223157801.125,,1.417910e+004,1.519983e+002,-7.237383e-004,8.618701e-008,0.000000e+000,0.000000e+000,2,9.792482e-001,1.825000e+000,,,,,,,,,,,,,,,,,,1,8.000000e-001,4.000000e+000,2,2,4.528809e-002,0,,0,
1223158866.468,,-1.537602e+004,1.520028e+002,7.855857e-004,8.034243e-007,0.000000e+000,0.000000e+000,2,9.794282e-001,1.825000e+000,,,,,,,,,,,,,,,,,,1,8.000000e-001,4.000000e+000,2,2,4.069519e-002,0,,0,
1223159767.343,,-4.494861e+004,1.519858e+002,2.341329e-003,1.993744e-006,0.000000e+000,0.000000e+000,2,9.787117e-001,1.825000e+000,,,,,,,,,,,,,,,,,,1,8.000000e-001,4.000000e+000,2,2,4.069519e-002,0,,0,
1223160775.500,,-4.495006e+004,1.520096e+002,2.348577e-003,2.808692e-007,0.000000e+000,0.000000e+000,2,9.793367e-001,1.825000e+000,,,,,,,,,,,,,,,,,,1,8.000000e-001,4.000000e+000,2,2,4.528809e-002,0,,0,
1223161382.265,,-1.536729e+004,1.519983e+002,7.872381e-004,2.766340e-006,0.000000e+000,0.000000e+000,2,9.803714e-001,1.825000e+000,,,,,,,,,,,,,,,,,,1,8.000000e-001,4.000000e+000,2,2,1.809692e-002,0,,0,
1223162873.109,,1.301042e+004,1.620141e+002,-6.326383e-004,1.356108e-006,0.000000e+000,0.000000e+000,2,9.489722e-001,1.825000e+000,,,,,,,,,,,,,,,,,,1,8.000000e-001,4.000000e+000,2,2,2.029419e-002,0,,0,
1223163756.859,,4.258358e+004,1.619975e+002,-2.106925e-003,1.169196e-005,0.000000e+000,0.000000e+000,2,9.468474e-001,1.825000e+000,,,,,,,,,,,,,,,,,,1,8.000000e-001,4.000000e+000,2,2,3.050232e-002,0,,0,
1223164789.031,,4.731655e+004,1.620141e+002,-2.355690e-003,8.400065e-006,0.000000e+000,0.000000e+000,2,9.489918e-001,1.825000e+000,,,,,,,,,,,,,,,,,,1,8.000000e-001,4.000000e+000,2,2,1.519775e-002,0,,0,
1223165423.375,,1.773770e+004,1.620090e+002,-8.714616e-004,2.372530e-006,0.000000e+000,0.000000e+000,2,9.518549e-001,1.825000e+000,,,,,,,,,,,,,,,,,,1,8.000000e-001,4.000000e+000,2,2,5.599976e-002,0,,0,
1223166611.421,,-1.892385e+004,1.620077e+002,9.267770e-004,4.374793e-007,0.000000e+000,0.000000e+000,2,9.498597e-001,1.825000e+000,,,,,,,,,,,,,,,,,,1,8.000000e-001,4.000000e+000,2,2,3.050232e-002,0,,0,
1223167557.515,,-4.849979e+004,1.620090e+002,2.412023e-003,1.336351e-005,0.000000e+000,0.000000e+000,2,9.480653e-001,1.825000e+000,,,,,,,,,,,,,,,,,,1,8.000000e-001,4.000000e+000,2,2,5.599976e-002,0,,0,
1223168527.937,,-4.140325e+004,1.619912e+002,2.062916e-003,1.624629e-006,0.000000e+000,0.000000e+000,2,9.488184e-001,1.825000e+000,,,,,,,,,,,,,,,,,,1,8.000000e-001,4.000000e+000,2,2,6.100464e-002,0,,0,
1223169123.406,,-1.181204e+004,1.619810e+002,5.721067e-004,1.015599e-006,0.000000e+000,0.000000e+000,2,9.503607e-001,1.825000e+000,,,,,,,,,,,,,,,,,,1,8.000000e-001,4.000000e+000,2,2,1.530457e-002,0,,0,
1223170687.750,,2.010637e+004,1.720006e+002,-1.032584e-003,4.314043e-006,0.000000e+000,0.000000e+000,2,9.850538e-001,1.825000e+000,,,,,,,,,,,,,,,,,,1,8.000000e-001,4.000000e+000,2,2,4.539490e-002,0,,0,
1223171647.609,,4.968013e+004,1.720049e+002,-2.591447e-003,9.956040e-006,0.000000e+000,0.000000e+000,2,9.851036e-001,1.825000e+000,,,,,,,,,,,,,,,,,,1,8.000000e-001,4.000000e+000,2,2,1.699829e-002,0,,0,
1223172601.515,,4.021856e+004,1.720063e+002,-2.090582e-003,1.258643e-006,0.000000e+000,0.000000e+000,2,9.851007e-001,1.825000e+000,,,,,,,,,,,,,,,,,,1,8.000000e-001,4.000000e+000,2,2,2.839661e-002,0,,0,
1223173194.546,,1.062792e+004,1.719992e+002,-5.330570e-004,5.444475e-006,0.000000e+000,0.000000e+000,2,9.857858e-001,1.825000e+000,,,,,,,,,,,,,,,,,,1,8.000000e-001,4.000000e+000,2,2,3.410339e-002,0,,0,
1223174305.656,,-1.892385e+004,1.719992e+002,9.736433e-004,8.678794e-007,0.000000e+000,0.000000e+000,2,9.853752e-001,1.825000e+000,,,,,,,,,,,,,,,,,,1,8.000000e-001,4.000000e+000,2,2,5.110168e-002,0,,0,
1223175246.828,,-4.849833e+004,1.719921e+002,2.531788e-003,9.357259e-006,0.000000e+000,0.000000e+000,2,9.841241e-001,1.825000e+000,,,,,,,,,,,,,,,,,,1,8.000000e-001,4.000000e+000,2,2,5.110168e-002,0,,0,
1223176218.453,,-4.140179e+004,1.720034e+002,2.159066e-003,1.188706e-005,0.000000e+000,0.000000e+000,2,9.817224e-001,1.825000e+000,,,,,,,,,,,,,,,,,,1,8.000000e-001,4.000000e+000,2,2,1.699829e-002,0,,0,
1223176800.515,,-1.181175e+004,1.719907e+002,5.961934e-004,1.415294e-006,0.000000e+000,0.000000e+000,2,9.816085e-001,1.825000e+000,,,,,,,,,,,,,,,,,,1,8.000000e-001,4.000000e+000,2,2,2.270508e-002,0,,0,
1223178258.531,,1.655810e+004,1.820166e+002,-8.466354e-004,1.356849e-006,0.000000e+000,0.000000e+000,2,9.711295e-001,1.825000e+000,,,,,,,,,,,,,,,,,,1,8.000000e-001,4.000000e+000,2,2,6.408691e-003,0,,0,
1223179182.359,,4.613476e+004,1.820103e+002,-2.403490e-003,1.230787e-005,0.000000e+000,0.000000e+000,2,9.685317e-001,1.825000e+000,,,,,,,,,,,,,,,,,,1,8.000000e-001,4.000000e+000,2,2,4.409790e-002,0,,0,
1223180177.328,,4.376829e+004,1.819930e+002,-2.276008e-003,6.083470e-006,0.000000e+000,0.000000e+000,2,9.698663e-001,1.825000e+000,,,,,,,,,,,,,,,,,,1,8.000000e-001,4.000000e+000,2,2,3.790283e-002,0,,0,
1223180774.468,,1.418492e+004,1.820071e+002,-7.313465e-004,5.721929e-006,0.000000e+000,0.000000e+000,2,9.720808e-001,1.825000e+000,,,,,,,,,,,,,,,,,,1,8.000000e-001,4.000000e+000,2,2,3.160095e-002,0,,0,
1223181924.546,,-1.774207e+004,1.820040e+002,9.089174e-004,4.571534e-007,0.000000e+000,0.000000e+000,2,9.707880e-001,1.825000e+000,,,,,,,,,,,,,,,,,,1,8.000000e-001,4.000000e+000,2,2,1.249695e-002,0,,0,
1223182856.250,,-4.731655e+004,1.820008e+002,2.456988e-003,5.457688e-007,0.000000e+000,0.000000e+000,2,9.688143e-001,1.825000e+000,,,,,,,,,,,,,,,,,,1,8.000000e-001,4.000000e+000,2,2,2.519226e-002,0,,0,
1223183842.046,,-4.258504e+004,1.820009e+002,2.210261e-003,1.655252e-006,0.000000e+000,0.000000e+000,2,9.699274e-001,1.825000e+000,,,,,,,,,,,,,,,,,,1,8.000000e-001,4.000000e+000,2,2,1.260376e-002,0,,0,
1223184436.328,,-1.299440e+004,1.820040e+002,6.606092e-004,4.441842e-006,0.000000e+000,0.000000e+000,2,9.725937e-001,1.825000e+000,,,,,,,,,,,,,,,,,,1,8.000000e-001,4.000000e+000,2,2,1.879883e-002,0,,0,
1223186231.312,,2.010637e+004,1.920096e+002,-1.012683e-003,3.463203e-006,0.000000e+000,0.000000e+000,2,9.595790e-001,1.825000e+000,,,,,,,,,,,,,,,,,,1,8.000000e-001,4.000000e+000,2,2,1.390076e-002,0,,0,
1223187192.843,,4.968158e+004,1.920027e+002,-2.543685e-003,2.788936e-007,0.000000e+000,0.000000e+000,2,9.581772e-001,1.825000e+000,,,,,,,,,,,,,,,,,,1,8.000000e-001,4.000000e+000,2,2,3.479004e-002,0,,0,
1223188148.484,,4.022002e+004,1.920027e+002,-2.051248e-003,5.526835e-007,0.000000e+000,0.000000e+000,2,9.590032e-001,1.825000e+000,,,,,,,,,,,,,,,,,,1,8.000000e-001,4.000000e+000,2,2,2.090454e-002,0,,0,
1223188743.625,,1.063054e+004,1.920009e+002,-5.284699e-004,1.816924e-006,0.000000e+000,0.000000e+000,2,9.605787e-001,1.825000e+000,,,,,,,,,,,,,,,,,,1,8.000000e-001,4.000000e+000,2,2,2.780151e-002,0,,0,
1223189883.093,,-2.128961e+004,1.920009e+002,1.076086e-003,1.180441e-007,0.000000e+000,0.000000e+000,2,9.595949e-001,1.825000e+000,,,,,,,,,,,,,,,,,,1,8.000000e-001,4.000000e+000,2,2,3.479004e-002,0,,0,
1223190860.453,,-5.086482e+004,1.919974e+002,2.600339e-003,1.125469e-005,0.000000e+000,0.000000e+000,2,9.582350e-001,1.825000e+000,,,,,,,,,,,,,,,,,,1,8.000000e-001,4.000000e+000,2,2,2.090454e-002,0,,0,
1223191800.562,,-3.903532e+004,1.919940e+002,1.993816e-003,4.273460e-006,0.000000e+000,0.000000e+000,2,9.594076e-001,1.825000e+000,,,,,,,,,,,,,,,,,,1,8.000000e-001,4.000000e+000,2,2,3.479004e-002,0,,0,
1223192378.109,,-9.455450e+003,1.920096e+002,4.876974e-004,2.730871e-005,0.000000e+000,0.000000e+000,2,9.633243e-001,1.825000e+000,,,,,,,,,,,,,,,,,,1,8.000000e-001,4.000000e+000,2,2,2.789307e-002,0,,0,
1223193927.578,,1.892385e+004,2.019925e+002,-9.602862e-004,5.982836e-006,0.000000e+000,0.000000e+000,2,9.618481e-001,1.825000e+000,,,,,,,,,,,,,,,,,,1,8.000000e-001,4.000000e+000,2,2,3.059387e-002,0,,0,
1223194869.921,,4.849833e+004,2.019963e+002,-2.484646e-003,4.045274e-006,0.000000e+000,0.000000e+000,2,9.599640e-001,1.825000e+000,,,,,,,,,,,,,,,,,,1,8.000000e-001,4.000000e+000,2,2,1.521301e-002,0,,0,
1223195843.187,,4.140179e+004,2.019944e+002,-2.129695e-003,1.412117e-005,0.000000e+000,0.000000e+000,2,9.621595e-001,1.825000e+000,,,,,,,,,,,,,,,,,,1,8.000000e-001,4.000000e+000,2,2,2.290344e-002,0,,0,
1223196438.656,,1.181174e+004,2.019963e+002,-5.923297e-004,5.391990e-009,0.000000e+000,0.000000e+000,2,9.619863e-001,1.825000e+000,,,,,,,,,,,,,,,,,,1,8.000000e-001,4.000000e+000,2,2,0.000000e+000,0,,0,
1223197555.078,,-1.774207e+004,2.020116e+002,8.975281e-004,6.082893e-007,0.000000e+000,0.000000e+000,2,9.614224e-001,1.825000e+000,,,,,,,,,,,,,,,,,,1,8.000000e-001,4.000000e+000,2,2,0.000000e+000,0,,0,
1223198487.578,,-4.731364e+004,2.020001e+002,2.430268e-003,7.490944e-007,0.000000e+000,0.000000e+000,2,9.610027e-001,1.825000e+000,,,,,,,,,,,,,,,,,,1,8.000000e-001,4.000000e+000,2,2,1.528931e-002,0,,0,
1223199478.296,,-4.258359e+004,2.020116e+002,2.184868e-003,7.311490e-007,0.000000e+000,0.000000e+000,2,9.603317e-001,1.825000e+000,,,,,,,,,,,,,,,,,,1,8.000000e-001,4.000000e+000,2,2,0.000000e+000,0,,0,
1223200071.968,,-1.299412e+004,2.019982e+002,6.521726e-004,7.751481e-007,0.000000e+000,0.000000e+000,2,9.622505e-001,1.825000e+000,,,,,,,,,,,,,,,,,,1,8.000000e-001,4.000000e+000,2,2,7.598877e-003,0,,0,
1223201613.468,,1.655810e+004,2.120078e+002,-8.628953e-004,2.444641e-006,0.000000e+000,0.000000e+000,2,9.884087e-001,1.825000e+000,,,,,,,,,,,,,,,,,,1,8.000000e-001,4.000000e+000,2,2,2.510071e-002,0,,0,
1223202536.125,,4.613476e+004,2.119953e+002,-2.445264e-003,2.994237e-006,0.000000e+000,0.000000e+000,2,9.878939e-001,1.825000e+000,,,,,,,,,,,,,,,,,,1,8.000000e-001,4.000000e+000,2,2,1.669312e-002,0,,0,
1223203533.468,,4.376829e+004,2.120016e+002,-2.314600e-003,4.848863e-006,0.000000e+000,0.000000e+000,2,9.887875e-001,1.825000e+000,,,,,,,,,,,,,,,,,,1,8.000000e-001,4.000000e+000,2,2,3.350830e-002,0,,0,
1223204138.250,,1.418434e+004,2.119953e+002,-7.430003e-004,9.718100e-006,0.000000e+000,0.000000e+000,2,9.830781e-001,1.825000e+000,,,,,,,,,,,,,,,,,,1,8.000000e-001,4.000000e+000,2,2,2.510071e-002,0,,0,
1223205202.281,,-1.537573e+004,2.120057e+002,7.983876e-004,1.533586e-006,0.000000e+000,0.000000e+000,2,9.880495e-001,1.825000e+000,,,,,,,,,,,,,,,,,,1,8.000000e-001,4.000000e+000,2,2,3.350830e-002,0,,0,
1223206111.031,,-4.495007e+004,2.119932e+002,2.378939e-003,9.716001e-006,0.000000e+000,0.000000e+000,2,9.880227e-001,1.825000e+000,,,,,,,,,,,,,,,,,,1,8.000000e-001,4.000000e+000,2,2,1.679993e-002,0,,0,
1223207125.812,,-4.495152e+004,2.120016e+002,2.374197e-003,1.908297e-006,0.000000e+000,0.000000e+000,2,9.875574e-001,1.825000e+000,,,,,,,,,,,,,,,,,,1,8.000000e-001,4.000000e+000,2,2,3.349304e-002,0,,0,
1223207736.828,,-1.536846e+004,2.120016e+002,7.970949e-004,7.192047e-006,0.000000e+000,0.000000e+000,2,9.920005e-001,1.825000e+000,,,,,,,,,,,,,,,,,,1,8.000000e-001,4.000000e+000,2,2,2.510071e-002,0,,0,
1223209137.343,,1.301013e+004,2.219903e+002,-6.615286e-004,1.587915e-006,0.000000e+000,0.000000e+000,2,9.675523e-001,1.825000e+000,,,,,,,,,,,,,,,,,,1,8.000000e-001,4.000000e+000,2,2,9.185791e-003,0,,0,
1223210020.421,,4.258358e+004,2.220040e+002,-2.213926e-003,2.113928e-006,0.000000e+000,0.000000e+000,2,9.663930e-001,1.825000e+000,,,,,,,,,,,,,,,,,,1,8.000000e-001,4.000000e+000,2,2,9.109497e-003,0,,0,
1223211051.718,,4.731655e+004,2.220086e+002,-2.477700e-003,2.237405e-006,0.000000e+000,0.000000e+000,2,9.667435e-001,1.825000e+000,,,,,,,,,,,,,,,,,,1,8.000000e-001,4.000000e+000,2,2,1.820374e-002,0,,0,
1223211687.546,,1.773770e+004,2.219949e+002,-9.130869e-004,1.487117e-006,0.000000e+000,0.000000e+000,2,9.681841e-001,1.825000e+000,,,,,,,,,,,,,,,,,,1,8.000000e-001,4.000000e+000,2,2,2.738953e-002,0,,0,
1223213049.281,,-2.128961e+004,2.219903e+002,1.097472e-003,5.951596e-007,0.000000e+000,0.000000e+000,2,9.676118e-001,1.825000e+000,,,,,,,,,,,,,,,,,,1,8.000000e-001,4.000000e+000,2,2,9.185791e-003,0,,0,
1223214020.781,,-5.086627e+004,2.219926e+002,2.667155e-003,1.587422e-005,0.000000e+000,0.000000e+000,2,9.664358e-001,1.825000e+000,,,,,,,,,,,,,,,,,,1,8.000000e-001,4.000000e+000,2,2,9.185791e-003,0,,0,
1223214963.312,,-3.903532e+004,2.219949e+002,2.043345e-003,5.765228e-006,0.000000e+000,0.000000e+000,2,9.661366e-001,1.825000e+000,,,,,,,,,,,,,,,,,,1,8.000000e-001,4.000000e+000,2,2,9.185791e-003,0,,0,
1223215541.921,,-9.455159e+003,2.220131e+002,4.793238e-004,7.212297e-007,0.000000e+000,0.000000e+000,2,9.706925e-001,1.825000e+000,,,,,,,,,,,,,,,,,,1,8.000000e-001,4.000000e+000,2,2,9.094238e-003,0,,0,
1223217277.468,,2.483788e+004,2.319953e+002,-1.086286e-003,5.587174e-006,0.000000e+000,0.000000e+000,2,9.050552e-001,1.825000e+000,,,,,,,,,,,,,,,,,,1,8.000000e-001,4.000000e+000,2,2,1.989746e-002,0,,0,
1223218294.328,,5.441309e+004,2.319904e+002,-2.374014e-003,1.267517e-005,0.000000e+000,0.000000e+000,2,9.032744e-001,1.825000e+000,,,,,,,,,,,,,,,,,,1,8.000000e-001,4.000000e+000,2,2,1.980591e-002,0,,0,
1223219181.656,,3.548560e+004,2.319978e+002,-1.557974e-003,1.035578e-005,0.000000e+000,0.000000e+000,2,9.054793e-001,1.825000e+000,,,,,,,,,,,,,,,,,,1,8.000000e-001,4.000000e+000,2,2,1.989746e-002,0,,0,
1223220419.968,,-5.915041e+003,2.320003e+002,2.476185e-004,6.439742e-007,0.000000e+000,0.000000e+000,2,9.070762e-001,1.825000e+000,,,,,,,,,,,,,,,,,,1,8.000000e-001,4.000000e+000,2,2,2.980042e-002,0,,0,
1223221353.843,,-3.667101e+004,2.319978e+002,1.603623e-003,1.740286e-006,0.000000e+000,0.000000e+000,2,9.029508e-001,1.825000e+000,,,,,,,,,,,,,,,,,,1,8.000000e-001,4.000000e+000,2,2,9.994507e-003,0,,0,
1223222422.265,,-5.323130e+004,2.320028e+002,2.336726e-003,4.955547e-007,0.000000e+000,0.000000e+000,2,9.042169e-001,1.825000e+000,,,,,,,,,,,,,,,,,,1,8.000000e-001,4.000000e+000,2,2,9.994507e-003,0,,0,
1223223125.546,,-2.365682e+004,2.319953e+002,1.028658e-003,1.225551e-006,0.000000e+000,0.000000e+000,2,9.055188e-001,1.825000e+000,,,,,,,,,,,,,,,,,,1,8.000000e-001,4.000000e+000,2,2,1.989746e-002,0,,0,
1223224667.093,,7.095954e+003,2.420012e+002,-3.610535e-004,1.374300e-007,0.000000e+000,0.000000e+000,2,9.744747e-001,1.825000e+000,,,,,,,,,,,,,,,,,,1,8.000000e-001,4.000000e+000,2,2,2.149963e-002,0,,0,
1223225545.093,,3.667101e+004,2.419984e+002,-1.939767e-003,1.330671e-006,0.000000e+000,0.000000e+000,2,9.725095e-001,1.825000e+000,,,,,,,,,,,,,,,,,,1,8.000000e-001,4.000000e+000,2,2,1.069641e-002,0,,0,
1223226614.000,,5.323130e+004,2.420092e+002,-2.830190e-003,3.947974e-007,0.000000e+000,0.000000e+000,2,9.732068e-001,1.825000e+000,,,,,,,,,,,,,,,,,,1,8.000000e-001,4.000000e+000,2,2,1.080322e-002,0,,0,
1223227318.125,,2.365609e+004,2.419958e+002,-1.243683e-003,1.410685e-006,0.000000e+000,0.000000e+000,2,9.748293e-001,1.825000e+000,,,,,,,,,,,,,,,,,,1,8.000000e-001,4.000000e+000,2,2,2.149963e-002,0,,0,
1223228442.640,,-1.182834e+004,2.420012e+002,6.127262e-004,1.761318e-006,0.000000e+000,0.000000e+000,2,9.737473e-001,1.825000e+000,,,,,,,,,,,,,,,,,,1,8.000000e-001,4.000000e+000,2,2,2.149963e-002,0,,0,
1223229304.796,,-4.140325e+004,2.420011e+002,2.195179e-003,7.415047e-006,0.000000e+000,0.000000e+000,2,9.730582e-001,1.825000e+000,,,,,,,,,,,,,,,,,,1,8.000000e-001,4.000000e+000,2,2,0.000000e+000,0,,0,
1223230349.671,,-4.849979e+004,2.419984e+002,2.583780e-003,8.413565e-006,0.000000e+000,0.000000e+000,2,9.726509e-001,1.825000e+000,,,,,,,,,,,,,,,,,,1,8.000000e-001,4.000000e+000,2,2,1.069641e-002,0,,0,
1223231000.062,,-1.892167e+004,2.419958e+002,9.958602e-004,7.319969e-006,0.000000e+000,0.000000e+000,2,9.756234e-001,1.825000e+000,,,,,,,,,,,,,,,,,,1,8.000000e-001,4.000000e+000,2,2,2.149963e-002,0,,0,
1223232680.390,,1.419308e+004,2.520065e+002,-7.495001e-004,5.445340e-007,0.000000e+000,0.000000e+000,2,9.839195e-001,1.825000e+000,,,,,,,,,,,,,,,,,,1,8.000000e-001,4.000000e+000,2,2,2.319336e-002,0,,0,
1223233580.062,,4.376682e+004,2.520007e+002,-2.355952e-003,5.948303e-007,0.000000e+000,0.000000e+000,2,9.820278e-001,1.825000e+000,,,,,,,,,,,,,,,,,,1,8.000000e-001,4.000000e+000,2,2,1.159668e-002,0,,0,
1223234601.578,,4.613476e+004,2.519949e+002,-2.483282e-003,7.546426e-006,0.000000e+000,0.000000e+000,2,9.826639e-001,1.825000e+000,,,,,,,,,,,,,,,,,,1,8.000000e-001,4.000000e+000,2,2,1.159668e-002,0,,0,
1223235224.000,,1.655301e+004,2.520007e+002,-8.776839e-004,3.540870e-006,0.000000e+000,0.000000e+000,2,9.849585e-001,1.825000e+000,,,,,,,,,,,,,,,,,,1,8.000000e-001,4.000000e+000,2,2,1.159668e-002,0,,0,
1223236323.390,,-1.301070e+004,2.519978e+002,6.885305e-004,2.448963e-006,0.000000e+000,0.000000e+000,2,9.835341e-001,1.825000e+000,,,,,,,,,,,,,,,,,,1,8.000000e-001,4.000000e+000,2,2,1.159668e-002,0,,0,
1223237201.390,,-4.258504e+004,2.519832e+002,2.296053e-003,1.509170e-005,0.000000e+000,0.000000e+000,2,9.810148e-001,1.825000e+000,,,,,,,,,,,,,,,,,,1,8.000000e-001,4.000000e+000,2,2,1.170349e-002,0,,0,
1223238234.375,,-4.731655e+004,2.520007e+002,2.570642e-003,1.125617e-006,0.000000e+000,0.000000e+000,2,9.840518e-001,1.825000e+000,,,,,,,,,,,,,,,,,,1,8.000000e-001,4.000000e+000,2,2,1.159668e-002,0,,0,
1223238867.953,,-1.773770e+004,2.519949e+002,9.528140e-004,1.528354e-005,0.000000e+000,0.000000e+000,2,9.875233e-001,1.825000e+000,,,,,,,,,,,,,,,,,,1,8.000000e-001,4.000000e+000,2,2,1.159668e-002,0,,0,
1223240312.343,,1.064451e+004,2.620076e+002,-5.616205e-004,7.805398e-007,0.000000e+000,0.000000e+000,2,9.883726e-001,1.825000e+000,,,,,,,,,,,,,,,,,,1,8.000000e-001,4.000000e+000,2,2,1.242065e-002,0,,0,
1223241170.140,,4.022002e+004,2.620045e+002,-2.176730e-003,6.630061e-006,0.000000e+000,0.000000e+000,2,9.866731e-001,1.825000e+000,,,,,,,,,,,,,,,,,,1,8.000000e-001,4.000000e+000,2,2,1.242065e-002,0,,0,
1223242217.578,,4.968158e+004,2.619983e+002,-2.703880e-003,6.812643e-007,0.000000e+000,0.000000e+000,2,9.881317e-001,1.825000e+000,,,,,,,,,,,,,,,,,,1,8.000000e-001,4.000000e+000,2,2,2.490234e-002,0,,0,
1223242878.453,,2.010418e+004,2.619921e+002,-1.080133e-003,3.546591e-006,0.000000e+000,0.000000e+000,2,9.908939e-001,1.825000e+000,,,,,,,,,,,,,,,,,,1,8.000000e-001,4.000000e+000,2,2,1.248169e-002,0,,0,
1223244293.546,,-2.128961e+004,2.620014e+002,1.147191e-003,4.036055e-007,0.000000e+000,0.000000e+000,2,9.900616e-001,1.825000e+000,,,,,,,,,,,,,,,,,,1,8.000000e-001,4.000000e+000,2,2,1.242065e-002,0,,0,
1223245266.078,,-5.086627e+004,2.620076e+002,2.764847e-003,4.043299e-006,0.000000e+000,0.000000e+000,2,9.881874e-001,1.825000e+000,,,,,,,,,,,,,,,,,,1,8.000000e-001,4.000000e+000,2,2,1.242065e-002,0,,0,
1223246208.281,,-3.903532e+004,2.619920e+002,2.116383e-003,9.063219e-007,0.000000e+000,0.000000e+000,2,9.881853e-001,1.825000e+000,,,,,,,,,,,,,,,,,,1,8.000000e-001,4.000000e+000,2,2,2.490234e-002,0,,0,
1223246785.015,,-9.455450e+003,2.619983e+002,4.977616e-004,1.493209e-006,0.000000e+000,0.000000e+000,2,9.906149e-001,1.825000e+000,,,,,,,,,,,,,,,,,,1,8.000000e-001,4.000000e+000,2,2,2.490234e-002,0,,0,
1223248458.156,,2.365682e+004,2.720060e+002,-1.113017e-003,5.043628e-006,0.000000e+000,0.000000e+000,2,9.219403e-001,1.825000e+000,,,,,,,,,,,,,,,,,,1,8.000000e-001,4.000000e+000,2,2,1.348877e-002,0,,0,
1223249457.218,,5.322985e+004,2.719992e+002,-2.516397e-003,3.300790e-006,0.000000e+000,0.000000e+000,2,9.207753e-001,1.825000e+000,,,,,,,,,,,,,,,,,,1,8.000000e-001,4.000000e+000,2,2,0.000000e+000,0,,0,
1223250362.015,,3.667175e+004,2.719992e+002,-1.735588e-003,4.051613e-006,0.000000e+000,0.000000e+000,2,9.216448e-001,1.825000e+000,,,,,,,,,,,,,,,,,,1,8.000000e-001,4.000000e+000,2,2,0.000000e+000,0,,0,
1223250985.062,,7.090715e+003,2.719958e+002,-3.155531e-004,1.034578e-005,0.000000e+000,0.000000e+000,2,9.222567e-001,1.825000e+000,,,,,,,,,,,,,,,,,,1,8.000000e-001,4.000000e+000,2,2,1.351929e-002,0,,0,
1223252427.421,,-3.075481e+004,2.719958e+002,1.449628e-003,2.082729e-006,0.000000e+000,0.000000e+000,2,9.206184e-001,1.825000e+000,,,,,,,,,,,,,,,,,,1,8.000000e-001,4.000000e+000,2,2,1.351929e-002,0,,0,
1223253499.140,,-5.914605e+004,2.719992e+002,2.800147e-003,3.177477e-006,0.000000e+000,0.000000e+000,2,9.201432e-001,1.825000e+000,,,,,,,,,,,,,,,,,,1,8.000000e-001,4.000000e+000,2,2,2.700806e-002,0,,0,
1223254272.718,,-2.957229e+004,2.719924e+002,1.393224e-003,1.030252e-005,0.000000e+000,0.000000e+000,2,9.215130e-001,1.825000e+000,,,,,,,,,,,,,,,,,,1,8.000000e-001,4.000000e+000,2,2,1.351929e-002,0,,0,
1223255474.484,,3.056338e-001,2.819573e+002,-1.838631e-006,1.241506e-007,0.000000e+000,0.000000e+000,2,9.570699e-001,1.825000e+000,,,,,,,,,,,,,,,,,,1,8.000000e-001,4.000000e+000,2,2,1.440430e-002,0,,0,
1223256510.140,,2.957156e+004,2.820044e+002,-1.575087e-003,8.072603e-006,0.000000e+000,0.000000e+000,2,9.757979e-001,1.825000e+000,,,,,,,,,,,,,,,,,,1,8.000000e-001,4.000000e+000,2,2,0.000000e+000,0,,0,
1223257577.500,,5.914605e+004,2.820044e+002,-3.172880e-003,2.771320e-006,0.000000e+000,0.000000e+000,2,9.750283e-001,1.825000e+000,,,,,,,,,,,,,,,,,,1,8.000000e-001,4.000000e+000,2,2,0.000000e+000,0,,0,
1223258373.640,,3.075408e+004,2.820044e+002,-1.636651e-003,3.691636e-006,0.000000e+000,0.000000e+000,2,9.767313e-001,1.825000e+000,,,,,,,,,,,,,,,,,,1,8.000000e-001,4.000000e+000,2,2,0.000000e+000,0,,0,
1223259089.390,,1.183008e+003,2.819971e+002,-5.083825e-005,1.167733e-007,0.000000e+000,0.000000e+000,2,9.827738e-001,1.825000e+000,,,,,,,,,,,,,,,,,,1,8.000000e-001,4.000000e+000,2,2,1.449585e-002,0,,0,
1223260137.343,,-2.957156e+004,2.819971e+002,1.565915e-003,7.316430e-007,0.000000e+000,0.000000e+000,2,9.761257e-001,1.825000e+000,,,,,,,,,,,,,,,,,,1,8.000000e-001,4.000000e+000,2,2,1.449585e-002,0,,0,
1223261204.765,,-5.914605e+004,2.819971e+002,3.160147e-003,1.291406e-006,0.000000e+000,0.000000e+000,2,9.756281e-001,1.825000e+000,,,,,,,,,,,,,,,,,,1,8.000000e-001,4.000000e+000,2,2,1.449585e-002,0,,0,
1223262002.625,,-3.075408e+004,2.820008e+002,1.638167e-003,2.512430e-006,0.000000e+000,0.000000e+000,2,9.773741e-001,1.825000e+000,,,,,,,,,,,,,,,,,,1,8.000000e-001,4.000000e+000,2,2,1.449585e-002,0,,0,
1223263500.609,,4.731655e+003,2.920086e+002,-2.358554e-004,3.680955e-007,0.000000e+000,0.000000e+000,2,9.775153e-001,1.825000e+000,,,,,,,,,,,,,,,,,,1,8.000000e-001,4.000000e+000,2,2,0.000000e+000,0,,0,
1223264446.687,,3.430308e+004,2.919969e+002,-1.813865e-003,6.484029e-006,0.000000e+000,0.000000e+000,2,9.774328e-001,1.825000e+000,,,,,,,,,,,,,,,,,,1,8.000000e-001,4.000000e+000,2,2,1.559448e-002,0,,0,
1223265529.203,,5.559779e+004,2.919930e+002,-2.950269e-003,1.408297e-005,0.000000e+000,0.000000e+000,2,9.763327e-001,1.825000e+000,,,,,,,,,,,,,,,,,,1,8.000000e-001,4.000000e+000,2,2,0.000000e+000,0,,0,
1223266264.359,,2.602257e+004,2.919969e+002,-1.371085e-003,2.519344e-006,0.000000e+000,0.000000e+000,2,9.781003e-001,1.825000e+000,,,,,,,,,,,,,,,,,,1,8.000000e-001,4.000000e+000,2,2,1.559448e-002,0,,0,
1223267140.421,,-3.548850e+003,2.920008e+002,1.731557e-004,1.125700e-006,0.000000e+000,0.000000e+000,2,9.803206e-001,1.825000e+000,,,,,,,,,,,,,,,,,,1,8.000000e-001,4.000000e+000,2,2,1.559448e-002,0,,0,
1223268072.328,,-3.312056e+004,2.920047e+002,1.742825e-003,4.097793e-006,0.000000e+000,0.000000e+000,2,9.766380e-001,1.825000e+000,,,,,,,,,,,,,,,,,,1,8.000000e-001,4.000000e+000,2,2,1.559448e-002,0,,0,
1223269149.796,,-5.678102e+004,2.920008e+002,3.004819e-003,1.743167e-006,0.000000e+000,0.000000e+000,2,9.763001e-001,1.825000e+000,,,,,,,,,,,,,,,,,,1,8.000000e-001,4.000000e+000,2,2,3.118896e-002,0,,0,
1223269894.656,,-2.720582e+004,2.920008e+002,1.432341e-003,5.433404e-006,0.000000e+000,0.000000e+000,2,9.777980e-001,1.825000e+000,,,,,,,,,,,,,,,,,,1,8.000000e-001,4.000000e+000,2,2,1.559448e-002,0,,0,
1223271207.453,,2.366045e+003,3.020168e+002,-1.100448e-004,4.546530e-008,0.000000e+000,0.000000e+000,2,9.767437e-001,1.825000e+000,,,,,,,,,,,,,,,,,,1,8.000000e-001,4.000000e+000,2,2,1.669312e-002,0,,0,
1223272151.406,,3.193878e+004,3.020168e+002,-1.666124e-003,7.973821e-006,0.000000e+000,0.000000e+000,2,9.717327e-001,1.825000e+000,,,,,,,,,,,,,,,,,,1,8.000000e-001,4.000000e+000,2,2,1.669312e-002,0,,0,
1223273229.093,,5.796426e+004,3.020043e+002,-3.027215e-003,1.259269e-005,0.000000e+000,0.000000e+000,2,9.713559e-001,1.825000e+000,,,,,,,,,,,,,,,,,,1,8.000000e-001,4.000000e+000,2,2,1.672363e-002,0,,0,
1223273995.546,,2.838906e+004,3.019960e+002,-1.468981e-003,2.071781e-006,0.000000e+000,0.000000e+000,2,9.724070e-001,1.825000e+000,,,,,,,,,,,,,,,,,,1,8.000000e-001,4.000000e+000,2,2,1.672363e-002,0,,0,
1223275161.031,,-8.280067e+003,3.019960e+002,4.168914e-004,1.612940e-006,0.000000e+000,0.000000e+000,2,9.728121e-001,1.825000e+000,,,,,,,,,,,,,,,,,,1,8.000000e-001,4.000000e+000,2,2,1.672363e-002,0,,0,
1223275999.046,,-3.785280e+004,3.019918e+002,1.960486e-003,1.093513e-006,0.000000e+000,0.000000e+000,2,9.718099e-001,1.825000e+000,,,,,,,,,,,,,,,,,,1,8.000000e-001,4.000000e+000,2,2,0.000000e+000,0,,0,
1223276515.156,,-5.204805e+004,3.020043e+002,2.702539e-003,5.808198e-006,0.000000e+000,0.000000e+000,2,9.711317e-001,1.825000e+000,,,,,,,,,,,,,,,,,,1,8.000000e-001,4.000000e+000,2,2,1.672363e-002,0,,0,