File: debug/squid_Test.dat
[Header]
TITLE,MPMS RSO Measurement
BYAPP,MPMS Measurement,1.1,Summary
FILEOPENTIME, 1235126941.500000 2/20/2009, 11:49:01 AM

INFO, APPNAME, MPMS MultiVu Application, Revision 1.58,  Build 076

INFO, NAME, LaCoO_3 on YAlO_3
INFO, WEIGHT, 11.705
INFO, AREA, 2.000
INFO, LENGTH, 0.500
INFO, SHAPE, Triangle
INFO, COMMENT,
INFO, SEQUENCE FILE: MvsT-down.seq


INFO, BACKGROUND DATA FILE:, None


STARTUPAXIS,X,4,LINEAR,AUTO,0.000000,0.000000
STARTUPAXIS,Y1,5,LINEAR,AUTO,0.000000,0.000000


STARTUPGROUP,Longitudinal
FIELDGROUP,Longitudinal,1,2,3,4,5,6,7,8,9,10,11,19,20,21,22,23,35
FIELDGROUP,Transverse,1,2,3,4,12,13,14,15,16,17,18,24,25,26,27,28,35

PLOT_APPEARANCE,ALL,HORZ_GRID_ON,VERT_GRID_ON,MARKERS_AND_LINES

[Data]
Time,Comment,Field (Oe),Temperature (K),Long Moment (emu),Long Scan Std Dev,Long Offset (cm),Long Offset Std Dev,Long Algorithm,Long Reg Fit,Long Reg Factor,Trans Moment (emu),Trans Scan Std Dev,Trans Offset (cm),Trans Offset Std Dev,Trans Algorithm,Trans Reg Fit,Trans Reg Factor,Long Moment [w/o ABS] (emu),Long Scan Std Dev [w/o ABS],Long Offset [w/o ABS] (cm),Long Offset Std Dev [w/o ABS],Long Reg Fit [w/o ABS],Trans Moment [w/o ABS] (emu),Trans Scan Std Dev [w/o ABS],Trans Offset [w/o ABS] (cm),Trans Offset Std Dev [w/o ABS],Trans Reg Fit [w/o ABS],RSO Position (deg),Amplitude (cm),Frequency,Cycles to Average,Scans per Measurement,Delta Temp (K),Error,EC Comp. Running,Using ABS,
1235126941.500,,1.000000e+002,3.000009e+002,-1.432833e-006,5.957108e-008,-6.604727e-003,3.761883e-002,3,6.198851e-001,1.825000e+000,,,,,,,,,,,,,,,,,,0,5.000000e+000,5.000000e-001,3,3,3.289795e-002,0,,0,
1235141304.218,,3.000000e+003,9.438066e+000,-5.239659e-005,1.724459e-007,3.959328e-003,3.142300e-004,3,7.668574e-001,1.825000e+000,,,,,,,,,,,,,,,,,,0,4.000000e+000,1.500000e+000,3,8,7.981405e-001,0,,0,
1235141916.390,,3.000000e+003,1.943489e+001,-5.577413e-005,4.872738e-008,1.687494e-003,5.057493e-004,3,7.648238e-001,1.825000e+000,,,,,,,,,,,,,,,,,,0,4.000000e+000,1.500000e+000,3,8,8.327808e-001,0,,0,
1235142517.468,,3.000000e+003,2.944021e+001,-5.678996e-005,4.083883e-008,1.297475e-003,3.153878e-004,3,7.649492e-001,1.825000e+000,,,,,,,,,,,,,,,,,,0,4.000000e+000,1.500000e+000,3,8,8.420200e-001,0,,0,
1235143116.640,,3.000000e+003,3.942962e+001,-5.738883e-005,2.760322e-008,-2.574252e-004,4.433730e-004,3,7.642473e-001,1.825000e+000,,,,,,,,,,,,,,,,,,0,4.000000e+000,1.500000e+000,3,8,8.390198e-001,0,,0,
1235143716.109,,3.000000e+003,4.943267e+001,-5.784453e-005,5.851945e-008,3.670666e-003,1.324177e-003,3,7.704371e-001,1.825000e+000,,,,,,,,,,,,,,,,,,0,4.000000e+000,1.500000e+000,3,8,7.997513e-001,0,,0,
1235144318.078,,3.000000e+003,5.946346e+001,-5.660882e-005,5.903565e-008,-2.366228e-003,1.046059e-003,3,7.598975e-001,1.825000e+000,,,,,,,,,,,,,,,,,,0,4.000000e+000,1.500000e+000,3,8,8.543205e-001,0,,0,
1235144915.437,,3.000000e+003,6.943642e+001,-5.815581e-005,6.396809e-008,-4.526183e-003,6.437547e-004,3,7.602523e-001,1.825000e+000,,,,,,,,,,,,,,,,,,0,4.000000e+000,1.500000e+000,3,8,8.203430e-001,0,,0,
1235145514.734,,3.000000e+003,7.944013e+001,-5.886448e-005,5.134108e-008,-4.412619e-003,6.001843e-004,3,7.612538e-001,1.825000e+000,,,,,,,,,,,,,,,,,,0,4.000000e+000,1.500000e+000,3,8,8.273392e-001,0,,0,
1235146116.406,,3.000000e+003,8.943479e+001,-5.910675e-005,4.262485e-008,-4.883064e-003,4.309572e-004,3,7.615947e-001,1.825000e+000,,,,,,,,,,,,,,,,,,0,4.000000e+000,1.500000e+000,3,8,8.312759e-001,0,,0,
1235146714.734,,3.000000e+003,9.944537e+001,-5.916886e-005,3.806671e-008,-6.136869e-003,1.734776e-003,3,7.612497e-001,1.825000e+000,,,,,,,,,,,,,,,,,,0,4.000000e+000,1.500000e+000,3,8,8.907623e-001,0,,0,
1235147315.468,,3.000000e+003,1.094527e+002,-5.920107e-005,4.608571e-008,-6.299030e-003,6.511895e-004,3,7.615064e-001,1.825000e+000,,,,,,,,,,,,,,,,,,0,4.000000e+000,1.500000e+000,3,8,8.474960e-001,0,,0,
1235147916.250,,3.000000e+003,1.194508e+002,-5.927466e-005,6.503661e-008,-7.482937e-003,6.169751e-004,3,7.612773e-001,1.825000e+000,,,,,,,,,,,,,,,,,,0,4.000000e+000,1.500000e+000,3,8,8.054962e-001,0,,0,
1235148515.312,,3.000000e+003,1.294378e+002,-5.929519e-005,2.423023e-008,-9.739234e-003,1.727152e-003,3,7.611979e-001,1.825000e+000,,,,,,,,,,,,,,,,,,0,4.000000e+000,1.500000e+000,3,8,8.522949e-001,0,,0,
1235149200.531,,3.000000e+003,1.408752e+002,-5.929714e-005,4.927565e-008,-1.112692e-002,1.487371e-003,3,7.611528e-001,1.825000e+000,,,,,,,,,,,,,,,,,,0,4.000000e+000,1.500000e+000,3,8,8.242035e-001,0,,0,
1235149773.078,,3.000000e+003,1.504332e+002,-5.930096e-005,3.760509e-008,-1.216574e-002,5.675149e-004,3,7.610203e-001,1.825000e+000,,,,,,,,,,,,,,,,,,0,4.000000e+000,1.500000e+000,3,8,8.341980e-001,0,,0,
1235150369.984,,3.000000e+003,1.604028e+002,-5.931294e-005,3.498979e-008,-1.380117e-002,2.490692e-004,3,7.608809e-001,1.825000e+000,,,,,,,,,,,,,,,,,,0,4.000000e+000,1.500000e+000,3,8,8.745117e-001,0,,0,
1235150976.718,,3.000000e+003,1.705010e+002,-5.931588e-005,4.032677e-008,-1.472244e-002,1.650930e-003,3,7.606776e-001,1.825000e+000,,,,,,,,,,,,,,,,,,0,4.000000e+000,1.500000e+000,3,8,8.157959e-001,0,,0,
1235151573.062,,3.000000e+003,1.804415e+002,-5.929860e-005,6.090210e-008,-1.661441e-002,1.591926e-003,3,7.604507e-001,1.825000e+000,,,,,,,,,,,,,,,,,,0,4.000000e+000,1.500000e+000,3,8,8.433990e-001,0,,0,
1235152172.562,,3.000000e+003,1.904390e+002,-5.971784e-005,4.376057e-008,-1.964174e-002,6.880008e-004,3,7.620409e-001,1.825000e+000,,,,,,,,,,,,,,,,,,0,4.000000e+000,1.500000e+000,3,8,8.083038e-001,0,,0,
1235152773.953,,3.000000e+003,2.004727e+002,-5.971773e-005,6.227964e-008,-2.114200e-002,1.046781e-003,3,7.614786e-001,1.825000e+000,,,,,,,,,,,,,,,,,,0,4.000000e+000,1.500000e+000,3,8,8.583984e-001,0,,0,
1235153372.312,,3.000000e+003,2.104538e+002,-5.968157e-005,8.891740e-008,-2.199532e-002,8.888465e-004,3,7.614295e-001,1.825000e+000,,,,,,,,,,,,,,,,,,0,4.000000e+000,1.500000e+000,3,8,8.415070e-001,0,,0,
1235153972.015,,3.000000e+003,2.204439e+002,-5.972110e-005,6.963310e-008,-2.322001e-002,7.984869e-004,3,7.614040e-001,1.825000e+000,,,,,,,,,,,,,,,,,,0,4.000000e+000,1.500000e+000,3,8,8.197937e-001,0,,0,
1235154570.703,,3.000000e+003,2.304274e+002,-5.966450e-005,6.298882e-008,-2.365522e-002,1.073344e-003,3,7.610552e-001,1.825000e+000,,,,,,,,,,,,,,,,,,0,4.000000e+000,1.500000e+000,3,8,8.332062e-001,0,,0,
1235155170.562,,3.000000e+003,2.404226e+002,-5.968921e-005,6.538099e-008,-2.498846e-002,5.133891e-004,3,7.606860e-001,1.825000e+000,,,,,,,,,,,,,,,,,,0,4.000000e+000,1.500000e+000,3,8,7.962036e-001,0,,0,
1235155771.312,,3.000000e+003,2.504269e+002,-5.968099e-005,6.893544e-008,-2.637102e-002,1.873828e-003,3,7.603996e-001,1.825000e+000,,,,,,,,,,,,,,,,,,0,4.000000e+000,1.500000e+000,3,8,8.480988e-001,0,,0,
1235156371.359,,3.000000e+003,2.604359e+002,-5.969836e-005,4.932370e-008,-2.600798e-002,1.415519e-003,3,7.603428e-001,1.825000e+000,,,,,,,,,,,,,,,,,,0,4.000000e+000,1.500000e+000,3,8,8.017883e-001,0,,0,
1235156971.843,,3.000000e+003,2.704560e+002,-5.975299e-005,3.526570e-008,-2.554510e-002,1.805704e-003,3,7.597193e-001,1.825000e+000,,,,,,,,,,,,,,,,,,0,4.000000e+000,1.500000e+000,3,8,8.254089e-001,0,,0,
1235157570.359,,3.000000e+003,2.804405e+002,-5.987057e-005,3.592176e-008,-2.365183e-002,5.570687e-004,3,7.597043e-001,1.825000e+000,,,,,,,,,,,,,,,,,,0,4.000000e+000,1.500000e+000,3,8,8.457947e-001,0,,0,
1235158182.437,,3.000000e+003,2.906565e+002,-5.971832e-005,5.508903e-008,-2.108696e-002,6.563719e-004,3,7.591074e-001,1.825000e+000,,,,,,,,,,,,,,,,,,0,4.000000e+000,1.500000e+000,3,8,8.325195e-001,0,,0,
1235159006.218,,3.000000e+003,3.000015e+002,-5.941205e-005,7.768779e-008,-1.767071e-002,1.080344e-003,3,7.587193e-001,1.825000e+000,,,,,,,,,,,,,,,,,,0,4.000000e+000,1.500000e+000,3,8,1.651001e-002,0,,0,
1235159839.421,,3.000000e+003,2.862140e+002,-5.940914e-005,4.573331e-008,-1.925198e-002,1.536276e-003,3,7.597249e-001,1.825000e+000,,,,,,,,,,,,,,,,,,0,4.000000e+000,1.500000e+000,3,8,5.527954e-001,0,,0,
1235160364.843,,3.000000e+003,2.795616e+002,-5.952246e-005,5.609082e-008,-1.977001e-002,1.008879e-003,3,7.601685e-001,1.825000e+000,,,,,,,,,,,,,,,,,,0,4.000000e+000,1.500000e+000,3,8,7.548828e-001,0,,0,
1235160919.296,,3.000000e+003,2.705601e+002,-5.952645e-005,4.030999e-008,-2.069733e-002,8.388167e-004,3,7.597463e-001,1.825000e+000,,,,,,,,,,,,,,,,,,0,4.000000e+000,1.500000e+000,3,8,7.993164e-001,0,,0,
1235161527.125,,3.000000e+003,2.605701e+002,-5.962166e-005,6.812121e-008,-2.124253e-002,8.828326e-004,3,7.602193e-001,1.825000e+000,,,,,,,,,,,,,,,,,,0,4.000000e+000,1.500000e+000,3,8,8.150024e-001,0,,0,
1235162130.546,,3.000000e+003,2.505502e+002,-5.966732e-005,7.499486e-008,-2.076875e-002,7.397222e-004,3,7.607791e-001,1.825000e+000,,,,,,,,,,,,,,,,,,0,4.000000e+000,1.500000e+000,3,8,8.489990e-001,0,,0,
1235162760.062,,3.000000e+003,2.406939e+002,-5.760274e-005,5.295115e-006,-5.917865e-002,9.465756e-002,3,7.090398e-001,1.825000e+000,,,,,,,,,,,,,,,,,,0,4.000000e+000,1.500000e+000,3,6,6.063995e-001,1,,0,
1235163326.953,,3.000000e+003,2.306015e+002,-5.973843e-005,8.497825e-008,-2.037011e-002,5.419657e-004,3,7.612919e-001,1.825000e+000,,,,,,,,,,,,,,,,,,0,4.000000e+000,1.500000e+000,3,8,7.460938e-001,0,,0,
1235163929.531,,3.000000e+003,2.206084e+002,-5.977306e-005,1.053140e-007,-1.979291e-002,1.056609e-003,3,7.618277e-001,1.825000e+000,,,,,,,,,,,,,,,,,,0,4.000000e+000,1.500000e+000,3,8,7.577972e-001,0,,0,
1235164533.906,,3.000000e+003,2.105739e+002,-5.983246e-005,8.412676e-008,-1.863838e-002,8.738878e-004,3,7.617082e-001,1.825000e+000,,,,,,,,,,,,,,,,,,0,4.000000e+000,1.500000e+000,3,8,7.680054e-001,0,,0,
1235165137.640,,3.000000e+003,2.005984e+002,-5.974176e-005,4.146604e-008,-1.662692e-002,9.546497e-004,3,7.615680e-001,1.825000e+000,,,,,,,,,,,,,,,,,,0,4.000000e+000,1.500000e+000,3,8,7.915955e-001,0,,0,
1235165739.109,,3.000000e+003,1.905893e+002,-5.983245e-005,3.294481e-008,-1.619975e-002,6.430707e-004,3,7.618995e-001,1.825000e+000,,,,,,,,,,,,,,,,,,0,4.000000e+000,1.500000e+000,3,8,8.091888e-001,0,,0,
1235166341.593,,3.000000e+003,1.805841e+002,-5.985385e-005,7.351075e-008,-1.582164e-002,7.195863e-004,3,7.625121e-001,1.825000e+000,,,,,,,,,,,,,,,,,,0,4.000000e+000,1.500000e+000,3,8,7.947083e-001,0,,0,
1235166943.500,,3.000000e+003,1.705695e+002,-5.987017e-005,6.956836e-008,-1.442689e-002,7.656202e-004,3,7.625182e-001,1.825000e+000,,,,,,,,,,,,,,,,,,0,4.000000e+000,1.500000e+000,3,8,7.716064e-001,0,,0,
1235167543.187,,3.000000e+003,1.605989e+002,-5.990682e-005,8.230170e-008,-1.405115e-002,2.275943e-003,3,7.628931e-001,1.825000e+000,,,,,,,,,,,,,,,,,,0,4.000000e+000,1.500000e+000,3,8,8.164063e-001,0,,0,
1235168148.578,,3.000000e+003,1.505383e+002,-5.981183e-005,8.746582e-008,-1.274293e-002,1.731161e-003,3,7.631446e-001,1.825000e+000,,,,,,,,,,,,,,,,,,0,4.000000e+000,1.500000e+000,3,8,7.554016e-001,0,,0,
1235168748.296,,3.000000e+003,1.405854e+002,-5.986585e-005,5.716878e-008,-1.030048e-002,7.606204e-004,3,7.630625e-001,1.825000e+000,,,,,,,,,,,,,,,,,,0,4.000000e+000,1.500000e+000,3,8,7.900085e-001,0,,0,
1235169407.406,,3.000000e+003,1.295615e+002,-5.984730e-005,8.697606e-008,-9.942677e-003,1.303148e-003,3,7.632661e-001,1.825000e+000,,,,,,,,,,,,,,,,,,0,4.000000e+000,1.500000e+000,3,8,8.466034e-001,0,,0,
1235170003.312,,3.000000e+003,1.195456e+002,-5.977769e-005,5.735218e-008,-8.211127e-003,1.808811e-003,3,7.633547e-001,1.825000e+000,,,,,,,,,,,,,,,,,,0,4.000000e+000,1.500000e+000,3,8,8.365936e-001,0,,0,
1235170601.828,,3.000000e+003,1.095563e+002,-5.977556e-005,6.212763e-008,-7.341863e-003,8.711290e-004,3,7.633845e-001,1.825000e+000,,,,,,,,,,,,,,,,,,0,4.000000e+000,1.500000e+000,3,8,8.355026e-001,0,,0,
1235171193.921,,3.000000e+003,9.957629e+001,-5.969698e-005,3.689914e-008,-7.173958e-003,1.942039e-003,3,7.634805e-001,1.825000e+000,,,,,,,,,,,,,,,,,,0,4.000000e+000,1.500000e+000,3,8,8.342667e-001,0,,0,
1235171784.921,,3.000000e+003,8.954236e+001,-5.958151e-005,7.306331e-008,-6.121923e-003,1.801938e-003,3,7.633785e-001,1.825000e+000,,,,,,,,,,,,,,,,,,0,4.000000e+000,1.500000e+000,3,8,8.546906e-001,0,,0,
1235172366.484,,3.000000e+003,7.955823e+001,-5.943458e-005,3.846383e-008,-4.994235e-003,9.104827e-004,3,7.634475e-001,1.825000e+000,,,,,,,,,,,,,,,,,,0,4.000000e+000,1.500000e+000,3,8,8.323288e-001,0,,0,
1235172942.281,,3.000000e+003,6.956152e+001,-5.897628e-005,6.593069e-008,-3.994319e-003,6.878806e-004,3,7.625989e-001,1.825000e+000,,,,,,,,,,,,,,,,,,0,4.000000e+000,1.500000e+000,3,8,8.853226e-001,0,,0,
1235173511.218,,3.000000e+003,5.949689e+001,-5.842515e-005,6.610416e-008,-4.126053e-003,1.511302e-003,3,7.624812e-001,1.825000e+000,,,,,,,,,,,,,,,,,,0,4.000000e+000,1.500000e+000,3,8,8.661880e-001,0,,0,
1235174065.578,,3.000000e+003,4.955832e+001,-5.736338e-005,1.480880e-006,3.767539e-002,1.122822e-001,3,7.205608e-001,1.825000e+000,,,,,,,,,,,,,,,,,,0,4.000000e+000,1.500000e+000,3,8,8.729515e-001,0,,0,
1235174796.671,,3.000000e+003,3.645924e+001,-5.718961e-005,5.705211e-008,-4.749825e-004,1.571423e-003,3,7.645652e-001,1.825000e+000,,,,,,,,,,,,,,,,,,0,4.000000e+000,1.500000e+000,3,8,8.712196e-001,0,,0,
1235175680.421,,3.000000e+003,2.078345e+001,-8.916685e-005,3.765726e-005,2.812042e-001,6.385564e-001,3,1.895253e-001,1.825000e+000,,,,,,,,,,,,,,,,,,0,4.000000e+000,1.500000e+000,3,8,7.458611e-001,0,,0,
1235176496.000,,3.000000e+003,7.400951e+000,-6.712179e-005,3.044538e-005,3.752544e-001,3.168374e-001,3,2.667939e-001,1.825000e+000,,,,,,,,,,,,,,,,,,0,4.000000e+000,1.500000e+000,3,3,6.993642e-001,1,,0,
1235177603.734,,2.004815e+002,4.008753e+000,-1.096091e-005,2.245317e-005,0.000000e+000,0.000000e+000,2,0.000000e+000,1.825000e+000,,,,,,,,,,,,,,,,,,1,8.000000e-001,4.000000e+000,3,3,1.579404e-002,0,,0,
1235178050.421,,1.405947e+003,4.005458e+000,1.451650e-005,3.235953e-005,0.000000e+000,0.000000e+000,2,6.341968e-001,1.825000e+000,,,,,,,,,,,,,,,,,,1,8.000000e-001,4.000000e+000,3,3,1.753569e-002,0,,0,
1235178559.265,,2.410508e+003,3.996956e+000,-7.239074e-006,4.245247e-007,0.000000e+000,0.000000e+000,2,7.320468e-001,1.825000e+000,,,,,,,,,,,,,,,,,,1,8.000000e-001,4.000000e+000,3,3,7.335901e-003,0,,0,
1235179183.078,,4.597030e+004,4.000210e+000,-1.292895e-004,3.784108e-005,0.000000e+000,0.000000e+000,2,5.791048e-001,1.825000e+000,,,,,,,,,,,,,,,,,,1,8.000000e-001,4.000000e+000,3,3,8.289814e-004,0,,0,
1235179717.609,,4.015961e+004,3.998607e+000,-1.231582e-004,3.271578e-005,0.000000e+000,0.000000e+000,2,5.391016e-001,1.825000e+000,,,,,,,,,,,,,,,,,,1,8.000000e-001,4.000000e+000,3,3,5.168915e-004,0,,0,
1235180381.328,,8.024938e+003,3.999658e+000,2.581617e-005,7.244703e-005,0.000000e+000,0.000000e+000,2,3.818958e-001,1.825000e+000,,,,,,,,,,,,,,,,,,1,8.000000e-001,4.000000e+000,3,3,3.108978e-004,0,,0,
1235180749.015,,3.013262e+003,3.999434e+000,4.693029e-005,1.204830e-004,0.000000e+000,0.000000e+000,2,5.568279e-001,1.825000e+000,,,,,,,,,,,,,,,,,,1,8.000000e-001,4.000000e+000,3,3,6.210804e-004,0,,0,
1235181097.203,,2.109094e+003,3.999520e+000,9.770126e-005,1.324316e-004,0.000000e+000,0.000000e+000,2,3.526032e-001,1.825000e+000,,,,,,,,,,,,,,,,,,1,8.000000e-001,4.000000e+000,3,3,3.099442e-004,0,,0,
1235181473.000,,1.556435e+003,3.999537e+000,1.486157e-005,3.632016e-005,0.000000e+000,0.000000e+000,2,6.994401e-001,1.825000e+000,,,,,,,,,,,,,,,,,,1,8.000000e-001,4.000000e+000,3,3,1.039505e-004,0,,0,
1235181802.015,,1.004110e+003,3.999520e+000,8.110375e-005,2.986582e-005,0.000000e+000,0.000000e+000,2,5.033776e-001,1.825000e+000,,,,,,,,,,,,,,,,,,1,8.000000e-001,4.000000e+000,3,3,3.099442e-004,0,,0,
1235182302.656,,4.011959e+002,3.999503e+000,4.809004e-005,9.492852e-005,0.000000e+000,0.000000e+000,2,6.881971e-001,1.825000e+000,,,,,,,,,,,,,,,,,,1,8.000000e-001,4.000000e+000,3,3,4.129410e-004,0,,0,
1235182549.171,,-1.001316e+002,3.999366e+000,5.989386e-008,6.066462e-005,0.000000e+000,0.000000e+000,2,4.533557e-001,1.825000e+000,,,,,,,,,,,,,,,,,,1,8.000000e-001,4.000000e+000,3,3,3.101826e-004,0,,0,
1235182865.921,,-6.026234e+002,3.999572e+000,6.014523e-005,2.834706e-006,0.000000e+000,0.000000e+000,2,6.818461e-001,1.825000e+000,,,,,,,,,,,,,,,,,,1,8.000000e-001,4.000000e+000,3,3,2.069473e-004,0,,0,
1235183435.296,,-1.155093e+003,3.999124e+000,-2.436067e-005,2.822028e-005,0.000000e+000,0.000000e+000,2,4.418372e-001,1.825000e+000,,,,,,,,,,,,,,,,,,1,8.000000e-001,4.000000e+000,3,3,2.069473e-004,0,,0,
1235183963.796,,-1.808045e+003,3.999003e+000,2.589860e-005,3.526267e-005,0.000000e+000,0.000000e+000,2,7.162907e-001,1.825000e+000,,,,,,,,,,,,,,,,,,1,8.000000e-001,4.000000e+000,3,3,0.000000e+000,0,,0,
1235184467.031,,-2.310303e+003,3.999003e+000,-1.080723e-005,3.304681e-005,0.000000e+000,0.000000e+000,2,6.977148e-001,1.825000e+000,,,,,,,,,,,,,,,,,,1,8.000000e-001,4.000000e+000,3,3,2.069473e-004,0,,0,
1235185017.453,,-5.524703e+003,3.999193e+000,-4.364164e-005,9.870133e-005,0.000000e+000,0.000000e+000,2,4.699449e-001,1.825000e+000,,,,,,,,,,,,,,,,,,1,8.000000e-001,4.000000e+000,3,3,3.101826e-004,0,,0,
1235185651.218,,-1.003644e+004,3.999210e+000,1.749644e-006,8.794640e-005,0.000000e+000,0.000000e+000,2,4.435816e-001,1.825000e+000,,,,,,,,,,,,,,,,,,1,8.000000e-001,4.000000e+000,3,3,4.141331e-004,0,,0,
1235186222.343,,-6.026234e+004,3.999383e+000,1.829203e-004,1.193973e-004,0.000000e+000,0.000000e+000,2,4.965004e-001,1.825000e+000,,,,,,,,,,,,,,,,,,1,8.000000e-001,4.000000e+000,3,3,3.101826e-004,0,,0,
1235186764.531,,-2.508966e+004,3.999296e+000,4.722569e-005,2.978234e-005,0.000000e+000,0.000000e+000,2,2.333173e-001,1.825000e+000,,,,,,,,,,,,,,,,,,1,8.000000e-001,4.000000e+000,3,3,4.131794e-004,0,,0,
1235187307.625,,-7.021729e+003,3.999366e+000,-3.520077e-005,5.790760e-005,0.000000e+000,0.000000e+000,2,5.893140e-001,1.825000e+000,,,,,,,,,,,,,,,,,,1,8.000000e-001,4.000000e+000,3,3,3.101826e-004,0,,0,
1235187790.734,,-2.461011e+003,3.999175e+000,3.482546e-006,5.014045e-005,0.000000e+000,0.000000e+000,2,6.948358e-001,1.825000e+000,,,,,,,,,,,,,,,,,,1,8.000000e-001,4.000000e+000,3,3,2.069473e-004,0,,0,
1235188394.531,,-1.757543e+003,3.999210e+000,2.892662e-005,8.479447e-005,0.000000e+000,0.000000e+000,2,6.357117e-001,1.825000e+000,,,,,,,,,,,,,,,,,,1,8.000000e-001,4.000000e+000,3,3,2.071857e-004,0,,0,
1235188711.328,,-1.205334e+003,3.999089e+000,4.558374e-005,9.118162e-005,0.000000e+000,0.000000e+000,2,2.001572e-001,1.825000e+000,,,,,,,,,,,,,,,,,,1,8.000000e-001,4.000000e+000,3,3,3.099442e-004,0,,0,
1235189031.328,,-6.527620e+002,3.999279e+000,5.823595e-005,1.405276e-004,0.000000e+000,0.000000e+000,2,5.382136e-001,1.825000e+000,,,,,,,,,,,,,,,,,,1,8.000000e-001,4.000000e+000,3,3,1.041889e-004,0,,0,
1235189362.953,,-1.505612e+002,3.999141e+000,-1.229127e-005,4.940328e-005,0.000000e+000,0.000000e+000,2,8.151711e-002,1.825000e+000,,,,,,,,,,,,,,,,,,1,8.000000e-001,4.000000e+000,3,3,3.111362e-004,0,,0,
1235189626.187,,3.511591e+002,3.999141e+000,-5.142955e-005,9.222462e-005,0.000000e+000,0.000000e+000,2,6.273019e-001,1.825000e+000,,,,,,,,,,,,,,,,,,1,8.000000e-001,4.000000e+000,3,3,2.069473e-004,0,,0,
1235190026.437,,8.535200e+002,3.999072e+000,-4.397216e-005,8.842705e-005,0.000000e+000,0.000000e+000,2,2.775982e-001,1.825000e+000,,,,,,,,,,,,,,,,,,1,8.000000e-001,4.000000e+000,3,3,2.069473e-004,0,,0,
1235190249.140,,1.355881e+003,3.999245e+000,-4.869946e-005,1.171892e-004,0.000000e+000,0.000000e+000,2,5.994115e-001,1.825000e+000,,,,,,,,,,,,,,,,,,1,8.000000e-001,4.000000e+000,3,3,3.101826e-004,0,,0,
1235190497.421,,1.857819e+003,3.999158e+000,-3.334195e-005,7.531945e-005,0.000000e+000,0.000000e+000,2,4.668438e-001,1.825000e+000,,,,,,,,,,,,,,,,,,1,8.000000e-001,4.000000e+000,3,3,1.029968e-004,0,,0,
1235191003.328,,2.460719e+003,3.999192e+000,-2.621786e-005,3.232501e-005,0.000000e+000,0.000000e+000,2,7.041307e-001,1.825000e+000,,,,,,,,,,,,,,,,,,1,8.000000e-001,4.000000e+000,3,3,4.141331e-004,0,,0,
1235191670.765,,6.528929e+003,3.999348e+000,-2.134297e-005,1.010588e-004,0.000000e+000,0.000000e+000,2,5.042765e-001,1.825000e+000,,,,,,,,,,,,,,,,,,1,8.000000e-001,4.000000e+000,3,3,3.101826e-004,0,,0,
1235192340.953,,3.012608e+004,3.999236e+000,-7.057177e-005,3.840435e-005,0.000000e+000,0.000000e+000,2,5.077060e-001,1.825000e+000,,,,,,,,,,,,,,,,,,1,8.000000e-001,4.000000e+000,3,2,1.041889e-004,0,,0,
1235194139.437,,3.000000e+003,4.473312e+000,-8.831095e-005,9.875685e-005,-9.713747e-002,1.015784e+000,3,1.078402e-001,1.825000e+000,,,,,,,,,,,,,,,,,,0,4.000000e+000,1.500000e+000,3,8,4.056439e-001,0,,0,
1235195480.750,,3.000000e+003,8.923846e+000,-3.350951e-005,1.690229e-004,2.929804e-001,8.489841e-001,3,8.451288e-002,1.825000e+000,,,,,,,,,,,,,,,,,,0,4.000000e+000,1.500000e+000,3,8,3.016987e-001,0,,0,
1235196447.000,,3.000000e+003,1.284219e+001,1.051342e-005,1.258376e-005,1.561673e-001,4.417078e-001,3,1.473913e-002,1.825000e+000,,,,,,,,,,,,,,,,,,0,4.000000e+000,1.500000e+000,3,8,3.227205e-001,0,,0,
1235197467.312,,3.000000e+003,1.704178e+001,2.066962e-005,2.188535e-005,2.385465e-001,4.680755e-001,3,6.900542e-002,1.825000e+000,,,,,,,,,,,,,,,,,,0,4.000000e+000,1.500000e+000,3,7,2.802410e-001,1,,0,
1235198542.890,,3.000000e+003,2.157660e+001,2.930200e-005,3.624040e-005,2.282242e-001,9.400877e-001,3,3.010562e-002,1.825000e+000,,,,,,,,,,,,,,,,,,0,4.000000e+000,1.500000e+000,3,8,2.934704e-001,0,,0,
1235199649.375,,3.000000e+003,2.620380e+001,-7.530314e-005,1.773383e-004,7.579935e-002,9.446015e-001,3,1.051501e-001,1.825000e+000,,,,,,,,,,,,,,,,,,0,4.000000e+000,1.500000e+000,3,8,2.925911e-001,0,,0,
1235200413.781,,3.000000e+003,2.940600e+001,-4.518357e-005,7.814675e-005,-6.584959e-002,7.650517e-001,3,6.233281e-002,1.825000e+000,,,,,,,,,,,,,,,,,,0,4.000000e+000,1.500000e+000,3,8,2.432995e-001,0,,0,
1235200938.328,,3.000000e+003,3.162663e+001,6.944413e-006,4.274921e-008,0.000000e+000,0.000000e+000,3,0.000000e+000,1.825000e+000,,,,,,,,,,,,,,,,,,0,4.000000e+000,1.500000e+000,3,8,2.176590e-001,0,,0,
1235201463.703,,3.000000e+003,3.381211e+001,7.012259e-006,2.979015e-008,0.000000e+000,0.000000e+000,3,0.000000e+000,1.825000e+000,,,,,,,,,,,,,,,,,,0,4.000000e+000,1.500000e+000,3,8,2.085915e-001,0,,0,
1235201990.109,,3.000000e+003,3.601047e+001,6.890832e-006,2.327124e-007,0.000000e+000,0.000000e+000,3,0.000000e+000,1.825000e+000,,,,,,,,,,,,,,,,,,0,4.000000e+000,1.500000e+000,3,8,2.174683e-001,0,,0,
1235202517.765,,3.000000e+003,3.820738e+001,7.092036e-006,3.456686e-008,0.000000e+000,0.000000e+000,3,0.000000e+000,1.825000e+000,,,,,,,,,,,,,,,,,,0,4.000000e+000,1.500000e+000,3,8,2.139015e-001,0,,0,
1235203040.218,,3.000000e+003,4.038297e+001,7.048872e-006,4.763027e-008,0.000000e+000,0.000000e+000,3,0.000000e+000,1.825000e+000,,,,,,,,,,,,,,,,,,0,4.000000e+000,1.500000e+000,3,8,2.063408e-001,0,,0,
1235203565.093,,3.000000e+003,4.257057e+001,7.063091e-006,3.481081e-008,0.000000e+000,0.000000e+000,3,0.000000e+000,1.825000e+000,,,,,,,,,,,,,,,,,,0,4.000000e+000,1.500000e+000,3,8,2.140007e-001,0,,0,
1235204089.203,,3.000000e+003,4.475491e+001,6.873276e-006,5.455663e-008,0.000000e+000,0.000000e+000,3,0.000000e+000,1.825000e+000,,,,,,,,,,,,,,,,,,0,4.000000e+000,1.500000e+000,3,8,2.229309e-001,0,,0,
1235204608.687,,3.000000e+003,4.692140e+001,6.485338e-006,3.494081e-008,0.000000e+000,0.000000e+000,3,0.000000e+000,1.825000e+000,,,,,,,,,,,,,,,,,,0,4.000000e+000,1.500000e+000,3,8,2.219582e-001,0,,0,
1235205127.703,,3.000000e+003,4.908431e+001,6.072379e-006,2.663784e-008,0.000000e+000,0.000000e+000,3,0.000000e+000,1.825000e+000,,,,,,,,,,,,,,,,,,0,4.000000e+000,1.500000e+000,3,8,1.961288e-001,0,,0,
1235205642.421,,3.000000e+003,5.122692e+001,5.851600e-006,5.120224e-008,0.000000e+000,0.000000e+000,3,0.000000e+000,1.825000e+000,,,,,,,,,,,,,,,,,,0,4.000000e+000,1.500000e+000,3,8,2.226410e-001,0,,0,
1235206168.046,,3.000000e+003,5.341243e+001,5.895585e-006,4.876732e-008,0.000000e+000,0.000000e+000,3,0.000000e+000,1.825000e+000,,,,,,,,,,,,,,,,,,0,4.000000e+000,1.500000e+000,3,8,2.017097e-001,0,,0,
1235206690.796,,3.000000e+003,5.559330e+001,6.077945e-006,1.365247e-007,0.000000e+000,0.000000e+000,3,0.000000e+000,1.825000e+000,,,,,,,,,,,,,,,,,,0,4.000000e+000,1.500000e+000,3,8,1.848679e-001,0,,0,
1235207219.328,,3.000000e+003,5.779457e+001,6.361024e-006,3.697454e-008,0.000000e+000,0.000000e+000,3,0.000000e+000,1.825000e+000,,,,,,,,,,,,,,,,,,0,4.000000e+000,1.500000e+000,3,8,1.893616e-001,0,,0,
1235207747.921,,3.000000e+003,5.999571e+001,6.690582e-006,4.776680e-008,0.000000e+000,0.000000e+000,3,0.000000e+000,1.825000e+000,,,,,,,,,,,,,,,,,,0,4.000000e+000,1.500000e+000,3,8,2.129593e-001,0,,0,
1235208313.562,,3.000000e+003,6.235252e+001,7.023525e-006,1.416951e-007,0.000000e+000,0.000000e+000,3,0.000000e+000,1.825000e+000,,,,,,,,,,,,,,,,,,0,4.000000e+000,1.500000e+000,3,8,2.181702e-001,0,,0,
1235208913.390,,3.000000e+003,6.485613e+001,7.346489e-006,1.706683e-007,0.000000e+000,0.000000e+000,3,0.000000e+000,1.825000e+000,,,,,,,,,,,,,,,,,,0,4.000000e+000,1.500000e+000,3,8,2.233200e-001,0,,0,
1235209512.625,,3.000000e+003,6.735316e+001,7.603774e-006,5.183521e-008,0.000000e+000,0.000000e+000,3,0.000000e+000,1.825000e+000,,,,,,,,,,,,,,,,,,0,4.000000e+000,1.500000e+000,3,8,1.789093e-001,0,,0,
1235210112.453,,3.000000e+003,6.985333e+001,7.751542e-006,3.026380e-008,0.000000e+000,0.000000e+000,3,0.000000e+000,1.825000e+000,,,,,,,,,,,,,,,,,,0,4.000000e+000,1.500000e+000,3,8,2.116928e-001,0,,0,
1235210712.734,,3.000000e+003,7.236062e+001,7.833724e-006,4.118888e-008,0.000000e+000,0.000000e+000,3,0.000000e+000,1.825000e+000,,,,,,,,,,,,,,,,,,0,4.000000e+000,1.500000e+000,3,8,2.042770e-001,0,,0,
1235211309.562,,3.000000e+003,7.484830e+001,7.855270e-006,1.544829e-007,0.000000e+000,0.000000e+000,3,0.000000e+000,1.825000e+000,,,,,,,,,,,,,,,,,,0,4.000000e+000,1.500000e+000,3,8,1.975250e-001,0,,0,
1235211910.609,,3.000000e+003,7.734457e+001,8.035760e-006,4.628023e-008,0.000000e+000,0.000000e+000,3,0.000000e+000,1.825000e+000,,,,,,,,,,,,,,,,,,0,4.000000e+000,1.500000e+000,3,8,1.974640e-001,0,,0,
1235212513.437,,3.000000e+003,7.986088e+001,8.006355e-006,3.988056e-008,0.000000e+000,0.000000e+000,3,0.000000e+000,1.825000e+000,,,,,,,,,,,,,,,,,,0,4.000000e+000,1.500000e+000,3,8,2.235413e-001,0,,0,
1235213110.390,,3.000000e+003,8.235342e+001,8.080657e-006,4.756205e-008,0.000000e+000,0.000000e+000,3,0.000000e+000,1.825000e+000,,,,,,,,,,,,,,,,,,0,4.000000e+000,1.500000e+000,3,8,2.081757e-001,0,,0,
1235213711.921,,3.000000e+003,8.485677e+001,8.096685e-006,3.667455e-008,0.000000e+000,0.000000e+000,3,0.000000e+000,1.825000e+000,,,,,,,,,,,,,,,,,,0,4.000000e+000,1.500000e+000,3,8,2.196808e-001,0,,0,
1235214312.109,,3.000000e+003,8.734907e+001,8.010432e-006,2.108963e-007,0.000000e+000,0.000000e+000,3,0.000000e+000,1.825000e+000,,,,,,,,,,,,,,,,,,0,4.000000e+000,1.500000e+000,3,8,1.968536e-001,0,,0,
1235214913.140,,3.000000e+003,8.985090e+001,8.113254e-006,1.529238e-007,0.000000e+000,0.000000e+000,3,0.000000e+000,1.825000e+000,,,,,,,,,,,,,,,,,,0,4.000000e+000,1.500000e+000,3,8,1.922989e-001,0,,0,
1235215514.296,,3.000000e+003,9.236633e+001,7.551404e-006,1.639339e-006,2.367353e-001,6.695887e-001,3,0.000000e+000,1.825000e+000,,,,,,,,,,,,,,,,,,0,4.000000e+000,1.500000e+000,3,8,2.320633e-001,0,,0,
1235216106.265,,3.000000e+003,9.483231e+001,8.198163e-006,2.118306e-007,0.000000e+000,0.000000e+000,3,0.000000e+000,1.825000e+000,,,,,,,,,,,,,,,,,,0,4.000000e+000,1.500000e+000,3,8,2.070236e-001,0,,0,
1235216935.281,,3.000000e+003,9.826227e+001,-7.718891e-005,1.242626e-004,4.343335e-001,7.647701e-001,3,7.481092e-002,1.825000e+000,,,,,,,,,,,,,,,,,,0,4.000000e+000,1.500000e+000,3,8,2.710266e-001,0,,0,
1235217580.812,,3.000000e+003,1.009860e+002,7.057247e-006,2.150656e-006,4.728117e-001,8.754787e-001,3,0.000000e+000,1.825000e+000,,,,,,,,,,,,,,,,,,0,4.000000e+000,1.500000e+000,3,8,2.175980e-001,0,,0,
1235218110.125,,3.000000e+003,1.031918e+002,4.561590e-006,5.378480e-006,7.092057e-001,9.788005e-001,3,0.000000e+000,1.825000e+000,,,,,,,,,,,,,,,,,,0,4.000000e+000,1.500000e+000,3,8,2.626038e-001,0,,0,
1235218643.468,,3.000000e+003,1.054196e+002,7.094877e-006,2.141690e-006,4.720363e-001,8.740474e-001,3,0.000000e+000,1.825000e+000,,,,,,,,,,,,,,,,,,0,4.000000e+000,1.500000e+000,3,8,1.817017e-001,0,,0,
1235219226.531,,3.000000e+003,1.078491e+002,5.438716e-006,2.428928e-006,1.177864e+000,9.753748e-001,3,0.000000e+000,1.825000e+000,,,,,,,,,,,,,,,,,,0,4.000000e+000,1.500000e+000,3,8,1.840057e-001,0,,0,
1235219826.093,,3.000000e+003,1.103497e+002,7.227628e-006,2.133933e-006,4.694874e-001,8.693219e-001,3,0.000000e+000,1.825000e+000,,,,,,,,,,,,,,,,,,0,4.000000e+000,1.500000e+000,3,8,2.380981e-001,0,,0,
1235220426.406,,3.000000e+003,1.128511e+002,5.403976e-006,2.355258e-006,1.176425e+000,9.741763e-001,3,0.000000e+000,1.825000e+000,,,,,,,,,,,,,,,,,,0,4.000000e+000,1.500000e+000,3,8,2.154007e-001,0,,0,
1235221023.343,,3.000000e+003,1.153383e+002,5.383252e-006,2.494301e-006,1.181525e+000,9.784040e-001,3,0.000000e+000,1.825000e+000,,,,,,,,,,,,,,,,,,0,4.000000e+000,1.500000e+000,3,8,1.959991e-001,0,,0,
1235221624.234,,3.000000e+003,1.178506e+002,4.834364e-006,2.242899e-006,1.412382e+000,8.717479e-001,3,0.000000e+000,1.825000e+000,,,,,,,,,,,,,,,,,,0,4.000000e+000,1.500000e+000,3,8,2.212982e-001,0,,0,
1235222226.906,,3.000000e+003,1.203657e+002,4.392469e-006,1.664803e-006,1.641088e+000,6.631253e-001,3,0.000000e+000,1.825000e+000,,,,,,,,,,,,,,,,,,0,4.000000e+000,1.500000e+000,3,8,1.936035e-001,0,,0,
1235222828.046,,3.000000e+003,1.228668e+002,4.834091e-006,2.159092e-006,1.408609e+000,8.694407e-001,3,0.000000e+000,1.825000e+000,,,,,,,,,,,,,,,,,,0,4.000000e+000,1.500000e+000,3,8,2.198944e-001,0,,0,
1235223435.359,,3.000000e+003,1.254098e+002,5.466137e-006,2.443463e-006,1.174083e+000,9.722562e-001,3,0.000000e+000,1.825000e+000,,,,,,,,,,,,,,,,,,0,4.000000e+000,1.500000e+000,3,8,1.630020e-001,0,,0,
1235224024.765,,3.000000e+003,1.278498e+002,4.284794e-006,1.550875e-006,1.641867e+000,6.634499e-001,3,0.000000e+000,1.825000e+000,,,,,,,,,,,,,,,,,,0,4.000000e+000,1.500000e+000,3,8,1.885986e-001,0,,0,
1235224623.656,,3.000000e+003,1.303620e+002,3.851767e-006,1.681909e-007,1.868022e+000,8.509737e-003,3,0.000000e+000,1.825000e+000,,,,,,,,,,,,,,,,,,0,4.000000e+000,1.500000e+000,3,8,1.878052e-001,0,,0,
1235225220.468,,3.000000e+003,1.328452e+002,5.629900e-006,2.441040e-006,1.165683e+000,9.653111e-001,3,0.000000e+000,1.825000e+000,,,,,,,,,,,,,,,,,,0,4.000000e+000,1.500000e+000,3,8,1.721039e-001,0,,0,
1235225821.546,,3.000000e+003,1.353492e+002,5.632419e-006,2.477268e-006,1.166322e+000,9.658262e-001,3,0.000000e+000,1.825000e+000,,,,,,,,,,,,,,,,,,0,4.000000e+000,1.500000e+000,3,8,1.773071e-001,0,,0,
1235226416.718,,3.000000e+003,1.378261e+002,6.245476e-006,2.627007e-006,9.331337e-001,9.976030e-001,3,0.000000e+000,1.825000e+000,,,,,,,,,,,,,,,,,,0,4.000000e+000,1.500000e+000,3,8,2.055054e-001,0,,0,
1235227020.625,,3.000000e+003,1.403525e+002,6.932181e-006,2.583034e-006,6.991411e-001,9.649115e-001,3,0.000000e+000,1.825000e+000,,,,,,,,,,,,,,,,,,0,4.000000e+000,1.500000e+000,3,8,1.921082e-001,0,,0,
1235227622.375,,3.000000e+003,1.428627e+002,6.913788e-006,2.562093e-006,6.986682e-001,9.642851e-001,3,0.000000e+000,1.825000e+000,,,,,,,,,,,,,,,,,,0,4.000000e+000,1.500000e+000,3,8,2.097931e-001,0,,0,
1235228218.250,,3.000000e+003,1.453517e+002,6.315680e-006,2.588343e-006,9.319267e-001,9.962837e-001,3,0.000000e+000,1.825000e+000,,,,,,,,,,,,,,,,,,0,4.000000e+000,1.500000e+000,3,8,1.666107e-001,0,,0,
1235228818.484,,3.000000e+003,1.478464e+002,8.335656e-006,1.771156e-006,2.316863e-001,6.553079e-001,3,0.000000e+000,1.825000e+000,,,,,,,,,,,,,,,,,,0,4.000000e+000,1.500000e+000,3,8,1.676941e-001,0,,0,
1235229422.875,,3.000000e+003,1.503593e+002,7.703214e-006,2.321774e-006,4.637113e-001,8.586298e-001,3,0.000000e+000,1.825000e+000,,,,,,,,,,,,,,,,,,0,4.000000e+000,1.500000e+000,3,8,2.039948e-001,0,,0,
1235230016.187,,3.000000e+003,1.528331e+002,8.366054e-006,1.685012e-006,2.307110e-001,6.525493e-001,3,0.000000e+000,1.825000e+000,,,,,,,,,,,,,,,,,,0,4.000000e+000,1.500000e+000,3,8,2.057037e-001,0,,0,
1235230618.406,,3.000000e+003,1.553369e+002,8.990000e-006,5.896273e-008,0.000000e+000,0.000000e+000,3,0.000000e+000,1.825000e+000,,,,,,,,,,,,,,,,,,0,4.000000e+000,1.500000e+000,3,8,2.212982e-001,0,,0,
1235231223.140,,3.000000e+003,1.578586e+002,8.404969e-006,1.801357e-006,2.321007e-001,6.564798e-001,3,0.000000e+000,1.825000e+000,,,,,,,,,,,,,,,,,,0,4.000000e+000,1.500000e+000,3,8,2.135010e-001,0,,0,
1235231819.015,,3.000000e+003,1.603619e+002,7.634004e-006,2.443195e-006,4.671935e-001,8.650962e-001,3,0.000000e+000,1.825000e+000,,,,,,,,,,,,,,,,,,0,4.000000e+000,1.500000e+000,3,8,2.248077e-001,0,,0,
1235232419.531,,3.000000e+003,1.628420e+002,9.117057e-006,3.767692e-008,0.000000e+000,0.000000e+000,3,0.000000e+000,1.825000e+000,,,,,,,,,,,,,,,,,,0,4.000000e+000,1.500000e+000,3,8,2.005005e-001,0,,0,
1235233017.312,,3.000000e+003,1.653355e+002,9.188349e-006,3.053388e-008,0.000000e+000,0.000000e+000,3,0.000000e+000,1.825000e+000,,,,,,,,,,,,,,,,,,0,4.000000e+000,1.500000e+000,3,8,2.059937e-001,0,,0,
1235233713.078,,3.000000e+003,1.682330e+002,8.456640e-006,1.999321e-006,2.356358e-001,6.664788e-001,3,0.000000e+000,1.825000e+000,,,,,,,,,,,,,,,,,,0,4.000000e+000,1.500000e+000,3,8,2.236023e-001,0,,0,
1235234279.312,,3.000000e+003,1.705922e+002,7.791068e-006,2.602457e-006,4.696781e-001,8.696765e-001,3,0.000000e+000,1.825000e+000,,,,,,,,,,,,,,,,,,0,4.000000e+000,1.500000e+000,3,8,1.734009e-001,0,,0,
1235234934.500,,3.000000e+003,1.733262e+002,9.248718e-006,6.049867e-008,0.000000e+000,0.000000e+000,3,0.000000e+000,1.825000e+000,,,,,,,,,,,,,,,,,,0,4.000000e+000,1.500000e+000,3,8,2.015076e-001,0,,0,
1235235540.234,,3.000000e+003,1.758532e+002,9.315283e-006,8.156444e-008,0.000000e+000,0.000000e+000,3,0.000000e+000,1.825000e+000,,,,,,,,,,,,,,,,,,0,4.000000e+000,1.500000e+000,3,8,2.305908e-001,0,,0,
1235236137.031,,3.000000e+003,1.783276e+002,5.200098e-006,2.477005e-005,-2.347304e-002,5.866501e-001,3,1.416141e-001,1.825000e+000,,,,,,,,,,,,,,,,,,0,4.000000e+000,1.500000e+000,3,8,1.941071e-001,0,,0,
1235236737.984,,3.000000e+003,1.808404e+002,8.667136e-006,1.978052e-006,2.322146e-001,6.568019e-001,3,0.000000e+000,1.825000e+000,,,,,,,,,,,,,,,,,,0,4.000000e+000,1.500000e+000,3,8,2.304077e-001,0,,0,
1235237341.140,,3.000000e+003,1.833515e+002,1.787119e-006,2.144630e-005,-1.486766e-001,4.205210e-001,3,9.422597e-002,1.825000e+000,,,,,,,,,,,,,,,,,,0,4.000000e+000,1.500000e+000,3,8,2.044067e-001,0,,0,
1235237937.812,,3.000000e+003,1.858379e+002,-2.479938e-006,3.150423e-005,-1.864738e-001,6.911117e-001,3,2.344294e-001,1.825000e+000,,,,,,,,,,,,,,,,,,0,4.000000e+000,1.500000e+000,3,8,1.766968e-001,0,,0,
1235238539.125,,3.000000e+003,1.883356e+002,-8.656319e-006,2.753008e-005,-5.434386e-001,7.873471e-001,3,1.882794e-001,1.825000e+000,,,,,,,,,,,,,,,,,,0,4.000000e+000,1.500000e+000,3,8,1.811981e-001,0,,0,
1235239140.609,,3.000000e+003,1.908414e+002,1.977667e-005,1.414976e-005,3.763535e-001,5.194343e-001,3,1.416673e-001,1.825000e+000,,,,,,,,,,,,,,,,,,0,4.000000e+000,1.500000e+000,3,8,2.062988e-001,0,,0,
1235239742.312,,3.000000e+003,1.933496e+002,1.969012e-005,1.429959e-005,5.815889e-001,6.578247e-001,3,1.419825e-001,1.825000e+000,,,,,,,,,,,,,,,,,,0,4.000000e+000,1.500000e+000,3,8,2.113037e-001,0,,0,
1235240341.718,,3.000000e+003,1.958571e+002,2.318904e-005,1.467890e-005,4.979130e-001,5.322931e-001,3,1.894057e-001,1.825000e+000,,,,,,,,,,,,,,,,,,0,4.000000e+000,1.500000e+000,3,8,2.019958e-001,0,,0,
1235240942.078,,3.000000e+003,1.983520e+002,1.419076e-005,2.269509e-005,5.034993e-001,8.473062e-001,3,1.616951e-001,1.825000e+000,,,,,,,,,,,,,,,,,,0,4.000000e+000,1.500000e+000,3,8,2.362976e-001,0,,0,
1235241539.203,,3.000000e+003,2.008416e+002,1.555410e-005,3.025286e-005,3.453449e-001,7.903601e-001,3,2.840236e-001,1.825000e+000,,,,,,,,,,,,,,,,,,0,4.000000e+000,1.500000e+000,3,8,1.812897e-001,0,,0,
1235242135.312,,3.000000e+003,2.033396e+002,3.760728e-006,3.669209e-005,3.086836e-001,1.103892e+000,3,3.300464e-001,1.825000e+000,,,,,,,,,,,,,,,,,,0,4.000000e+000,1.500000e+000,3,8,1.932983e-001,0,,0,
1235242736.625,,3.000000e+003,2.058522e+002,1.241228e-005,3.219361e-005,1.084514e-001,1.132920e+000,3,2.831736e-001,1.825000e+000,,,,,,,,,,,,,,,,,,0,4.000000e+000,1.500000e+000,3,8,1.897888e-001,0,,0,
1235243382.796,,3.000000e+003,2.085440e+002,1.144671e-005,5.881360e-005,3.082339e-001,1.157408e+000,3,4.486242e-002,1.825000e+000,,,,,,,,,,,,,,,,,,0,4.000000e+000,1.500000e+000,3,8,2.189026e-001,0,,0,
1235244427.625,,3.000000e+003,2.128730e+002,-1.820842e-006,4.294509e-005,1.057306e-001,9.372189e-001,3,1.783484e-001,1.825000e+000,,,,,,,,,,,,,,,,,,0,4.000000e+000,1.500000e+000,3,8,2.528992e-001,0,,0,
1235245126.375,,3.000000e+003,2.158196e+002,3.551386e-005,4.450309e-005,2.235420e-001,8.830463e-001,3,0.000000e+000,1.825000e+000,,,,,,,,,,,,,,,,,,0,4.000000e+000,1.500000e+000,3,8,2.076874e-001,0,,0,
1235245685.671,,3.000000e+003,2.181461e+002,2.238246e-005,3.138631e-005,5.964794e-001,8.024051e-001,3,3.766188e-001,1.825000e+000,,,,,,,,,,,,,,,,,,0,4.000000e+000,1.500000e+000,3,8,2.207947e-001,0,,0,
1235246206.750,,3.000000e+003,2.203159e+002,2.325410e-005,1.456747e-005,4.973095e-001,5.316471e-001,3,1.880118e-001,1.825000e+000,,,,,,,,,,,,,,,,,,0,4.000000e+000,1.500000e+000,3,8,1.889954e-001,0,,0,
1235246725.343,,3.000000e+003,2.224790e+002,2.579447e-005,3.122283e-005,7.211887e-001,7.733191e-001,3,4.234287e-001,1.825000e+000,,,,,,,,,,,,,,,,,,0,4.000000e+000,1.500000e+000,3,8,2.017059e-001,0,,0,
1235247248.468,,3.000000e+003,2.246741e+002,3.003349e-005,1.266435e-005,7.458503e-001,4.603493e-001,3,2.817838e-001,1.825000e+000,,,,,,,,,,,,,,,,,,0,4.000000e+000,1.500000e+000,3,8,2.055054e-001,0,,0,
1235247788.609,,3.000000e+003,2.269168e+002,2.327546e-005,1.455722e-005,4.974184e-001,5.317639e-001,3,1.879357e-001,1.825000e+000,,,,,,,,,,,,,,,,,,0,4.000000e+000,1.500000e+000,3,8,2.189026e-001,0,,0,
1235248372.234,,3.000000e+003,2.293451e+002,3.343293e-005,9.753968e-006,8.690487e-001,3.511491e-001,3,3.291385e-001,1.825000e+000,,,,,,,,,,,,,,,,,,0,4.000000e+000,1.500000e+000,3,8,1.846008e-001,0,,0,
1235248972.625,,3.000000e+003,2.318421e+002,3.681759e-005,6.889172e-008,9.949356e-001,8.003020e-004,3,3.727201e-001,1.825000e+000,,,,,,,,,,,,,,,,,,0,4.000000e+000,1.500000e+000,3,8,2.082977e-001,0,,0,
1235249574.250,,3.000000e+003,2.343553e+002,3.685087e-005,4.315200e-008,9.943064e-001,6.225738e-004,3,3.730855e-001,1.825000e+000,,,,,,,,,,,,,,,,,,0,4.000000e+000,1.500000e+000,3,8,1.923065e-001,0,,0,
1235250172.578,,3.000000e+003,2.368486e+002,3.344314e-005,9.664133e-006,8.697681e-001,3.514401e-001,3,3.269570e-001,1.825000e+000,,,,,,,,,,,,,,,,,,0,4.000000e+000,1.500000e+000,3,8,2.167969e-001,0,,0,
1235250773.687,,3.000000e+003,2.393545e+002,3.345434e-005,9.658579e-006,8.696663e-001,3.513984e-001,3,3.257396e-001,1.825000e+000,,,,,,,,,,,,,,,,,,0,4.000000e+000,1.500000e+000,3,8,1.894989e-001,0,,0,
1235251375.015,,3.000000e+003,2.418636e+002,3.695041e-005,6.963064e-008,9.937615e-001,8.269862e-004,3,3.734955e-001,1.825000e+000,,,,,,,,,,,,,,,,,,0,4.000000e+000,1.500000e+000,3,8,1.932983e-001,0,,0,
1235251970.000,,3.000000e+003,2.443416e+002,3.006863e-005,1.274718e-005,7.452281e-001,4.599652e-001,3,2.794149e-001,1.825000e+000,,,,,,,,,,,,,,,,,,0,4.000000e+000,1.500000e+000,3,8,2.079010e-001,0,,0,
1235252586.312,,3.000000e+003,2.469117e+002,3.698663e-005,7.279655e-008,9.936060e-001,6.656529e-004,3,3.739730e-001,1.825000e+000,,,,,,,,,,,,,,,,,,0,4.000000e+000,1.500000e+000,3,8,1.896973e-001,0,,0,
1235253175.453,,3.000000e+003,2.493701e+002,3.694801e-005,4.659197e-008,9.941788e-001,8.382790e-004,3,3.720188e-001,1.825000e+000,,,,,,,,,,,,,,,,,,0,4.000000e+000,1.500000e+000,3,8,2.160950e-001,0,,0,
1235253768.359,,3.000000e+003,2.518459e+002,3.356692e-005,9.727300e-006,8.701283e-001,3.515856e-001,3,3.258303e-001,1.825000e+000,,,,,,,,,,,,,,,,,,0,4.000000e+000,1.500000e+000,3,8,2.200012e-001,0,,0,
1235254371.000,,3.000000e+003,2.543572e+002,3.703608e-005,4.979049e-008,9.941992e-001,6.877878e-004,3,3.729691e-001,1.825000e+000,,,,,,,,,,,,,,,,,,0,4.000000e+000,1.500000e+000,3,8,2.124023e-001,0,,0,
1235254968.625,,3.000000e+003,2.568551e+002,3.708261e-005,4.445911e-008,9.939376e-001,6.404063e-004,3,3.736322e-001,1.825000e+000,,,,,,,,,,,,,,,,,,0,4.000000e+000,1.500000e+000,3,8,1.922913e-001,0,,0,
1235255581.328,,3.000000e+003,2.594110e+002,3.712779e-005,4.831691e-008,9.938967e-001,7.156139e-004,3,3.739146e-001,1.825000e+000,,,,,,,,,,,,,,,,,,0,4.000000e+000,1.500000e+000,3,8,1.959229e-001,0,,0,
1235256167.218,,3.000000e+003,2.618514e+002,2.881630e-005,1.251719e-005,7.841801e-001,4.951670e-001,3,2.337249e-001,1.825000e+000,,,,,,,,,,,,,,,,,,0,4.000000e+000,1.500000e+000,3,8,2.118835e-001,0,,0,
1235256826.046,,3.000000e+003,2.646050e+002,3.052952e-005,6.838560e-005,1.972546e-001,1.064468e+000,3,3.208450e-002,1.825000e+000,,,,,,,,,,,,,,,,,,0,4.000000e+000,1.500000e+000,3,8,2.162781e-001,0,,0,
1235257369.890,,3.000000e+003,2.668546e+002,3.373400e-005,9.795801e-006,8.713201e-001,3.520685e-001,3,3.273908e-001,1.825000e+000,,,,,,,,,,,,,,,,,,0,4.000000e+000,1.500000e+000,3,8,2.072144e-001,0,,0,
1235257968.171,,3.000000e+003,2.693530e+002,3.314225e-005,1.157273e-005,1.091821e+000,2.884591e-001,3,3.287399e-001,1.825000e+000,,,,,,,,,,,,,,,,,,0,4.000000e+000,1.500000e+000,3,8,1.847839e-001,0,,0,
1235258570.218,,3.000000e+003,2.718552e+002,3.290743e-005,1.222981e-005,1.105080e+000,3.213109e-001,3,3.298828e-001,1.825000e+000,,,,,,,,,,,,,,,,,,0,4.000000e+000,1.500000e+000,3,8,2.018127e-001,0,,0,
1235259171.171,,3.000000e+003,2.743556e+002,2.333392e-005,1.482106e-005,4.957616e-001,5.300049e-001,3,1.881948e-001,1.825000e+000,,,,,,,,,,,,,,,,,,0,4.000000e+000,1.500000e+000,3,8,1.918945e-001,0,,0,
1235259770.296,,3.000000e+003,2.768450e+002,3.034705e-005,1.271239e-005,7.464297e-001,4.607083e-001,3,2.826536e-001,1.825000e+000,,,,,,,,,,,,,,,,,,0,4.000000e+000,1.500000e+000,3,8,2.234192e-001,0,,0,
1235260374.390,,3.000000e+003,2.793622e+002,3.371574e-005,9.680103e-006,8.715900e-001,3.521764e-001,3,3.291600e-001,1.825000e+000,,,,,,,,,,,,,,,,,,0,4.000000e+000,1.500000e+000,3,8,2.134094e-001,0,,0,
1235260972.125,,3.000000e+003,2.818559e+002,1.574161e-005,3.040900e-005,3.489763e-001,7.939660e-001,3,2.822893e-001,1.825000e+000,,,,,,,,,,,,,,,,,,0,4.000000e+000,1.500000e+000,3,8,2.028198e-001,0,,0,
1235261574.203,,3.000000e+003,2.843649e+002,2.257024e-005,1.563047e-005,7.311692e-001,6.724306e-001,3,1.886970e-001,1.825000e+000,,,,,,,,,,,,,,,,,,0,4.000000e+000,1.500000e+000,3,8,1.917114e-001,0,,0,
1235262171.937,,3.000000e+003,2.868607e+002,-2.257761e-006,3.179482e-005,-1.736110e-001,7.172531e-001,3,2.348849e-001,1.825000e+000,,,,,,,,,,,,,,,,,,0,4.000000e+000,1.500000e+000,3,8,1.802063e-001,0,,0,
1235262769.046,,3.000000e+003,2.893604e+002,-7.137031e-006,2.752921e-005,-3.441866e-001,5.387926e-001,3,1.875302e-001,1.825000e+000,,,,,,,,,,,,,,,,,,0,4.000000e+000,1.500000e+000,3,8,1.986084e-001,0,,0,
1235263366.156,,3.000000e+003,2.918455e+002,8.674848e-006,1.929026e-006,2.319199e-001,6.559685e-001,3,0.000000e+000,1.825000e+000,,,,,,,,,,,,,,,,,,0,4.000000e+000,1.500000e+000,3,8,1.865234e-001,0,,0,
1235263968.500,,3.000000e+003,2.943653e+002,9.330702e-006,5.259380e-008,0.000000e+000,0.000000e+000,3,0.000000e+000,1.825000e+000,,,,,,,,,,,,,,,,,,0,4.000000e+000,1.500000e+000,3,8,2.056885e-001,0,,0,
1235264595.796,,3.000000e+003,2.968613e+002,4.922157e-005,8.037700e-005,1.271627e-001,7.804042e-001,3,0.000000e+000,1.825000e+000,,,,,,,,,,,,,,,,,,0,4.000000e+000,1.500000e+000,3,6,2.414246e-001,1,,0,
1235265160.312,,3.000000e+003,2.993466e+002,9.141222e-006,4.370004e-008,0.000000e+000,0.000000e+000,3,0.000000e+000,1.825000e+000,,,,,,,,,,,,,,,,,,0,4.000000e+000,1.500000e+000,3,8,1.968994e-001,0,,0,
1235266086.109,,6.024341e+002,3.000060e+002,-1.943180e-006,2.936242e-007,0.000000e+000,0.000000e+000,2,6.812435e-001,1.825000e+000,,,,,,,,,,,,,,,,,,1,8.000000e-001,4.000000e+000,3,3,1.651001e-002,0,,0,
1235266613.968,,1.606937e+003,2.999922e+002,-5.540400e-006,4.277125e-007,0.000000e+000,0.000000e+000,2,6.926768e-001,1.825000e+000,,,,,,,,,,,,,,,,,,1,8.000000e-001,4.000000e+000,3,3,0.000000e+000,0,,0,
1235267125.750,,2.511004e+003,2.999977e+002,-8.405318e-006,8.283187e-008,0.000000e+000,0.000000e+000,2,6.709083e-001,1.825000e+000,,,,,,,,,,,,,,,,,,1,8.000000e-001,4.000000e+000,3,3,1.651001e-002,0,,0,
1235267655.828,,5.082406e+004,2.999895e+002,-1.716190e-004,1.979478e-006,0.000000e+000,0.000000e+000,2,6.416590e-001,1.825000e+000,,,,,,,,,,,,,,,,,,1,8.000000e-001,4.000000e+000,3,3,1.638794e-002,0,,0,
1235268124.484,,3.516176e+004,3.000005e+002,-1.137167e-004,2.622471e-006,0.000000e+000,0.000000e+000,2,6.296724e-001,1.825000e+000,,,,,,,,,,,,,,,,,,1,8.000000e-001,4.000000e+000,3,3,1.651001e-002,0,,0,
1235268602.281,,8.048805e+003,3.000087e+002,-2.739723e-005,1.252336e-007,0.000000e+000,0.000000e+000,2,6.503972e-001,1.825000e+000,,,,,,,,,,,,,,,,,,1,8.000000e-001,4.000000e+000,3,3,0.000000e+000,0,,0,
1235269155.203,,3.013262e+003,2.999950e+002,-9.628080e-006,1.921483e-007,0.000000e+000,0.000000e+000,2,6.512773e-001,1.825000e+000,,,,,,,,,,,,,,,,,,1,8.000000e-001,4.000000e+000,3,3,3.289795e-002,0,,0,
1235269518.546,,2.109167e+003,3.000032e+002,-7.168306e-006,1.590550e-006,0.000000e+000,0.000000e+000,2,6.591479e-001,1.825000e+000,,,,,,,,,,,,,,,,,,1,8.000000e-001,4.000000e+000,3,3,1.651001e-002,0,,0,
1235269924.218,,1.606763e+003,3.000032e+002,-5.628325e-006,7.688117e-007,0.000000e+000,0.000000e+000,2,6.497630e-001,1.825000e+000,,,,,,,,,,,,,,,,,,1,8.000000e-001,4.000000e+000,3,3,1.651001e-002,0,,0,
1235270293.578,,1.104562e+003,3.000060e+002,-4.397767e-006,9.032789e-007,0.000000e+000,0.000000e+000,2,7.424199e-001,1.825000e+000,,,,,,,,,,,,,,,,,,1,8.000000e-001,4.000000e+000,3,3,1.651001e-002,0,,0,
1235270642.718,,6.023323e+002,3.000004e+002,-1.948007e-006,2.324149e-007,0.000000e+000,0.000000e+000,2,7.168610e-001,1.825000e+000,,,,,,,,,,,,,,,,,,1,8.000000e-001,4.000000e+000,3,3,1.651001e-002,0,,0,
1235271026.828,,9.984054e+001,3.000004e+002,-3.229838e-007,4.397143e-008,0.000000e+000,0.000000e+000,2,2.272073e-001,1.825000e+000,,,,,,,,,,,,,,,,,,1,8.000000e-001,4.000000e+000,3,3,1.651001e-002,0,,0,
1235271393.000,,-4.015888e+002,2.999977e+002,1.284671e-006,4.452523e-007,0.000000e+000,0.000000e+000,2,5.405483e-001,1.825000e+000,,,,,,,,,,,,,,,,,,1,8.000000e-001,4.000000e+000,3,3,1.651001e-002,0,,0,
1235271800.906,,-9.040662e+002,2.999949e+002,2.757417e-006,4.206550e-007,0.000000e+000,0.000000e+000,2,6.884267e-001,1.825000e+000,,,,,,,,,,,,,,,,,,1,8.000000e-001,4.000000e+000,3,3,1.651001e-002,0,,0,
1235272330.203,,-1.406179e+003,3.000060e+002,4.429367e-006,8.037993e-007,0.000000e+000,0.000000e+000,2,6.207736e-001,1.825000e+000,,,,,,,,,,,,,,,,,,1,8.000000e-001,4.000000e+000,3,3,1.651001e-002,0,,0,
1235272826.562,,-1.908395e+003,3.000032e+002,6.083290e-006,4.714779e-007,0.000000e+000,0.000000e+000,2,6.593379e-001,1.825000e+000,,,,,,,,,,,,,,,,,,1,8.000000e-001,4.000000e+000,3,3,1.651001e-002,0,,0,
1235273294.843,,-2.410726e+003,3.000005e+002,7.741854e-006,4.282625e-007,0.000000e+000,0.000000e+000,2,6.520131e-001,1.825000e+000,,,,,,,,,,,,,,,,,,1,8.000000e-001,4.000000e+000,3,3,1.651001e-002,0,,0,
1235273834.890,,-6.027107e+003,2.999977e+002,2.021143e-005,8.068736e-007,0.000000e+000,0.000000e+000,2,6.605341e-001,1.825000e+000,,,,,,,,,,,,,,,,,,1,8.000000e-001,4.000000e+000,3,3,1.651001e-002,0,,0,
1235274391.343,,-1.508436e+004,2.999922e+002,4.919396e-005,1.951274e-006,0.000000e+000,0.000000e+000,2,6.355878e-001,1.825000e+000,,,,,,,,,,,,,,,,,,1,8.000000e-001,4.000000e+000,3,3,0.000000e+000,0,,0,
1235274846.109,,-6.531113e+004,3.000060e+002,2.174364e-004,1.019687e-005,0.000000e+000,0.000000e+000,2,6.346700e-001,1.825000e+000,,,,,,,,,,,,,,,,,,1,8.000000e-001,4.000000e+000,3,3,1.651001e-002,0,,0,
1235275326.406,,-2.009109e+004,2.999922e+002,6.667789e-005,3.803410e-007,0.000000e+000,0.000000e+000,2,6.423034e-001,1.825000e+000,,,,,,,,,,,,,,,,,,1,8.000000e-001,4.000000e+000,3,3,3.289795e-002,0,,0,
1235275857.906,,-6.529220e+003,2.999977e+002,2.088850e-005,1.647328e-007,0.000000e+000,0.000000e+000,2,6.351275e-001,1.825000e+000,,,,,,,,,,,,,,,,,,1,8.000000e-001,4.000000e+000,3,3,1.651001e-002,0,,0,
1235276376.015,,-2.461084e+003,3.000060e+002,8.200030e-006,2.231152e-007,0.000000e+000,0.000000e+000,2,6.715591e-001,1.825000e+000,,,,,,,,,,,,,,,,,,1,8.000000e-001,4.000000e+000,3,3,1.651001e-002,0,,0,
1235276677.921,,-1.958751e+003,2.999977e+002,6.256928e-006,2.820658e-007,0.000000e+000,0.000000e+000,2,6.604209e-001,1.825000e+000,,,,,,,,,,,,,,,,,,1,8.000000e-001,4.000000e+000,3,3,1.651001e-002,0,,0,
1235276993.640,,-1.456391e+003,3.000005e+002,4.486998e-006,2.016115e-006,0.000000e+000,0.000000e+000,2,5.901879e-001,1.825000e+000,,,,,,,,,,,,,,,,,,1,8.000000e-001,4.000000e+000,3,3,1.651001e-002,0,,0,
1235277295.609,,-9.541609e+002,3.000087e+002,3.941618e-006,1.129130e-006,0.000000e+000,0.000000e+000,2,6.892335e-001,1.825000e+000,,,,,,,,,,,,,,,,,,1,8.000000e-001,4.000000e+000,3,3,0.000000e+000,0,,0,
1235277642.125,,-4.519893e+002,3.000060e+002,1.330187e-006,3.617475e-007,0.000000e+000,0.000000e+000,2,6.773829e-001,1.825000e+000,,,,,,,,,,,,,,,,,,1,8.000000e-001,4.000000e+000,3,3,1.651001e-002,0,,0,
1235278022.109,,4.976016e+001,2.999949e+002,-4.413530e-007,2.711140e-007,0.000000e+000,0.000000e+000,2,2.325615e-001,1.825000e+000,,,,,,,,,,,,,,,,,,1,8.000000e-001,4.000000e+000,3,3,1.651001e-002,0,,0,
1235278346.531,,5.521647e+002,3.000032e+002,-9.315482e-007,2.913297e-007,0.000000e+000,0.000000e+000,2,2.468615e-001,1.825000e+000,,,,,,,,,,,,,,,,,,1,8.000000e-001,4.000000e+000,3,3,1.651001e-002,0,,0,
1235278767.390,,1.054554e+003,3.000060e+002,-4.105672e-006,3.835888e-007,0.000000e+000,0.000000e+000,2,7.192519e-001,1.825000e+000,,,,,,,,,,,,,,,,,,1,8.000000e-001,4.000000e+000,3,3,1.651001e-002,0,,0,
1235279187.015,,1.556552e+003,3.000004e+002,-5.064737e-006,2.939014e-007,0.000000e+000,0.000000e+000,2,6.723682e-001,1.825000e+000,,,,,,,,,,,,,,,,,,1,8.000000e-001,4.000000e+000,3,3,1.651001e-002,0,,0,
1235279655.984,,2.058738e+003,3.000004e+002,-6.787632e-006,1.939878e-007,0.000000e+000,0.000000e+000,2,6.764044e-001,1.825000e+000,,,,,,,,,,,,,,,,,,1,8.000000e-001,4.000000e+000,3,3,1.651001e-002,0,,0,
1235280131.000,,2.511003e+003,3.000005e+002,-8.105006e-006,2.521286e-007,0.000000e+000,0.000000e+000,2,6.675566e-001,1.825000e+000,,,,,,,,,,,,,,,,,,1,8.000000e-001,4.000000e+000,3,3,1.651001e-002,0,,0,
1235280654.343,,7.553096e+003,2.999977e+002,-2.426865e-005,6.915625e-007,0.000000e+000,0.000000e+000,2,6.413064e-001,1.825000e+000,,,,,,,,,,,,,,,,,,1,8.000000e-001,4.000000e+000,3,3,1.651001e-002,0,,0,
1235281127.734,,3.015009e+004,2.999963e+002,-9.855151e-005,3.906208e-006,0.000000e+000,0.000000e+000,2,6.447721e-001,1.825000e+000,,,,,,,,,,,,,,,,,,1,8.000000e-001,4.000000e+000,3,2,1.651001e-002,0,,0,
1235281409.718,,6.531113e+004,2.999963e+002,-2.117237e-004,1.872674e-006,0.000000e+000,0.000000e+000,2,6.257688e-001,1.825000e+000,,,,,,,,,,,,,,,,,,1,8.000000e-001,4.000000e+000,3,2,1.651001e-002,0,,0,